Workbook

Sheet DICIEMBRE 2024

Sheet ENERO
N1: 9 | O1: 10
C2: TRABAJADOR | F2: MES | N2: H. EXT. | O2: H.S/D EXT Festivos
F3: Enero | H3: 0.020833333 | I3: 0.33333333 | N3: =+J37 -> -170 | O3: =+K37 -> 0
P4: total
B5: FECHAS | C5: ENTRADA | D5: SALIDA | E5: ENTRADA | F5: SALIDA | G5: H.TRAB | H5: DESCONTAR | I5: H.LAB | J5: H. EXT | K5: H EXT Festivos | L5: OBSERVACIONES | N5: =+N3*N1 -> -1530 | O5: =+O3*O1 -> 0 | P5: =+O5+N5 -> -1530
A6: Mi. | B6: 45658 | C6: 0 | D6: 0 | E6: 0 | F6: 0 | G6: =(F6*24-E6*24)+(D6*24-C6*24) -> 0 | H6: 0 | I6: 0 | K6: =G6-I6+H6 -> 0
A7: Ju. | B7: 45659 | C7: 0 | D7: 0 | E7: 0 | F7: 0 | G7: =(F7*24-E7*24)+(D7*24-C7*24) -> 0 | H7: =+$H$3*24 -> 0.5 | I7: =+$I$3*24 -> 8 | J7: =G7-I7-H7 -> -8.5
A8: Vi. | B8: 45660 | C8: 0 | D8: 0 | E8: 0 | F8: 0 | G8: =(F8*24-E8*24)+(D8*24-C8*24) -> 0 | H8: =+$H$3*24 -> 0.5 | I8: =+$I$3*24 -> 8 | J8: =G8-I8-H8 -> -8.5
A9: Sá. | B9: 45661 | C9: 0 | D9: 0 | E9: 0 | F9: 0 | G9: =(F9*24-E9*24)+(D9*24-C9*24) -> 0 | H9: 0 | I9: 0 | K9: =G9-I9+H9 -> 0
A10: Do. | B10: 45662 | C10: 0 | D10: 0 | E10: 0 | F10: 0 | G10: =(F10*24-E10*24)+(D10*24-C10*24) -> 0 | H10: 0 | I10: 0 | K10: =G10-I10+H10 -> 0
A11: Lu. | B11: 45663 | C11: 0 | D11: 0 | E11: 0 | F11: 0 | G11: =(F11*24-E11*24)+(D11*24-C11*24) -> 0 | H11: 0 | I11: 0 | K11: =G11-I11+H11 -> 0
A12: Ma. | B12: 45664 | C12: 0 | D12: 0 | E12: 0 | F12: 0 | G12: =(F12*24-E12*24)+(D12*24-C12*24) -> 0 | H12: =+$H$3*24 -> 0.5 | I12: =+$I$3*24 -> 8 | J12: =G12-I12-H12 -> -8.5
A13: Mi. | B13: 45665 | C13: 0 | D13: 0 | E13: 0 | F13: 0 | G13: =(F13*24-E13*24)+(D13*24-C13*24) -> 0 | H13: =+$H$3*24 -> 0.5 | I13: =+$I$3*24 -> 8 | J13: =G13-I13-H13 -> -8.5
A14: Ju. | B14: 45666 | C14: 0 | D14: 0 | E14: 0 | F14: 0 | G14: =(F14*24-E14*24)+(D14*24-C14*24) -> 0 | H14: =+$H$3*24 -> 0.5 | I14: =+$I$3*24 -> 8 | J14: =G14-I14-H14 -> -8.5
A15: Vi. | B15: 45667 | C15: 0 | D15: 0 | E15: 0 | F15: 0 | G15: =(F15*24-E15*24)+(D15*24-C15*24) -> 0 | H15: =+$H$3*24 -> 0.5 | I15: =+$I$3*24 -> 8 | J15: =G15-I15-H15 -> -8.5
A16: Sá. | B16: 45668 | C16: 0 | D16: 0 | E16: 0 | F16: 0 | G16: =(F16*24-E16*24)+(D16*24-C16*24) -> 0 | H16: 0 | I16: 0 | K16: =G16-I16+H16 -> 0
A17: Do. | B17: 45669 | C17: 0 | D17: 0 | E17: 0 | F17: 0 | G17: =(F17*24-E17*24)+(D17*24-C17*24) -> 0 | H17: 0 | I17: 0 | K17: =G17-I17+H17 -> 0
A18: Lu. | B18: 45670 | C18: 0 | D18: 0 | E18: 0 | F18: 0 | G18: =(F18*24-E18*24)+(D18*24-C18*24) -> 0 | H18: =+$H$3*24 -> 0.5 | I18: =+$I$3*24 -> 8 | J18: =G18-I18-H18 -> -8.5
A19: Ma. | B19: 45671 | C19: 0 | D19: 0 | E19: 0 | F19: 0 | G19: =(F19*24-E19*24)+(D19*24-C19*24) -> 0 | H19: =+$H$3*24 -> 0.5 | I19: =+$I$3*24 -> 8 | J19: =G19-I19-H19 -> -8.5
A20: Mi. | B20: 45672 | C20: 0 | D20: 0 | E20: 0 | F20: 0 | G20: =(F20*24-E20*24)+(D20*24-C20*24) -> 0 | H20: =+$H$3*24 -> 0.5 | I20: =+$I$3*24 -> 8 | J20: =G20-I20-H20 -> -8.5
A21: Ju. | B21: 45673 | C21: 0 | D21: 0 | E21: 0 | F21: 0 | G21: =(F21*24-E21*24)+(D21*24-C21*24) -> 0 | H21: =+$H$3*24 -> 0.5 | I21: =+$I$3*24 -> 8 | J21: =G21-I21-H21 -> -8.5
A22: Vi. | B22: 45674 | C22: 0 | D22: 0 | E22: 0 | F22: 0 | G22: =(F22*24-E22*24)+(D22*24-C22*24) -> 0 | H22: =+$H$3*24 -> 0.5 | I22: =+$I$3*24 -> 8 | J22: =G22-I22-H22 -> -8.5
A23: Sá. | B23: 45675 | C23: 0 | D23: 0 | E23: 0 | F23: 0 | G23: =(F23*24-E23*24)+(D23*24-C23*24) -> 0 | H23: 0 | I23: 0 | K23: =G23-I23+H23 -> 0
A24: Do. | B24: 45676 | C24: 0 | D24: 0 | E24: 0 | F24: 0 | G24: =(F24*24-E24*24)+(D24*24-C24*24) -> 0 | H24: 0 | I24: 0 | K24: =G24-I24+H24 -> 0
A25: Lu. | B25: 45677 | C25: 0 | D25: 0 | E25: 0 | F25: 0 | G25: =(F25*24-E25*24)+(D25*24-C25*24) -> 0 | H25: 0 | I25: 0 | K25: =G25-I25+H25 -> 0
A26: Ma. | B26: 45678 | C26: 0 | D26: 0 | E26: 0 | F26: 0 | G26: =(F26*24-E26*24)+(D26*24-C26*24) -> 0 | H26: =+$H$3*24 -> 0.5 | I26: =+$I$3*24 -> 8 | J26: =G26-I26-H26 -> -8.5
A27: Mi. | B27: 45679 | C27: 0 | D27: 0 | E27: 0 | F27: 0 | G27: =(F27*24-E27*24)+(D27*24-C27*24) -> 0 | H27: =+$H$3*24 -> 0.5 | I27: =+$I$3*24 -> 8 | J27: =G27-I27-H27 -> -8.5
A28: Ju. | B28: 45680 | C28: 0 | D28: 0 | E28: 0 | F28: 0 | G28: =(F28*24-E28*24)+(D28*24-C28*24) -> 0 | H28: =+$H$3*24 -> 0.5 | I28: =+$I$3*24 -> 8 | J28: =G28-I28-H28 -> -8.5
A29: Vi. | B29: 45681 | C29: 0 | D29: 0 | E29: 0 | F29: 0 | G29: =(F29*24-E29*24)+(D29*24-C29*24) -> 0 | H29: =+$H$3*24 -> 0.5 | I29: =+$I$3*24 -> 8 | J29: =G29-I29-H29 -> -8.5
A30: Sá. | B30: 45682 | C30: 0 | D30: 0 | E30: 0 | F30: 0 | G30: =(F30*24-E30*24)+(D30*24-C30*24) -> 0 | H30: 0 | I30: 0 | K30: =G30-I30+H30 -> 0
A31: Do. | B31: 45683 | C31: 0 | D31: 0 | E31: 0 | F31: 0 | G31: =(F31*24-E31*24)+(D31*24-C31*24) -> 0 | H31: 0 | I31: 0 | K31: =G31-I31+H31 -> 0
A32: Lu. | B32: 45684 | C32: 0 | D32: 0 | E32: 0 | F32: 0 | G32: =(F32*24-E32*24)+(D32*24-C32*24) -> 0 | H32: =+$H$3*24 -> 0.5 | I32: =+$I$3*24 -> 8 | J32: =G32-I32-H32 -> -8.5
A33: Ma. | B33: 45685 | C33: 0 | D33: 0 | E33: 0 | F33: 0 | G33: =(F33*24-E33*24)+(D33*24-C33*24) -> 0 | H33: =+$H$3*24 -> 0.5 | I33: =+$I$3*24 -> 8 | J33: =G33-I33-H33 -> -8.5
A34: Mi. | B34: 45686 | C34: 0 | D34: 0 | E34: 0 | F34: 0 | G34: =(F34*24-E34*24)+(D34*24-C34*24) -> 0 | H34: =+$H$3*24 -> 0.5 | I34: =+$I$3*24 -> 8 | J34: =G34-I34-H34 -> -8.5
A35: Ju. | B35: 45687 | C35: 0 | D35: 0 | E35: 0 | F35: 0 | G35: =(F35*24-E35*24)+(D35*24-C35*24) -> 0 | H35: =+$H$3*24 -> 0.5 | I35: =+$I$3*24 -> 8 | J35: =G35-I35-H35 -> -8.5
A36: Vi. | B36: 45688 | C36: 0 | D36: 0 | E36: 0 | F36: 0 | G36: =(F36*24-E36*24)+(D36*24-C36*24) -> 0 | H36: =+$H$3*24 -> 0.5 | I36: =+$I$3*24 -> 8 | J36: =G36-I36-H36 -> -8.5
G37: =SUM(G6:G36) -> 0 | H37: =SUM(H6:H36) -> 10 | I37: =SUM(I6:I36) -> 160 | J37: =SUM(J6:J36) -> -170 | K37: =SUM(K6:K36) -> 0

Sheet FEBRERO
N1: 9 | O1: 10
C2: TRABAJADOR | F2: MES | N2: H. EXT. | O2: H.S/D EXT Festivos
C3: =+ENERO!$C$3 -> 0 | F3: Febrero | H3: 0.020833333 | I3: 0.33333333 | N3: =+J34 -> -161.16667 | O3: =+K34 -> 0
P4: total
B5: FECHAS | C5: ENTRADA | D5: SALIDA | E5: ENTRADA | F5: SALIDA | G5: H.TRAB | H5: DESCONTAR | I5: H.LAB | J5: H. EXT | K5: H EXT Festivos | L5: OBSERVACIONES | N5: =+N3*N1 -> -1450.5 | O5: =+O3*O1 -> 0 | P5: =+O5+N5 -> -1450.5
A6: Sá. | B6: 45689 | C6: 0 | D6: 0 | E6: 0 | F6: 0 | G6: =(F6*24-E6*24)+(D6*24-C6*24) -> 0 | H6: 0 | I6: 0 | K6: =G6-I6+H6 -> 0
A7: Do. | B7: 45690 | C7: 0 | D7: 0 | E7: 0 | F7: 0 | G7: =(F7*24-E7*24)+(D7*24-C7*24) -> 0 | H7: 0 | I7: 0 | K7: =G7-I7+H7 -> 0
A8: Lu. | B8: 45691 | C8: 0.29166667 | D8: 0.65972222 | E8: 0 | F8: 0 | G8: =(F8*24-E8*24)+(D8*24-C8*24) -> 8.8333333 | H8: =+$H$3*24 -> 0.5 | I8: =+$I$3*24 -> 8 | J8: =G8-I8-H8 -> 0.33333333
A9: Ma. | B9: 45692 | C9: 0 | D9: 0 | E9: 0 | F9: 0 | G9: =(F9*24-E9*24)+(D9*24-C9*24) -> 0 | H9: =+$H$3*24 -> 0.5 | I9: =+$I$3*24 -> 8 | J9: =G9-I9-H9 -> -8.5
A10: Mi. | B10: 45693 | C10: 0 | D10: 0 | E10: 0 | F10: 0 | G10: =(F10*24-E10*24)+(D10*24-C10*24) -> 0 | H10: =+$H$3*24 -> 0.5 | I10: =+$I$3*24 -> 8 | J10: =G10-I10-H10 -> -8.5
A11: Ju. | B11: 45694 | C11: 0 | D11: 0 | E11: 0 | F11: 0 | G11: =(F11*24-E11*24)+(D11*24-C11*24) -> 0 | H11: =+$H$3*24 -> 0.5 | I11: =+$I$3*24 -> 8 | J11: =G11-I11-H11 -> -8.5
A12: Vi. | B12: 45695 | C12: 0 | D12: 0 | E12: 0 | F12: 0 | G12: =(F12*24-E12*24)+(D12*24-C12*24) -> 0 | H12: =+$H$3*24 -> 0.5 | I12: =+$I$3*24 -> 8 | J12: =G12-I12-H12 -> -8.5
A13: Sá. | B13: 45696 | C13: 0 | D13: 0 | E13: 0 | F13: 0 | G13: =(F13*24-E13*24)+(D13*24-C13*24) -> 0 | H13: 0 | I13: 0 | K13: =G13-I13+H13 -> 0
A14: Do. | B14: 45697 | C14: 0 | D14: 0 | E14: 0 | F14: 0 | G14: =(F14*24-E14*24)+(D14*24-C14*24) -> 0 | H14: 0 | I14: 0 | K14: =G14-I14+H14 -> 0
A15: Lu. | B15: 45698 | C15: 0 | D15: 0 | E15: 0 | F15: 0 | G15: =(F15*24-E15*24)+(D15*24-C15*24) -> 0 | H15: =+$H$3*24 -> 0.5 | I15: =+$I$3*24 -> 8 | J15: =G15-I15-H15 -> -8.5
A16: Ma. | B16: 45699 | C16: 0 | D16: 0 | E16: 0 | F16: 0 | G16: =(F16*24-E16*24)+(D16*24-C16*24) -> 0 | H16: =+$H$3*24 -> 0.5 | I16: =+$I$3*24 -> 8 | J16: =G16-I16-H16 -> -8.5
A17: Mi. | B17: 45700 | C17: 0 | D17: 0 | E17: 0 | F17: 0 | G17: =(F17*24-E17*24)+(D17*24-C17*24) -> 0 | H17: =+$H$3*24 -> 0.5 | I17: =+$I$3*24 -> 8 | J17: =G17-I17-H17 -> -8.5
A18: Ju. | B18: 45701 | C18: 0 | D18: 0 | E18: 0 | F18: 0 | G18: =(F18*24-E18*24)+(D18*24-C18*24) -> 0 | H18: =+$H$3*24 -> 0.5 | I18: =+$I$3*24 -> 8 | J18: =G18-I18-H18 -> -8.5
A19: Vi. | B19: 45702 | C19: 0 | D19: 0 | E19: 0 | F19: 0 | G19: =(F19*24-E19*24)+(D19*24-C19*24) -> 0 | H19: =+$H$3*24 -> 0.5 | I19: =+$I$3*24 -> 8 | J19: =G19-I19-H19 -> -8.5
A20: Sá. | B20: 45703 | C20: 0 | D20: 0 | E20: 0 | F20: 0 | G20: =(F20*24-E20*24)+(D20*24-C20*24) -> 0 | H20: 0 | I20: 0 | K20: =G20-I20+H20 -> 0
A21: Do. | B21: 45704 | C21: 0 | D21: 0 | E21: 0 | F21: 0 | G21: =(F21*24-E21*24)+(D21*24-C21*24) -> 0 | H21: 0 | I21: 0 | K21: =G21-I21+H21 -> 0
A22: Lu. | B22: 45705 | C22: 0 | D22: 0 | E22: 0 | F22: 0 | G22: =(F22*24-E22*24)+(D22*24-C22*24) -> 0 | H22: =+$H$3*24 -> 0.5 | I22: =+$I$3*24 -> 8 | J22: =G22-I22-H22 -> -8.5
A23: Vi. | B23: 45706 | C23: 0 | D23: 0 | E23: 0 | F23: 0 | G23: =(F23*24-E23*24)+(D23*24-C23*24) -> 0 | H23: =+$H$3*24 -> 0.5 | I23: =+$I$3*24 -> 8 | J23: =G23-I23-H23 -> -8.5
A24: Mi. | B24: 45707 | C24: 0 | D24: 0 | E24: 0 | F24: 0 | G24: =(F24*24-E24*24)+(D24*24-C24*24) -> 0 | H24: =+$H$3*24 -> 0.5 | I24: =+$I$3*24 -> 8 | J24: =G24-I24-H24 -> -8.5
A25: Ju. | B25: 45708 | C25: 0 | D25: 0 | E25: 0 | F25: 0 | G25: =(F25*24-E25*24)+(D25*24-C25*24) -> 0 | H25: =+$H$3*24 -> 0.5 | I25: =+$I$3*24 -> 8 | J25: =G25-I25-H25 -> -8.5
A26: Vi. | B26: 45709 | C26: 0 | D26: 0 | E26: 0 | F26: 0 | G26: =(F26*24-E26*24)+(D26*24-C26*24) -> 0 | H26: =+$H$3*24 -> 0.5 | I26: =+$I$3*24 -> 8 | J26: =G26-I26-H26 -> -8.5
A27: Sá. | B27: 45710 | C27: 0 | D27: 0 | E27: 0 | F27: 0 | G27: =(F27*24-E27*24)+(D27*24-C27*24) -> 0 | H27: 0 | I27: 0 | K27: =G27-I27+H27 -> 0
A28: Do. | B28: 45711 | C28: 0 | D28: 0 | E28: 0 | F28: 0 | G28: =(F28*24-E28*24)+(D28*24-C28*24) -> 0 | H28: 0 | I28: 0 | K28: =G28-I28+H28 -> 0
A29: Lu. | B29: 45712 | C29: 0 | D29: 0 | E29: 0 | F29: 0 | G29: =(F29*24-E29*24)+(D29*24-C29*24) -> 0 | H29: =+$H$3*24 -> 0.5 | I29: =+$I$3*24 -> 8 | J29: =G29-I29-H29 -> -8.5
A30: Ma. | B30: 45713 | C30: 0 | D30: 0 | E30: 0 | F30: 0 | G30: =(F30*24-E30*24)+(D30*24-C30*24) -> 0 | H30: =+$H$3*24 -> 0.5 | I30: =+$I$3*24 -> 8 | J30: =G30-I30-H30 -> -8.5
A31: Mi. | B31: 45714 | C31: 0 | D31: 0 | E31: 0 | F31: 0 | G31: =(F31*24-E31*24)+(D31*24-C31*24) -> 0 | H31: =+$H$3*24 -> 0.5 | I31: =+$I$3*24 -> 8 | J31: =G31-I31-H31 -> -8.5
A32: Ju. | B32: 45715 | C32: 0 | D32: 0 | E32: 0 | F32: 0 | G32: =(F32*24-E32*24)+(D32*24-C32*24) -> 0 | H32: =+$H$3*24 -> 0.5 | I32: =+$I$3*24 -> 8 | J32: =G32-I32-H32 -> -8.5
A33: Vi. | B33: 45716 | C33: 0 | D33: 0 | E33: 0 | F33: 0 | G33: =(F33*24-E33*24)+(D33*24-C33*24) -> 0 | H33: =+$H$3*24 -> 0.5 | I33: =+$I$3*24 -> 8 | J33: =G33-I33-H33 -> -8.5
G34: =SUM(G6:G33) -> 8.8333333 | H34: =SUM(H6:H33) -> 10 | I34: =SUM(I6:I33) -> 160 | J34: =SUM(J6:J33) -> -161.16667 | K34: =SUM(K6:K33) -> 0

Sheet MARZO
N1: 9 | O1: 10
C2: TRABAJADOR | F2: MES | N2: H. EXT. | O2: H.S/D EXT Festivos
C3: =+ENERO!$C$3 -> 0 | F3: Marzo | H3: 0.020833333 | I3: 0.33333333 | N3: =J37 -> 0 | O3: =K37 -> 0
P4: total
B5: FECHAS | C5: ENTRADA | D5: SALIDA | E5: ENTRADA | F5: SALIDA | G5: H.TRAB | H5: DESCONTAR | I5: H.LAB | J5: H. EXT | K5: H EXT Festivos | L5: OBSERVACIONES | N5: =+N3*N1 -> 0 | O5: =+O3*O1 -> 0 | P5: =+O5+N5 -> 0
A6: Sá. | B6: 45717 | C6: 0 | D6: 0 | E6: 0 | F6: 0 | G6: =(F6*24-E6*24)+(D6*24-C6*24) -> 0 | H6: 0 | I6: 0 | K6: =G6-I6+H6 -> 0
A7: Do. | B7: 45718 | C7: 0 | D7: 0 | E7: 0 | F7: 0 | G7: =(F7*24-E7*24)+(D7*24-C7*24) -> 0 | H7: 0 | I7: 0 | K7: =G7-I7+H7 -> 0
A8: Lu. | B8: 45719 | C8: 0 | D8: 0 | E8: 0 | F8: 0 | G8: =(F8*24-E8*24)+(D8*24-C8*24) -> 0 | H8: =+$H$3*24 -> 0.5 | I8: =+$I$3*24 -> 8 | J8: =G8-I8-H8 -> -8.5
A9: Ma. | B9: 45720 | C9: 0 | D9: 0 | E9: 0 | F9: 0 | G9: =(F9*24-E9*24)+(D9*24-C9*24) -> 0 | H9: =+$H$3*24 -> 0.5 | I9: =+$I$3*24 -> 8 | J9: =G9-I9-H9 -> -8.5
A10: Mi. | B10: 45721 | C10: 0 | D10: 0 | E10: 0 | F10: 0 | G10: =(F10*24-E10*24)+(D10*24-C10*24) -> 0 | H10: =+$H$3*24 -> 0.5 | I10: =+$I$3*24 -> 8 | J10: =G10-I10-H10 -> -8.5
A11: Ju. | B11: 45722 | C11: 0 | D11: 0 | E11: 0 | F11: 0 | G11: =(F11*24-E11*24)+(D11*24-C11*24) -> 0 | H11: =+$H$3*24 -> 0.5 | I11: =+$I$3*24 -> 8 | J11: =G11-I11-H11 -> -8.5
A12: Vi. | B12: 45723 | C12: 0 | D12: 0 | E12: 0 | F12: 0 | G12: =(F12*24-E12*24)+(D12*24-C12*24) -> 0 | H12: =+$H$3*24 -> 0.5 | I12: =+$I$3*24 -> 8 | J12: =G12-I12-H12 -> -8.5
A13: Sá. | B13: 45724 | C13: 0 | D13: 0 | E13: 0 | F13: 0 | G13: =(F13*24-E13*24)+(D13*24-C13*24) -> 0 | H13: 0 | I13: 0 | K13: =G13-I13+H13 -> 0
A14: Do. | B14: 45725 | C14: 0 | D14: 0 | E14: 0 | F14: 0 | G14: =(F14*24-E14*24)+(D14*24-C14*24) -> 0 | H14: 0 | I14: 0 | K14: =G14-I14+H14 -> 0
A15: Lu. | B15: 45726 | C15: 0 | D15: 0 | E15: 0 | F15: 0 | G15: =(F15*24-E15*24)+(D15*24-C15*24) -> 0 | H15: =+$H$3*24 -> 0.5 | I15: =+$I$3*24 -> 8 | J15: =G15-I15-H15 -> -8.5
A16: Ma. | B16: 45727 | C16: 0 | D16: 0 | E16: 0 | F16: 0 | G16: =(F16*24-E16*24)+(D16*24-C16*24) -> 0 | H16: =+$H$3*24 -> 0.5 | I16: =+$I$3*24 -> 8 | J16: =G16-I16-H16 -> -8.5
A17: Mi. | B17: 45728 | C17: 0 | D17: 0 | E17: 0 | F17: 0 | G17: =(F17*24-E17*24)+(D17*24-C17*24) -> 0 | H17: =+$H$3*24 -> 0.5 | I17: =+$I$3*24 -> 8 | J17: =G17-I17-H17 -> -8.5
A18: Ju. | B18: 45729 | C18: 0 | D18: 0 | E18: 0 | F18: 0 | G18: =(F18*24-E18*24)+(D18*24-C18*24) -> 0 | H18: =+$H$3*24 -> 0.5 | I18: =+$I$3*24 -> 8 | J18: =G18-I18-H18 -> -8.5
A19: Vi. | B19: 45730 | C19: 0 | D19: 0 | E19: 0 | F19: 0 | G19: =(F19*24-E19*24)+(D19*24-C19*24) -> 0 | H19: =+$H$3*24 -> 0.5 | I19: =+$I$3*24 -> 8 | J19: =G19-I19-H19 -> -8.5
A20: Sá. | B20: 45731 | C20: 0 | D20: 0 | E20: 0 | F20: 0 | G20: =(F20*24-E20*24)+(D20*24-C20*24) -> 0 | H20: 0 | I20: 0 | K20: =G20-I20+H20 -> 0
A21: Do. | B21: 45732 | C21: 0 | D21: 0 | E21: 0 | F21: 0 | G21: =(F21*24-E21*24)+(D21*24-C21*24) -> 0 | H21: 0 | I21: 0 | K21: =G21-I21+H21 -> 0
A22: Lu. | B22: 45733 | C22: 0 | D22: 0 | E22: 0 | F22: 0 | G22: =(F22*24-E22*24)+(D22*24-C22*24) -> 0 | H22: =+$H$3*24 -> 0.5 | I22: =+$I$3*24 -> 8 | J22: =G22-I22-H22 -> -8.5
A23: Ma. | B23: 45734 | C23: 0 | D23: 0 | E23: 0 | F23: 0 | G23: =(F23*24-E23*24)+(D23*24-C23*24) -> 0 | H23: =+$H$3*24 -> 0.5 | I23: =+$I$3*24 -> 8 | J23: =G23-I23-H23 -> -8.5
A24: Mi. | B24: 45735 | C24: 0 | D24: 0 | E24: 0 | F24: 0 | G24: =(F24*24-E24*24)+(D24*24-C24*24) -> 0 | H24: =+$H$3*24 -> 0.5 | I24: =+$I$3*24 -> 8 | J24: =G24-I24-H24 -> -8.5
A25: Ju. | B25: 45736 | C25: 0 | D25: 0 | E25: 0 | F25: 0 | G25: =(F25*24-E25*24)+(D25*24-C25*24) -> 0 | H25: =+$H$3*24 -> 0.5 | I25: =+$I$3*24 -> 8 | J25: =G25-I25-H25 -> -8.5
A26: Vi. | B26: 45737 | C26: 0 | D26: 0 | E26: 0 | F26: 0 | G26: =(F26*24-E26*24)+(D26*24-C26*24) -> 0 | H26: =+$H$3*24 -> 0.5 | I26: =+$I$3*24 -> 8 | J26: =G26-I26-H26 -> -8.5
A27: Sá. | B27: 45738 | C27: 0 | D27: 0 | E27: 0 | F27: 0 | G27: =(F27*24-E27*24)+(D27*24-C27*24) -> 0 | H27: 0 | I27: 0 | K27: =G27-I27+H27 -> 0
A28: Do. | B28: 45739 | C28: 0 | D28: 0 | E28: 0 | F28: 0 | G28: =(F28*24-E28*24)+(D28*24-C28*24) -> 0 | H28: 0 | I28: 0 | K28: =G28-I28+H28 -> 0
A29: Lu. | B29: 45740 | C29: 0 | D29: 0 | E29: 0 | F29: 0 | G29: =(F29*24-E29*24)+(D29*24-C29*24) -> 0 | H29: =+$H$3*24 -> 0.5 | I29: =+$I$3*24 -> 8 | J29: =G29-I29-H29 -> -8.5
A30: Ma. | B30: 45741 | C30: 0 | D30: 0 | E30: 0 | F30: 0 | G30: =(F30*24-E30*24)+(D30*24-C30*24) -> 0 | H30: =+$H$3*24 -> 0.5 | I30: =+$I$3*24 -> 8 | J30: =G30-I30-H30 -> -8.5
A31: Mi. | B31: 45742 | C31: 0 | D31: 0 | E31: 0 | F31: 0 | G31: =(F31*24-E31*24)+(D31*24-C31*24) -> 0 | H31: =+$H$3*24 -> 0.5 | I31: =+$I$3*24 -> 8 | J31: =G31-I31-H31 -> -8.5
A32: Ju. | B32: 45743 | C32: 0 | D32: 0 | E32: 0 | F32: 0 | G32: =(F32*24-E32*24)+(D32*24-C32*24) -> 0 | H32: =+$H$3*24 -> 0.5 | I32: =+$I$3*24 -> 8 | J32: =G32-I32-H32 -> -8.5
A33: Vi. | B33: 45744 | C33: 0 | D33: 0 | E33: 0 | F33: 0 | G33: =(F33*24-E33*24)+(D33*24-C33*24) -> 0 | H33: =+$H$3*24 -> 0.5 | I33: =+$I$3*24 -> 8 | J33: =G33-I33-H33 -> -8.5
A34: Sá. | B34: 45745 | C34: 0 | D34: 0 | E34: 0 | F34: 0 | G34: =(F34*24-E34*24)+(D34*24-C34*24) -> 0 | H34: 0 | I34: 0 | K34: =G34-I34+H34 -> 0
A35: Do. | B35: 45746 | C35: 0 | D35: 0 | E35: 0 | F35: 0 | G35: =(F35*24-E35*24)+(D35*24-C35*24) -> 0 | H35: 0 | I35: 0 | K35: =G35-I35+H35 -> 0
A36: Lu. | B36: 45747 | C36: 0 | D36: 0 | E36: 0 | F36: 0 | G36: =(F36*24-E36*24)+(D36*24-C36*24) -> 0 | H36: =+$H$3*24 -> 0.5 | I36: =+$I$3*24 -> 8 | J36: =G36-I36-H36 -> -8.5
G38: =SUM(G6:G36) -> 0 | H38: =SUM(H6:H36) -> 10.5 | I38: =SUM(I6:I36) -> 168 | J38: =SUM(J6:J36) -> -178.5 | K38: =SUM(K6:K36) -> 0

Sheet ABRIL
N1: 9 | O1: 10
C2: TRABAJADOR | F2: MES | M2: =+M5 -> dietas | N2: H. EXT. | O2: H.S/D EXT Festivos
C3: =+ENERO!$C$3 -> 0 | F3: Abril | H3: 0.020833333 | I3: 0.33333333 | M3: =SUM(M6:M36) -> 0 | N3: =J37 -> -161.5 | O3: =K37 -> 0
P4: total
B5: FECHAS | C5: ENTRADA | D5: SALIDA | E5: ENTRADA | F5: SALIDA | G5: H.TRAB | H5: DESCONTAR | I5: H.LAB | J5: H. EXT | K5: H EXT Festivos | L5: OBSERVACIONES | M5: dietas | N5: =+N3*N1 -> -1453.5 | O5: =+O3*O1 -> 0 | P5: =+O5+N5 -> -1453.5
A6: Ma. | B6: 45748 | C6: 0 | D6: 0 | E6: 0 | F6: 0 | G6: =(F6*24-E6*24)+(D6*24-C6*24) -> 0 | H6: =+$H$3*24 -> 0.5 | I6: =+$I$3*24 -> 8 | J6: =G6-I6-H6 -> -8.5
A7: Mi. | B7: 45749 | C7: 0 | D7: 0 | E7: 0 | F7: 0 | G7: =(F7*24-E7*24)+(D7*24-C7*24) -> 0 | H7: =+$H$3*24 -> 0.5 | I7: =+$I$3*24 -> 8 | J7: =G7-I7-H7 -> -8.5
A8: Ju. | B8: 45750 | C8: 0 | D8: 0 | E8: 0 | F8: 0 | G8: =(F8*24-E8*24)+(D8*24-C8*24) -> 0 | H8: =+$H$3*24 -> 0.5 | I8: =+$I$3*24 -> 8 | J8: =G8-I8-H8 -> -8.5
A9: Vi. | B9: 45751 | C9: 0 | D9: 0 | E9: 0 | F9: 0 | G9: =(F9*24-E9*24)+(D9*24-C9*24) -> 0 | H9: =+$H$3*24 -> 0.5 | I9: =+$I$3*24 -> 8 | J9: =G9-I9-H9 -> -8.5
A10: Sá. | B10: 45752 | C10: 0 | D10: 0 | E10: 0 | F10: 0 | G10: =(F10*24-E10*24)+(D10*24-C10*24) -> 0 | H10: 0 | I10: 0 | K10: =G10-I10+H10 -> 0
A11: Do. | B11: 45753 | C11: 0 | D11: 0 | E11: 0 | F11: 0 | G11: =(F11*24-E11*24)+(D11*24-C11*24) -> 0 | H11: 0 | I11: 0 | K11: =G11-I11+H11 -> 0
A12: Lu. | B12: 45754 | C12: 0 | D12: 0 | E12: 0 | F12: 0 | G12: =(F12*24-E12*24)+(D12*24-C12*24) -> 0 | H12: =+$H$3*24 -> 0.5 | I12: =+$I$3*24 -> 8 | J12: =G12-I12-H12 -> -8.5
A13: Ma. | B13: 45755 | C13: 0 | D13: 0 | E13: 0 | F13: 0 | G13: =(F13*24-E13*24)+(D13*24-C13*24) -> 0 | H13: =+$H$3*24 -> 0.5 | I13: =+$I$3*24 -> 8 | J13: =G13-I13-H13 -> -8.5
A14: Mi. | B14: 45756 | C14: 0 | D14: 0 | E14: 0 | F14: 0 | G14: =(F14*24-E14*24)+(D14*24-C14*24) -> 0 | H14: =+$H$3*24 -> 0.5 | I14: =+$I$3*24 -> 8 | J14: =G14-I14-H14 -> -8.5
A15: Ju. | B15: 45757 | C15: 0 | D15: 0 | E15: 0 | F15: 0 | G15: =(F15*24-E15*24)+(D15*24-C15*24) -> 0 | H15: =+$H$3*24 -> 0.5 | I15: =+$I$3*24 -> 8 | J15: =G15-I15-H15 -> -8.5
A16: Vi. | B16: 45758 | C16: 0 | D16: 0 | E16: 0 | F16: 0 | G16: =(F16*24-E16*24)+(D16*24-C16*24) -> 0 | H16: =+$H$3*24 -> 0.5 | I16: =+$I$3*24 -> 8 | J16: =G16-I16-H16 -> -8.5
A17: Sá. | B17: 45759 | C17: 0 | D17: 0 | E17: 0 | F17: 0 | G17: =(F17*24-E17*24)+(D17*24-C17*24) -> 0 | H17: 0 | I17: 0 | K17: =G17-I17+H17 -> 0
A18: Do. | B18: 45760 | C18: 0 | D18: 0 | E18: 0 | F18: 0 | G18: =(F18*24-E18*24)+(D18*24-C18*24) -> 0 | H18: 0 | I18: 0 | K18: =G18-I18+H18 -> 0
A19: Lu. | B19: 45761 | C19: 0 | D19: 0 | E19: 0 | F19: 0 | G19: =(F19*24-E19*24)+(D19*24-C19*24) -> 0 | H19: =+$H$3*24 -> 0.5 | I19: =+$I$3*24 -> 8 | J19: =G19-I19-H19 -> -8.5
A20: Ma. | B20: 45762 | C20: 0 | D20: 0 | E20: 0 | F20: 0 | G20: =(F20*24-E20*24)+(D20*24-C20*24) -> 0 | H20: =+$H$3*24 -> 0.5 | I20: =+$I$3*24 -> 8 | J20: =G20-I20-H20 -> -8.5
A21: Mi. | B21: 45763 | C21: 0 | D21: 0 | E21: 0 | F21: 0 | G21: =(F21*24-E21*24)+(D21*24-C21*24) -> 0 | H21: =+$H$3*24 -> 0.5 | I21: =+$I$3*24 -> 8 | J21: =G21-I21-H21 -> -8.5
A22: Ju. | B22: 45764 | C22: 0 | D22: 0 | E22: 0 | F22: 0 | G22: =(F22*24-E22*24)+(D22*24-C22*24) -> 0 | H22: 0 | I22: 0 | K22: =G22-I22+H22 -> 0
A23: Vi. | B23: 45765 | C23: 0 | D23: 0 | E23: 0 | F23: 0 | G23: =(F23*24-E23*24)+(D23*24-C23*24) -> 0 | H23: 0 | I23: 0 | K23: =G23-I23+H23 -> 0
A24: Sá. | B24: 45766 | C24: 0 | D24: 0 | E24: 0 | F24: 0 | G24: =(F24*24-E24*24)+(D24*24-C24*24) -> 0 | H24: 0 | I24: 0 | K24: =G24-I24+H24 -> 0
A25: Do. | B25: 45767 | C25: 0 | D25: 0 | E25: 0 | F25: 0 | G25: =(F25*24-E25*24)+(D25*24-C25*24) -> 0 | H25: 0 | I25: 0 | K25: =G25-I25+H25 -> 0
A26: Lu. | B26: 45768 | C26: 0 | D26: 0 | E26: 0 | F26: 0 | G26: =(F26*24-E26*24)+(D26*24-C26*24) -> 0 | H26: 0 | I26: 0 | K26: =G26-I26+H26 -> 0
A27: Ma. | B27: 45769 | C27: 0 | D27: 0 | E27: 0 | F27: 0 | G27: =(F27*24-E27*24)+(D27*24-C27*24) -> 0 | H27: =+$H$3*24 -> 0.5 | I27: =+$I$3*24 -> 8 | J27: =G27-I27-H27 -> -8.5
A28: Mi. | B28: 45770 | C28: 0 | D28: 0 | E28: 0 | F28: 0 | G28: =(F28*24-E28*24)+(D28*24-C28*24) -> 0 | H28: =+$H$3*24 -> 0.5 | I28: =+$I$3*24 -> 8 | J28: =G28-I28-H28 -> -8.5
A29: Ju. | B29: 45771 | C29: 0 | D29: 0 | E29: 0 | F29: 0 | G29: =(F29*24-E29*24)+(D29*24-C29*24) -> 0 | H29: =+$H$3*24 -> 0.5 | I29: =+$I$3*24 -> 8 | J29: =G29-I29-H29 -> -8.5
A30: Vi. | B30: 45772 | C30: 0 | D30: 0 | E30: 0 | F30: 0 | G30: =(F30*24-E30*24)+(D30*24-C30*24) -> 0 | H30: =+$H$3*24 -> 0.5 | I30: =+$I$3*24 -> 8 | J30: =G30-I30-H30 -> -8.5
A31: Sá. | B31: 45773 | C31: 0 | D31: 0 | E31: 0 | F31: 0 | G31: =(F31*24-E31*24)+(D31*24-C31*24) -> 0 | H31: 0 | I31: 0 | K31: =G31-I31+H31 -> 0
A32: Do. | B32: 45774 | C32: 0 | D32: 0 | E32: 0 | F32: 0 | G32: =(F32*24-E32*24)+(D32*24-C32*24) -> 0 | H32: 0 | I32: 0 | K32: =G32-I32+H32 -> 0
A33: Lu. | B33: 45775 | C33: 0 | D33: 0 | E33: 0 | F33: 0 | G33: =(F33*24-E33*24)+(D33*24-C33*24) -> 0 | H33: =+$H$3*24 -> 0.5 | I33: =+$I$3*24 -> 8 | J33: =G33-I33-H33 -> -8.5
A34: Ma. | B34: 45776 | C34: 0 | D34: 0 | E34: 0 | F34: 0 | G34: =(F34*24-E34*24)+(D34*24-C34*24) -> 0 | H34: =+$H$3*24 -> 0.5 | I34: =+$I$3*24 -> 8 | J34: =G34-I34-H34 -> -8.5
A35: Mi. | B35: 45777 | C35: 0 | D35: 0 | E35: 0 | F35: 0 | G35: =(F35*24-E35*24)+(D35*24-C35*24) -> 0 | H35: =+$H$3*24 -> 0.5 | I35: =+$I$3*24 -> 8 | J35: =G35-I35-H35 -> -8.5
G37: =SUM(G6:G36) -> 0 | H37: =SUM(H6:H36) -> 9.5 | I37: =SUM(I6:I36) -> 152 | J37: =SUM(J6:J36) -> -161.5 | K37: =SUM(K6:K36) -> 0

Sheet MAYO
N1: 9 | O1: 10
C2: TRABAJADOR | F2: MES | N2: H. EXT. | O2: H.S/D EXT Festivos
C3: =+ENERO!$C$3 -> 0 | F3: Mayo | H3: 0.020833333 | I3: 0.33333333 | N3: =J37 -> -178.5 | O3: =K37 -> 0
P4: total
B5: FECHAS | C5: ENTRADA | D5: SALIDA | E5: ENTRADA | F5: SALIDA | G5: H.TRAB | H5: DESCONTAR | I5: H.LAB | J5: H. EXT | K5: H EXT Festivos | L5: OBSERVACIONES | N5: =+N3*N1 -> -1606.5 | O5: =+O3*O1 -> 0 | P5: =+O5+N5 -> -1606.5
A6: Ju. | B6: 45778 | C6: 0 | D6: 0 | E6: 0 | F6: 0 | G6: =(F6*24-E6*24)+(D6*24-C6*24) -> 0 | H6: 0 | I6: 0 | K6: =G6-I6+H6 -> 0
A7: Vi. | B7: 45779 | C7: 0 | D7: 0 | E7: 0 | F7: 0 | G7: =(F7*24-E7*24)+(D7*24-C7*24) -> 0 | H7: =+$H$3*24 -> 0.5 | I7: =+$I$3*24 -> 8 | J7: =G7-I7-H7 -> -8.5
A8: Sá. | B8: 45780 | C8: 0 | D8: 0 | E8: 0 | F8: 0 | G8: =(F8*24-E8*24)+(D8*24-C8*24) -> 0 | H8: 0 | I8: 0 | K8: =G8-I8+H8 -> 0
A9: Do. | B9: 45781 | C9: 0 | D9: 0 | E9: 0 | F9: 0 | G9: =(F9*24-E9*24)+(D9*24-C9*24) -> 0 | H9: 0 | I9: 0 | K9: =G9-I9+H9 -> 0
A10: Lu. | B10: 45782 | C10: 0 | D10: 0 | E10: 0 | F10: 0 | G10: =(F10*24-E10*24)+(D10*24-C10*24) -> 0 | H10: =+$H$3*24 -> 0.5 | I10: =+$I$3*24 -> 8 | J10: =G10-I10-H10 -> -8.5
A11: Ma. | B11: 45783 | C11: 0 | D11: 0 | E11: 0 | F11: 0 | G11: =(F11*24-E11*24)+(D11*24-C11*24) -> 0 | H11: =+$H$3*24 -> 0.5 | I11: =+$I$3*24 -> 8 | J11: =G11-I11-H11 -> -8.5
A12: Mi. | B12: 45784 | C12: 0 | D12: 0 | E12: 0 | F12: 0 | G12: =(F12*24-E12*24)+(D12*24-C12*24) -> 0 | H12: =+$H$3*24 -> 0.5 | I12: =+$I$3*24 -> 8 | J12: =G12-I12-H12 -> -8.5
A13: Ju. | B13: 45785 | C13: 0 | D13: 0 | E13: 0 | F13: 0 | G13: =(F13*24-E13*24)+(D13*24-C13*24) -> 0 | H13: =+$H$3*24 -> 0.5 | I13: =+$I$3*24 -> 8 | J13: =G13-I13-H13 -> -8.5
A14: Vi. | B14: 45786 | C14: 0 | D14: 0 | E14: 0 | F14: 0 | G14: =(F14*24-E14*24)+(D14*24-C14*24) -> 0 | H14: =+$H$3*24 -> 0.5 | I14: =+$I$3*24 -> 8 | J14: =G14-I14-H14 -> -8.5
A15: Sá. | B15: 45787 | C15: 0 | D15: 0 | E15: 0 | F15: 0 | G15: =(F15*24-E15*24)+(D15*24-C15*24) -> 0 | H15: 0 | I15: 0 | K15: =G15-I15+H15 -> 0
A16: Do. | B16: 45788 | C16: 0 | D16: 0 | E16: 0 | F16: 0 | G16: =(F16*24-E16*24)+(D16*24-C16*24) -> 0 | H16: 0 | I16: 0 | K16: =G16-I16+H16 -> 0
A17: Lu. | B17: 45789 | C17: 0 | D17: 0 | E17: 0 | F17: 0 | G17: =(F17*24-E17*24)+(D17*24-C17*24) -> 0 | H17: =+$H$3*24 -> 0.5 | I17: =+$I$3*24 -> 8 | J17: =G17-I17-H17 -> -8.5
A18: Ma. | B18: 45790 | C18: 0 | D18: 0 | E18: 0 | F18: 0 | G18: =(F18*24-E18*24)+(D18*24-C18*24) -> 0 | H18: =+$H$3*24 -> 0.5 | I18: =+$I$3*24 -> 8 | J18: =G18-I18-H18 -> -8.5
A19: Mi. | B19: 45791 | C19: 0 | D19: 0 | E19: 0 | F19: 0 | G19: =(F19*24-E19*24)+(D19*24-C19*24) -> 0 | H19: =+$H$3*24 -> 0.5 | I19: =+$I$3*24 -> 8 | J19: =G19-I19-H19 -> -8.5
A20: Ju. | B20: 45792 | C20: 0 | D20: 0 | E20: 0 | F20: 0 | G20: =(F20*24-E20*24)+(D20*24-C20*24) -> 0 | H20: =+$H$3*24 -> 0.5 | I20: =+$I$3*24 -> 8 | J20: =G20-I20-H20 -> -8.5
A21: Vi. | B21: 45793 | C21: 0 | D21: 0 | E21: 0 | F21: 0 | G21: =(F21*24-E21*24)+(D21*24-C21*24) -> 0 | H21: =+$H$3*24 -> 0.5 | I21: =+$I$3*24 -> 8 | J21: =G21-I21-H21 -> -8.5
A22: Sá. | B22: 45794 | C22: 0 | D22: 0 | E22: 0 | F22: 0 | G22: =(F22*24-E22*24)+(D22*24-C22*24) -> 0 | H22: 0 | I22: 0 | K22: =G22-I22+H22 -> 0
A23: Do. | B23: 45795 | C23: 0 | D23: 0 | E23: 0 | F23: 0 | G23: =(F23*24-E23*24)+(D23*24-C23*24) -> 0 | H23: 0 | I23: 0 | K23: =G23-I23+H23 -> 0
A24: Ma. | B24: 45797 | C24: 0 | D24: 0 | E24: 0 | F24: 0 | G24: =(F24*24-E24*24)+(D24*24-C24*24) -> 0 | H24: =+$H$3*24 -> 0.5 | I24: =+$I$3*24 -> 8 | J24: =G24-I24-H24 -> -8.5
A25: Ma. | B25: 45797 | C25: 0 | D25: 0 | E25: 0 | F25: 0 | G25: =(F25*24-E25*24)+(D25*24-C25*24) -> 0 | H25: =+$H$3*24 -> 0.5 | I25: =+$I$3*24 -> 8 | J25: =G25-I25-H25 -> -8.5
A26: Mi. | B26: 45798 | C26: 0 | D26: 0 | E26: 0 | F26: 0 | G26: =(F26*24-E26*24)+(D26*24-C26*24) -> 0 | H26: =+$H$3*24 -> 0.5 | I26: =+$I$3*24 -> 8 | J26: =G26-I26-H26 -> -8.5
A27: Ju. | B27: 45799 | C27: 0 | D27: 0 | E27: 0 | F27: 0 | G27: =(F27*24-E27*24)+(D27*24-C27*24) -> 0 | H27: =+$H$3*24 -> 0.5 | I27: =+$I$3*24 -> 8 | J27: =G27-I27-H27 -> -8.5
A28: Vi. | B28: 45800 | C28: 0 | D28: 0 | E28: 0 | F28: 0 | G28: =(F28*24-E28*24)+(D28*24-C28*24) -> 0 | H28: =+$H$3*24 -> 0.5 | I28: =+$I$3*24 -> 8 | J28: =G28-I28-H28 -> -8.5
A29: Sá. | B29: 45801 | C29: 0 | D29: 0 | E29: 0 | F29: 0 | G29: =(F29*24-E29*24)+(D29*24-C29*24) -> 0 | H29: 0 | I29: 0 | K29: =G29-I29+H29 -> 0
A30: Do. | B30: 45802 | C30: 0 | D30: 0 | E30: 0 | F30: 0 | G30: =(F30*24-E30*24)+(D30*24-C30*24) -> 0 | H30: 0 | I30: 0 | K30: =G30-I30+H30 -> 0
A31: Lu. | B31: 45803 | C31: 0 | D31: 0 | E31: 0 | F31: 0 | G31: =(F31*24-E31*24)+(D31*24-C31*24) -> 0 | H31: =+$H$3*24 -> 0.5 | I31: =+$I$3*24 -> 8 | J31: =G31-I31-H31 -> -8.5
A32: Ma. | B32: 45804 | C32: 0 | D32: 0 | E32: 0 | F32: 0 | G32: =(F32*24-E32*24)+(D32*24-C32*24) -> 0 | H32: =+$H$3*24 -> 0.5 | I32: =+$I$3*24 -> 8 | J32: =G32-I32-H32 -> -8.5
A33: Mi. | B33: 45805 | C33: 0 | D33: 0 | E33: 0 | F33: 0 | G33: =(F33*24-E33*24)+(D33*24-C33*24) -> 0 | H33: =+$H$3*24 -> 0.5 | I33: =+$I$3*24 -> 8 | J33: =G33-I33-H33 -> -8.5
A34: Ju. | B34: 45806 | C34: 0 | D34: 0 | E34: 0 | F34: 0 | G34: =(F34*24-E34*24)+(D34*24-C34*24) -> 0 | H34: =+$H$3*24 -> 0.5 | I34: =+$I$3*24 -> 8 | J34: =G34-I34-H34 -> -8.5
A35: Vi. | B35: 45807 | C35: 0 | D35: 0 | E35: 0 | F35: 0 | G35: =(F35*24-E35*24)+(D35*24-C35*24) -> 0 | H35: =+$H$3*24 -> 0.5 | I35: =+$I$3*24 -> 8 | J35: =G35-I35-H35 -> -8.5
A36: Sá. | B36: 45808 | C36: 0 | D36: 0 | E36: 0 | F36: 0 | G36: =(F36*24-E36*24)+(D36*24-C36*24) -> 0 | H36: 0 | I36: 0 | K36: =G36-I36+H36 -> 0
G37: =SUM(G6:G36) -> 0 | H37: =SUM(H6:H36) -> 10.5 | I37: =SUM(I6:I36) -> 168 | J37: =SUM(J6:J36) -> -178.5 | K37: =SUM(K6:K36) -> 0

Sheet JUNIO
N1: 9 | O1: 10
C2: TRABAJADOR | F2: MES | N2: H. EXT. | O2: H.S/D EXT Festivos
C3: =+ENERO!$C$3 -> 0 | F3: Junio | H3: 0.020833333 | I3: 0.33333333 | N3: =J37 -> 0 | O3: =K37 -> 0
P4: total
B5: FECHAS | C5: ENTRADA | D5: SALIDA | E5: ENTRADA | F5: SALIDA | G5: H.TRAB | H5: DESCONTAR | I5: H.LAB | J5: H. EXT | K5: H EXT Festivos | L5: OBSERVACIONES | N5: =+N3*N1 -> 0 | O5: =+O3*O1 -> 0 | P5: =+O5+N5 -> 0
A6: Do. | B6: 45809 | C6: 0 | D6: 0 | E6: 0 | F6: 0 | G6: =(F6*24-E6*24)+(D6*24-C6*24) -> 0 | H6: 0 | I6: 0 | K6: =G6-I6+H6 -> 0
A7: Lu. | B7: 45810 | C7: 0 | D7: 0 | E7: 0 | F7: 0 | G7: =(F7*24-E7*24)+(D7*24-C7*24) -> 0 | H7: =+$H$3*24 -> 0.5 | I7: =+$I$3*24 -> 8 | J7: =G7-I7-H7 -> -8.5
A8: Ma. | B8: 45811 | C8: 0 | D8: 0 | E8: 0 | F8: 0 | G8: =(F8*24-E8*24)+(D8*24-C8*24) -> 0 | H8: =+$H$3*24 -> 0.5 | I8: =+$I$3*24 -> 8 | J8: =G8-I8-H8 -> -8.5
A9: Mi. | B9: 45812 | C9: 0 | D9: 0 | E9: 0 | F9: 0 | G9: =(F9*24-E9*24)+(D9*24-C9*24) -> 0 | H9: =+$H$3*24 -> 0.5 | I9: =+$I$3*24 -> 8 | J9: =G9-I9-H9 -> -8.5
A10: Ju. | B10: 45813 | C10: 0 | D10: 0 | E10: 0 | F10: 0 | G10: =(F10*24-E10*24)+(D10*24-C10*24) -> 0 | H10: =+$H$3*24 -> 0.5 | I10: =+$I$3*24 -> 8 | J10: =G10-I10-H10 -> -8.5
A11: Vi. | B11: 45814 | C11: 0 | D11: 0 | E11: 0 | F11: 0 | G11: =(F11*24-E11*24)+(D11*24-C11*24) -> 0 | H11: =+$H$3*24 -> 0.5 | I11: =+$I$3*24 -> 8 | J11: =G11-I11-H11 -> -8.5
A12: Sá. | B12: 45815 | C12: 0 | D12: 0 | E12: 0 | F12: 0 | G12: =(F12*24-E12*24)+(D12*24-C12*24) -> 0 | H12: 0 | I12: 0 | K12: =G12-I12+H12 -> 0
A13: Do. | B13: 45816 | C13: 0 | D13: 0 | E13: 0 | F13: 0 | G13: =(F13*24-E13*24)+(D13*24-C13*24) -> 0 | H13: 0 | I13: 0 | K13: =G13-I13+H13 -> 0
A14: Lu. | B14: 45817 | C14: 0 | D14: 0 | E14: 0 | F14: 0 | G14: =(F14*24-E14*24)+(D14*24-C14*24) -> 0 | H14: =+$H$3*24 -> 0.5 | I14: =+$I$3*24 -> 8 | J14: =G14-I14-H14 -> -8.5
A15: Ma. | B15: 45818 | C15: 0 | D15: 0 | E15: 0 | F15: 0 | G15: =(F15*24-E15*24)+(D15*24-C15*24) -> 0 | H15: =+$H$3*24 -> 0.5 | I15: =+$I$3*24 -> 8 | J15: =G15-I15-H15 -> -8.5
A16: Mi. | B16: 45819 | C16: 0 | D16: 0 | E16: 0 | F16: 0 | G16: =(F16*24-E16*24)+(D16*24-C16*24) -> 0 | H16: =+$H$3*24 -> 0.5 | I16: =+$I$3*24 -> 8 | J16: =G16-I16-H16 -> -8.5
A17: Ju. | B17: 45820 | C17: 0 | D17: 0 | E17: 0 | F17: 0 | G17: =(F17*24-E17*24)+(D17*24-C17*24) -> 0 | H17: =+$H$3*24 -> 0.5 | I17: =+$I$3*24 -> 8 | J17: =G17-I17-H17 -> -8.5
A18: Vi. | B18: 45821 | C18: 0 | D18: 0 | E18: 0 | F18: 0 | G18: =(F18*24-E18*24)+(D18*24-C18*24) -> 0 | H18: =+$H$3*24 -> 0.5 | I18: =+$I$3*24 -> 8 | J18: =G18-I18-H18 -> -8.5
A19: Sá. | B19: 45822 | C19: 0 | D19: 0 | E19: 0 | F19: 0 | G19: =(F19*24-E19*24)+(D19*24-C19*24) -> 0 | H19: 0 | I19: 0 | K19: =G19-I19+H19 -> 0
A20: Do. | B20: 45823 | C20: 0 | D20: 0 | E20: 0 | F20: 0 | G20: =(F20*24-E20*24)+(D20*24-C20*24) -> 0 | H20: 0 | I20: 0 | K20: =G20-I20+H20 -> 0
A21: Lu. | B21: 45824 | C21: 0 | D21: 0 | E21: 0 | F21: 0 | G21: =(F21*24-E21*24)+(D21*24-C21*24) -> 0 | H21: =+$H$3*24 -> 0.5 | I21: =+$I$3*24 -> 8 | J21: =G21-I21-H21 -> -8.5
A22: Ma. | B22: 45825 | C22: 0 | D22: 0 | E22: 0 | F22: 0 | G22: =(F22*24-E22*24)+(D22*24-C22*24) -> 0 | H22: =+$H$3*24 -> 0.5 | I22: =+$I$3*24 -> 8 | J22: =G22-I22-H22 -> -8.5
A23: Mi. | B23: 45826 | C23: 0 | D23: 0 | E23: 0 | F23: 0 | G23: =(F23*24-E23*24)+(D23*24-C23*24) -> 0 | H23: =+$H$3*24 -> 0.5 | I23: =+$I$3*24 -> 8 | J23: =G23-I23-H23 -> -8.5
A24: Ju. | B24: 45827 | C24: 0 | D24: 0 | E24: 0 | F24: 0 | G24: =(F24*24-E24*24)+(D24*24-C24*24) -> 0 | H24: =+$H$3*24 -> 0.5 | I24: =+$I$3*24 -> 8 | J24: =G24-I24-H24 -> -8.5
A25: Vi. | B25: 45828 | C25: 0 | D25: 0 | E25: 0 | F25: 0 | G25: =(F25*24-E25*24)+(D25*24-C25*24) -> 0 | H25: =+$H$3*24 -> 0.5 | I25: =+$I$3*24 -> 8 | J25: =G25-I25-H25 -> -8.5
A26: Sá. | B26: 45829 | C26: 0 | D26: 0 | E26: 0 | F26: 0 | G26: =(F26*24-E26*24)+(D26*24-C26*24) -> 0 | H26: 0 | I26: 0 | K26: =G26-I26+H26 -> 0
A27: Do. | B27: 45830 | C27: 0 | D27: 0 | E27: 0 | F27: 0 | G27: =(F27*24-E27*24)+(D27*24-C27*24) -> 0 | H27: 0 | I27: 0 | K27: =G27-I27+H27 -> 0
A28: Lu. | B28: 45831 | C28: 0 | D28: 0 | E28: 0 | F28: 0 | G28: =(F28*24-E28*24)+(D28*24-C28*24) -> 0 | H28: =+$H$3*24 -> 0.5 | I28: =+$I$3*24 -> 8 | J28: =G28-I28-H28 -> -8.5
A29: Ma. | B29: 45832 | C29: 0 | D29: 0 | E29: 0 | F29: 0 | G29: =(F29*24-E29*24)+(D29*24-C29*24) -> 0 | H29: =+$H$3*24 -> 0.5 | I29: =+$I$3*24 -> 8 | J29: =G29-I29-H29 -> -8.5
A30: Mi. | B30: 45833 | C30: 0 | D30: 0 | E30: 0 | F30: 0 | G30: =(F30*24-E30*24)+(D30*24-C30*24) -> 0 | H30: =+$H$3*24 -> 0.5 | I30: =+$I$3*24 -> 8 | J30: =G30-I30-H30 -> -8.5
A31: Ju. | B31: 45834 | C31: 0 | D31: 0 | E31: 0 | F31: 0 | G31: =(F31*24-E31*24)+(D31*24-C31*24) -> 0 | H31: =+$H$3*24 -> 0.5 | I31: =+$I$3*24 -> 8 | J31: =G31-I31-H31 -> -8.5
A32: Vi. | B32: 45835 | C32: 0 | D32: 0 | E32: 0 | F32: 0 | G32: =(F32*24-E32*24)+(D32*24-C32*24) -> 0 | H32: =+$H$3*24 -> 0.5 | I32: =+$I$3*24 -> 8 | J32: =G32-I32-H32 -> -8.5
A33: Sá. | B33: 45836 | C33: 0 | D33: 0 | E33: 0 | F33: 0 | G33: =(F33*24-E33*24)+(D33*24-C33*24) -> 0 | H33: 0 | I33: 0 | K33: =G33-I33+H33 -> 0
A34: Do. | B34: 45837 | C34: 0 | D34: 0 | E34: 0 | F34: 0 | G34: =(F34*24-E34*24)+(D34*24-C34*24) -> 0 | H34: 0 | I34: 0 | K34: =G34-I34+H34 -> 0
A35: Lu. | B35: 45838 | C35: 0 | D35: 0 | E35: 0 | F35: 0 | G35: =(F35*24-E35*24)+(D35*24-C35*24) -> 0 | H35: =+$H$3*24 -> 0.5 | I35: =+$I$3*24 -> 8 | J35: =G35-I35-H35 -> -8.5
G36: =SUM(G6:G35) -> 0 | H36: =SUM(H6:H35) -> 10.5 | I36: =SUM(I6:I35) -> 168 | J36: =SUM(J6:J35) -> -178.5 | K36: =SUM(K6:K35) -> 0

Sheet JULIO
N1: 9 | O1: 10
C2: TRABAJADOR | F2: MES | N2: H. EXT. | O2: H.S/D EXT Festivos
C3: =+ENERO!$C$3 -> 0 | F3: Julio | H3: 0.020833333 | I3: 0.33333333 | N3: =J37 -> -187 | O3: =K37 -> 0
P4: total
B5: FECHAS | C5: ENTRADA | D5: SALIDA | E5: ENTRADA | F5: SALIDA | G5: H.TRAB | H5: DESCONTAR | I5: H.LAB | J5: H. EXT | K5: H EXT Festivos | L5: OBSERVACIONES | N5: =+N3*N1 -> -1683 | O5: =+O3*O1 -> 0 | P5: =+O5+N5 -> -1683
A6: Ma. | B6: 45839 | C6: 0 | D6: 0 | E6: 0 | F6: 0 | G6: =(F6*24-E6*24)+(D6*24-C6*24) -> 0 | H6: =+$H$3*24 -> 0.5 | I6: =+$I$3*24 -> 8 | J6: =G6-I6-H6 -> -8.5
A7: Mi. | B7: 45840 | C7: 0 | D7: 0 | E7: 0 | F7: 0 | G7: =(F7*24-E7*24)+(D7*24-C7*24) -> 0 | H7: =+$H$3*24 -> 0.5 | I7: =+$I$3*24 -> 8 | J7: =G7-I7-H7 -> -8.5
A8: Ju. | B8: 45841 | C8: 0 | D8: 0 | E8: 0 | F8: 0 | G8: =(F8*24-E8*24)+(D8*24-C8*24) -> 0 | H8: =+$H$3*24 -> 0.5 | I8: =+$I$3*24 -> 8 | J8: =G8-I8-H8 -> -8.5
A9: Vi. | B9: 45842 | C9: 0 | D9: 0 | E9: 0 | F9: 0 | G9: =(F9*24-E9*24)+(D9*24-C9*24) -> 0 | H9: =+$H$3*24 -> 0.5 | I9: =+$I$3*24 -> 8 | J9: =G9-I9-H9 -> -8.5
A10: Sá. | B10: 45843 | C10: 0 | D10: 0 | E10: 0 | F10: 0 | G10: =(F10*24-E10*24)+(D10*24-C10*24) -> 0 | H10: 0 | I10: 0 | K10: =G10-I10+H10 -> 0
A11: Do. | B11: 45844 | C11: 0 | D11: 0 | E11: 0 | F11: 0 | G11: =(F11*24-E11*24)+(D11*24-C11*24) -> 0 | H11: 0 | I11: 0 | K11: =G11-I11+H11 -> 0
A12: Lu. | B12: 45845 | C12: 0 | D12: 0 | E12: 0 | F12: 0 | G12: =(F12*24-E12*24)+(D12*24-C12*24) -> 0 | H12: =+$H$3*24 -> 0.5 | I12: =+$I$3*24 -> 8 | J12: =G12-I12-H12 -> -8.5
A13: Ma. | B13: 45846 | C13: 0 | D13: 0 | E13: 0 | F13: 0 | G13: =(F13*24-E13*24)+(D13*24-C13*24) -> 0 | H13: =+$H$3*24 -> 0.5 | I13: =+$I$3*24 -> 8 | J13: =G13-I13-H13 -> -8.5
A14: Mi. | B14: 45847 | C14: 0 | D14: 0 | E14: 0 | F14: 0 | G14: =(F14*24-E14*24)+(D14*24-C14*24) -> 0 | H14: =+$H$3*24 -> 0.5 | I14: =+$I$3*24 -> 8 | J14: =G14-I14-H14 -> -8.5
A15: Ju. | B15: 45848 | C15: 0 | D15: 0 | E15: 0 | F15: 0 | G15: =(F15*24-E15*24)+(D15*24-C15*24) -> 0 | H15: =+$H$3*24 -> 0.5 | I15: =+$I$3*24 -> 8 | J15: =G15-I15-H15 -> -8.5
A16: Vi. | B16: 45849 | C16: 0 | D16: 0 | E16: 0 | F16: 0 | G16: =(F16*24-E16*24)+(D16*24-C16*24) -> 0 | H16: =+$H$3*24 -> 0.5 | I16: =+$I$3*24 -> 8 | J16: =G16-I16-H16 -> -8.5
A17: Sá. | B17: 45850 | C17: 0 | D17: 0 | E17: 0 | F17: 0 | G17: =(F17*24-E17*24)+(D17*24-C17*24) -> 0 | H17: 0 | I17: 0 | K17: =G17-I17+H17 -> 0
A18: Do. | B18: 45851 | C18: 0 | D18: 0 | E18: 0 | F18: 0 | G18: =(F18*24-E18*24)+(D18*24-C18*24) -> 0 | H18: 0 | I18: 0 | K18: =G18-I18+H18 -> 0
A19: Lu. | B19: 45852 | C19: 0 | D19: 0 | E19: 0 | F19: 0 | G19: =(F19*24-E19*24)+(D19*24-C19*24) -> 0 | H19: =+$H$3*24 -> 0.5 | I19: =+$I$3*24 -> 8 | J19: =G19-I19-H19 -> -8.5
A20: Ma. | B20: 45853 | C20: 0 | D20: 0 | E20: 0 | F20: 0 | G20: =(F20*24-E20*24)+(D20*24-C20*24) -> 0 | H20: =+$H$3*24 -> 0.5 | I20: =+$I$3*24 -> 8 | J20: =G20-I20-H20 -> -8.5
A21: Mi. | B21: 45854 | C21: 0 | D21: 0 | E21: 0 | F21: 0 | G21: =(F21*24-E21*24)+(D21*24-C21*24) -> 0 | H21: =+$H$3*24 -> 0.5 | I21: =+$I$3*24 -> 8 | J21: =G21-I21-H21 -> -8.5
A22: Ju. | B22: 45855 | C22: 0 | D22: 0 | E22: 0 | F22: 0 | G22: =(F22*24-E22*24)+(D22*24-C22*24) -> 0 | H22: =+$H$3*24 -> 0.5 | I22: =+$I$3*24 -> 8 | J22: =G22-I22-H22 -> -8.5
A23: Vi. | B23: 45856 | C23: 0 | D23: 0 | E23: 0 | F23: 0 | G23: =(F23*24-E23*24)+(D23*24-C23*24) -> 0 | H23: =+$H$3*24 -> 0.5 | I23: =+$I$3*24 -> 8 | J23: =G23-I23-H23 -> -8.5
A24: Sá. | B24: 45857 | C24: 0 | D24: 0 | E24: 0 | F24: 0 | G24: =(F24*24-E24*24)+(D24*24-C24*24) -> 0 | H24: 0 | I24: 0 | K24: =G24-I24+H24 -> 0
A25: Do. | B25: 45858 | C25: 0 | D25: 0 | E25: 0 | F25: 0 | G25: =(F25*24-E25*24)+(D25*24-C25*24) -> 0 | H25: 0 | I25: 0 | K25: =G25-I25+H25 -> 0
A26: Lu. | B26: 45859 | C26: 0 | D26: 0 | E26: 0 | F26: 0 | G26: =(F26*24-E26*24)+(D26*24-C26*24) -> 0 | H26: =+$H$3*24 -> 0.5 | I26: =+$I$3*24 -> 8 | J26: =G26-I26-H26 -> -8.5
A27: Ma. | B27: 45860 | C27: 0 | D27: 0 | E27: 0 | F27: 0 | G27: =(F27*24-E27*24)+(D27*24-C27*24) -> 0 | H27: =+$H$3*24 -> 0.5 | I27: =+$I$3*24 -> 8 | J27: =G27-I27-H27 -> -8.5
A28: Mi. | B28: 45861 | C28: 0 | D28: 0 | E28: 0 | F28: 0 | G28: =(F28*24-E28*24)+(D28*24-C28*24) -> 0 | H28: =+$H$3*24 -> 0.5 | I28: =+$I$3*24 -> 8 | J28: =G28-I28-H28 -> -8.5
A29: Ju. | B29: 45862 | C29: 0 | D29: 0 | E29: 0 | F29: 0 | G29: =(F29*24-E29*24)+(D29*24-C29*24) -> 0 | H29: =+$H$3*24 -> 0.5 | I29: =+$I$3*24 -> 8 | J29: =G29-I29-H29 -> -8.5
A30: Vi. | B30: 45863 | C30: 0 | D30: 0 | E30: 0 | F30: 0 | G30: =(F30*24-E30*24)+(D30*24-C30*24) -> 0 | H30: =+$H$3*24 -> 0.5 | I30: =+$I$3*24 -> 8 | J30: =G30-I30-H30 -> -8.5
A31: Sá. | B31: 45864 | C31: 0 | D31: 0 | E31: 0 | F31: 0 | G31: =(F31*24-E31*24)+(D31*24-C31*24) -> 0 | H31: 0 | I31: 0 | K31: =G31-I31+H31 -> 0
A32: Do. | B32: 45865 | C32: 0 | D32: 0 | E32: 0 | F32: 0 | G32: =(F32*24-E32*24)+(D32*24-C32*24) -> 0 | H32: 0 | I32: 0 | K32: =G32-I32+H32 -> 0
A33: Lu. | B33: 45866 | C33: 0 | D33: 0 | E33: 0 | F33: 0 | G33: =(F33*24-E33*24)+(D33*24-C33*24) -> 0 | H33: =+$H$3*24 -> 0.5 | I33: =+$I$3*24 -> 8 | J33: =G33-I33-H33 -> -8.5
A34: Ma. | B34: 45867 | C34: 0 | D34: 0 | E34: 0 | F34: 0 | G34: =(F34*24-E34*24)+(D34*24-C34*24) -> 0 | H34: =+$H$3*24 -> 0.5 | I34: =+$I$3*24 -> 8 | J34: =G34-I34-H34 -> -8.5
A35: Mi. | B35: 45868 | C35: 0 | D35: 0 | E35: 0 | F35: 0 | G35: =(F35*24-E35*24)+(D35*24-C35*24) -> 0 | H35: =+$H$3*24 -> 0.5 | I35: =+$I$3*24 -> 8 | J35: =G35-I35-H35 -> -8.5
A36: Ju. | B36: 45869 | C36: 0 | D36: 0 | E36: 0 | F36: 0 | G36: =(F36*24-E36*24)+(D36*24-C36*24) -> 0 | H36: =+$H$3*24 -> 0.5 | I36: =+$I$3*24 -> 8 | J36: =G36-I36-H36 -> -8.5
G37: =SUM(G7:G36) -> 0 | H37: =SUM(H7:H36) -> 11 | I37: =SUM(I7:I36) -> 176 | J37: =SUM(J7:J36) -> -187 | K37: =SUM(K7:K36) -> 0

Sheet AGOSTO
N1: 9 | O1: 10
C2: TRABAJADOR | F2: MES | N2: H. EXT. | O2: H.S/D EXT Festivos
C3: =+ENERO!$C$3 -> 0 | F3: Agosto | H3: 0.020833333 | I3: 0.33333333 | N3: =J37 -> -170 | O3: =K37 -> 0
P4: total
B5: FECHAS | C5: ENTRADA | D5: SALIDA | E5: ENTRADA | F5: SALIDA | G5: H.TRAB | H5: DESCONTAR | I5: H.LAB | J5: H. EXT | K5: H EXT Festivos | L5: OBSERVACIONES | N5: =+N3*N1 -> -1530 | O5: =+O3*O1 -> 0 | P5: =+O5+N5 -> -1530
A6: Vi. | B6: 45870 | C6: 0 | D6: 0 | E6: 0 | F6: 0 | G6: =(F6*24-E6*24)+(D6*24-C6*24) -> 0 | H6: =+$H$3*24 -> 0.5 | I6: =+$I$3*24 -> 8 | J6: =G6-I6-H6 -> -8.5
A7: Sá. | B7: 45871 | C7: 0 | D7: 0 | E7: 0 | F7: 0 | G7: =(F7*24-E7*24)+(D7*24-C7*24) -> 0 | H7: 0 | I7: 0 | K7: =G7-I7+H7 -> 0
A8: Do. | B8: 45872 | C8: 0 | D8: 0 | E8: 0 | F8: 0 | G8: =(F8*24-E8*24)+(D8*24-C8*24) -> 0 | H8: 0 | I8: 0 | K8: =G8-I8+H8 -> 0
A9: Lu. | B9: 45873 | C9: 0 | D9: 0 | E9: 0 | F9: 0 | G9: =(F9*24-E9*24)+(D9*24-C9*24) -> 0 | H9: =+$H$3*24 -> 0.5 | I9: =+$I$3*24 -> 8 | J9: =G9-I9-H9 -> -8.5
A10: Ma. | B10: 45874 | C10: 0 | D10: 0 | E10: 0 | F10: 0 | G10: =(F10*24-E10*24)+(D10*24-C10*24) -> 0 | H10: =+$H$3*24 -> 0.5 | I10: =+$I$3*24 -> 8 | J10: =G10-I10-H10 -> -8.5
A11: Mi. | B11: 45875 | C11: 0 | D11: 0 | E11: 0 | F11: 0 | G11: =(F11*24-E11*24)+(D11*24-C11*24) -> 0 | H11: =+$H$3*24 -> 0.5 | I11: =+$I$3*24 -> 8 | J11: =G11-I11-H11 -> -8.5
A12: Ju. | B12: 45876 | C12: 0 | D12: 0 | E12: 0 | F12: 0 | G12: =(F12*24-E12*24)+(D12*24-C12*24) -> 0 | H12: =+$H$3*24 -> 0.5 | I12: =+$I$3*24 -> 8 | J12: =G12-I12-H12 -> -8.5
A13: Vi. | B13: 45877 | C13: 0 | D13: 0 | E13: 0 | F13: 0 | G13: =(F13*24-E13*24)+(D13*24-C13*24) -> 0 | H13: =+$H$3*24 -> 0.5 | I13: =+$I$3*24 -> 8 | J13: =G13-I13-H13 -> -8.5
A14: Sá. | B14: 45878 | C14: 0 | D14: 0 | E14: 0 | F14: 0 | G14: =(F14*24-E14*24)+(D14*24-C14*24) -> 0 | H14: 0 | I14: 0 | K14: =G14-I14+H14 -> 0
A15: Do. | B15: 45879 | C15: 0 | D15: 0 | E15: 0 | F15: 0 | G15: =(F15*24-E15*24)+(D15*24-C15*24) -> 0 | H15: 0 | I15: 0 | K15: =G15-I15+H15 -> 0
A16: Lu. | B16: 45880 | C16: 0 | D16: 0 | E16: 0 | F16: 0 | G16: =(F16*24-E16*24)+(D16*24-C16*24) -> 0 | H16: =+$H$3*24 -> 0.5 | I16: =+$I$3*24 -> 8 | J16: =G16-I16-H16 -> -8.5
A17: Ma. | B17: 45881 | C17: 0 | D17: 0 | E17: 0 | F17: 0 | G17: =(F17*24-E17*24)+(D17*24-C17*24) -> 0 | H17: =+$H$3*24 -> 0.5 | I17: =+$I$3*24 -> 8 | J17: =G17-I17-H17 -> -8.5
A18: Mi. | B18: 45882 | C18: 0 | D18: 0 | E18: 0 | F18: 0 | G18: =(F18*24-E18*24)+(D18*24-C18*24) -> 0 | H18: =+$H$3*24 -> 0.5 | I18: =+$I$3*24 -> 8 | J18: =G18-I18-H18 -> -8.5
A19: Ju. | B19: 45883 | C19: 0 | D19: 0 | E19: 0 | F19: 0 | G19: =(F19*24-E19*24)+(D19*24-C19*24) -> 0 | H19: =+$H$3*24 -> 0.5 | I19: =+$I$3*24 -> 8 | J19: =G19-I19-H19 -> -8.5
A20: Vi. | B20: 45884 | C20: 0 | D20: 0 | E20: 0 | F20: 0 | G20: =(F20*24-E20*24)+(D20*24-C20*24) -> 0 | H20: 0 | I20: 0 | K20: =G20-I20+H20 -> 0
A21: Sá. | B21: 45885 | C21: 0 | D21: 0 | E21: 0 | F21: 0 | G21: =(F21*24-E21*24)+(D21*24-C21*24) -> 0 | H21: 0 | I21: 0 | K21: =G21-I21+H21 -> 0
A22: Do. | B22: 45886 | C22: 0 | D22: 0 | E22: 0 | F22: 0 | G22: =(F22*24-E22*24)+(D22*24-C22*24) -> 0 | H22: 0 | I22: 0 | K22: =G22-I22+H22 -> 0
A23: Lu. | B23: 45887 | C23: 0 | D23: 0 | E23: 0 | F23: 0 | G23: =(F23*24-E23*24)+(D23*24-C23*24) -> 0 | H23: =+$H$3*24 -> 0.5 | I23: =+$I$3*24 -> 8 | J23: =G23-I23-H23 -> -8.5
A24: Ma. | B24: 45888 | C24: 0 | D24: 0 | E24: 0 | F24: 0 | G24: =(F24*24-E24*24)+(D24*24-C24*24) -> 0 | H24: =+$H$3*24 -> 0.5 | I24: =+$I$3*24 -> 8 | J24: =G24-I24-H24 -> -8.5
A25: Mi. | B25: 45889 | C25: 0 | D25: 0 | E25: 0 | F25: 0 | G25: =(F25*24-E25*24)+(D25*24-C25*24) -> 0 | H25: =+$H$3*24 -> 0.5 | I25: =+$I$3*24 -> 8 | J25: =G25-I25-H25 -> -8.5
A26: Ju. | B26: 45890 | C26: 0 | D26: 0 | E26: 0 | F26: 0 | G26: =(F26*24-E26*24)+(D26*24-C26*24) -> 0 | H26: =+$H$3*24 -> 0.5 | I26: =+$I$3*24 -> 8 | J26: =G26-I26-H26 -> -8.5
A27: Vi. | B27: 45891 | C27: 0 | D27: 0 | E27: 0 | F27: 0 | G27: =(F27*24-E27*24)+(D27*24-C27*24) -> 0 | H27: =+$H$3*24 -> 0.5 | I27: =+$I$3*24 -> 8 | J27: =G27-I27-H27 -> -8.5
A28: Sá. | B28: 45892 | C28: 0 | D28: 0 | E28: 0 | F28: 0 | G28: =(F28*24-E28*24)+(D28*24-C28*24) -> 0 | H28: 0 | I28: 0 | K28: =G28-I28+H28 -> 0
A29: Do. | B29: 45893 | C29: 0 | D29: 0 | E29: 0 | F29: 0 | G29: =(F29*24-E29*24)+(D29*24-C29*24) -> 0 | H29: 0 | I29: 0 | K29: =G29-I29+H29 -> 0
A30: Lu. | B30: 45894 | C30: 0 | D30: 0 | E30: 0 | F30: 0 | G30: =(F30*24-E30*24)+(D30*24-C30*24) -> 0 | H30: =+$H$3*24 -> 0.5 | I30: =+$I$3*24 -> 8 | J30: =G30-I30-H30 -> -8.5
A31: Ma. | B31: 45895 | C31: 0 | D31: 0 | E31: 0 | F31: 0 | G31: =(F31*24-E31*24)+(D31*24-C31*24) -> 0 | H31: =+$H$3*24 -> 0.5 | I31: =+$I$3*24 -> 8 | J31: =G31-I31-H31 -> -8.5
A32: Mi. | B32: 45896 | C32: 0 | D32: 0 | E32: 0 | F32: 0 | G32: =(F32*24-E32*24)+(D32*24-C32*24) -> 0 | H32: =+$H$3*24 -> 0.5 | I32: =+$I$3*24 -> 8 | J32: =G32-I32-H32 -> -8.5
A33: Ju. | B33: 45897 | C33: 0 | D33: 0 | E33: 0 | F33: 0 | G33: =(F33*24-E33*24)+(D33*24-C33*24) -> 0 | H33: =+$H$3*24 -> 0.5 | I33: =+$I$3*24 -> 8 | J33: =G33-I33-H33 -> -8.5
A34: Vi. | B34: 45898 | C34: 0 | D34: 0 | E34: 0 | F34: 0 | G34: =(F34*24-E34*24)+(D34*24-C34*24) -> 0 | H34: =+$H$3*24 -> 0.5 | I34: =+$I$3*24 -> 8 | J34: =G34-I34-H34 -> -8.5
A35: Sá. | B35: 45899 | C35: 0 | D35: 0 | E35: 0 | F35: 0 | G35: =(F35*24-E35*24)+(D35*24-C35*24) -> 0 | H35: 0 | I35: 0 | K35: =G35-I35+H35 -> 0
A36: Do. | B36: 45900 | C36: 0 | D36: 0 | E36: 0 | F36: 0 | G36: =(F36*24-E36*24)+(D36*24-C36*24) -> 0 | H36: 0 | I36: 0 | K36: =G36-I36+H36 -> 0
G37: =SUM(G6:G36) -> 0 | H37: =SUM(H6:H36) -> 10 | I37: =SUM(I6:I36) -> 160 | J37: =SUM(J6:J36) -> -170 | K37: =SUM(K6:K36) -> 0

Sheet SEPTIEMBRE
N1: 9 | O1: 10
C2: TRABAJADOR | F2: MES | N2: H. EXT. | O2: H.S/D EXT Festivos
C3: =+ENERO!$C$3 -> 0 | F3: Septiembre | H3: 0.020833333 | I3: 0.33333333 | N3: =+J36 -> -187 | O3: =+K36 -> 0
P4: total
B5: FECHAS | C5: ENTRADA | D5: SALIDA | E5: ENTRADA | F5: SALIDA | G5: H.TRAB | H5: DESCONTAR | I5: H.LAB | J5: H. EXT | K5: H EXT Festivos | L5: OBSERVACIONES | N5: =+N3*N1 -> -1683 | O5: =+O3*O1 -> 0 | P5: =+O5+N5 -> -1683
A6: Lu. | B6: 45901 | C6: 0 | D6: 0 | E6: 0 | F6: 0 | G6: =(F6*24-E6*24)+(D6*24-C6*24) -> 0 | H6: =+$H$3*24 -> 0.5 | I6: =+$I$3*24 -> 8 | J6: =G6-I6-H6 -> -8.5
A7: Ma. | B7: 45902 | C7: 0 | D7: 0 | E7: 0 | F7: 0 | G7: =(F7*24-E7*24)+(D7*24-C7*24) -> 0 | H7: =+$H$3*24 -> 0.5 | I7: =+$I$3*24 -> 8 | J7: =G7-I7-H7 -> -8.5
A8: Mi. | B8: 45903 | C8: 0 | D8: 0 | E8: 0 | F8: 0 | G8: =(F8*24-E8*24)+(D8*24-C8*24) -> 0 | H8: =+$H$3*24 -> 0.5 | I8: =+$I$3*24 -> 8 | J8: =G8-I8-H8 -> -8.5
A9: Ju. | B9: 45904 | C9: 0 | D9: 0 | E9: 0 | F9: 0 | G9: =(F9*24-E9*24)+(D9*24-C9*24) -> 0 | H9: =+$H$3*24 -> 0.5 | I9: =+$I$3*24 -> 8 | J9: =G9-I9-H9 -> -8.5
A10: Vi. | B10: 45905 | C10: 0 | D10: 0 | E10: 0 | F10: 0 | G10: =(F10*24-E10*24)+(D10*24-C10*24) -> 0 | H10: =+$H$3*24 -> 0.5 | I10: =+$I$3*24 -> 8 | J10: =G10-I10-H10 -> -8.5
A11: Sá. | B11: 45906 | C11: 0 | D11: 0 | E11: 0 | F11: 0 | G11: =(F11*24-E11*24)+(D11*24-C11*24) -> 0 | H11: 0 | I11: 0 | K11: =G11-I11+H11 -> 0
A12: Do. | B12: 45907 | C12: 0 | D12: 0 | E12: 0 | F12: 0 | G12: =(F12*24-E12*24)+(D12*24-C12*24) -> 0 | H12: 0 | I12: 0 | K12: =G12-I12+H12 -> 0
A13: Lu. | B13: 45908 | C13: 0 | D13: 0 | E13: 0 | F13: 0 | G13: =(F13*24-E13*24)+(D13*24-C13*24) -> 0 | H13: =+$H$3*24 -> 0.5 | I13: =+$I$3*24 -> 8 | J13: =G13-I13-H13 -> -8.5
A14: Ma. | B14: 45909 | C14: 0 | D14: 0 | E14: 0 | F14: 0 | G14: =(F14*24-E14*24)+(D14*24-C14*24) -> 0 | H14: =+$H$3*24 -> 0.5 | I14: =+$I$3*24 -> 8 | J14: =G14-I14-H14 -> -8.5
A15: Mi. | B15: 45910 | C15: 0 | D15: 0 | E15: 0 | F15: 0 | G15: =(F15*24-E15*24)+(D15*24-C15*24) -> 0 | H15: =+$H$3*24 -> 0.5 | I15: =+$I$3*24 -> 8 | J15: =G15-I15-H15 -> -8.5
A16: Ju. | B16: 45911 | C16: 0 | D16: 0 | E16: 0 | F16: 0 | G16: =(F16*24-E16*24)+(D16*24-C16*24) -> 0 | H16: =+$H$3*24 -> 0.5 | I16: =+$I$3*24 -> 8 | J16: =G16-I16-H16 -> -8.5
A17: Vi. | B17: 45912 | C17: 0 | D17: 0 | E17: 0 | F17: 0 | G17: =(F17*24-E17*24)+(D17*24-C17*24) -> 0 | H17: =+$H$3*24 -> 0.5 | I17: =+$I$3*24 -> 8 | J17: =G17-I17-H17 -> -8.5
A18: Sá. | B18: 45913 | C18: 0 | D18: 0 | E18: 0 | F18: 0 | G18: =(F18*24-E18*24)+(D18*24-C18*24) -> 0 | H18: 0 | I18: 0 | K18: =G18-I18+H18 -> 0
A19: Do. | B19: 45914 | C19: 0 | D19: 0 | E19: 0 | F19: 0 | G19: =(F19*24-E19*24)+(D19*24-C19*24) -> 0 | H19: 0 | I19: 0 | K19: =G19-I19+H19 -> 0
A20: Lu. | B20: 45915 | C20: 0 | D20: 0 | E20: 0 | F20: 0 | G20: =(F20*24-E20*24)+(D20*24-C20*24) -> 0 | H20: =+$H$3*24 -> 0.5 | I20: =+$I$3*24 -> 8 | J20: =G20-I20-H20 -> -8.5
A21: Ma. | B21: 45916 | C21: 0 | D21: 0 | E21: 0 | F21: 0 | G21: =(F21*24-E21*24)+(D21*24-C21*24) -> 0 | H21: =+$H$3*24 -> 0.5 | I21: =+$I$3*24 -> 8 | J21: =G21-I21-H21 -> -8.5
A22: Mi. | B22: 45917 | C22: 0 | D22: 0 | E22: 0 | F22: 0 | G22: =(F22*24-E22*24)+(D22*24-C22*24) -> 0 | H22: =+$H$3*24 -> 0.5 | I22: =+$I$3*24 -> 8 | J22: =G22-I22-H22 -> -8.5
A23: Ju. | B23: 45918 | C23: 0 | D23: 0 | E23: 0 | F23: 0 | G23: =(F23*24-E23*24)+(D23*24-C23*24) -> 0 | H23: =+$H$3*24 -> 0.5 | I23: =+$I$3*24 -> 8 | J23: =G23-I23-H23 -> -8.5
A24: Vi. | B24: 45919 | C24: 0 | D24: 0 | E24: 0 | F24: 0 | G24: =(F24*24-E24*24)+(D24*24-C24*24) -> 0 | H24: =+$H$3*24 -> 0.5 | I24: =+$I$3*24 -> 8 | J24: =G24-I24-H24 -> -8.5
A25: Sá. | B25: 45920 | C25: 0 | D25: 0 | E25: 0 | F25: 0 | G25: =(F25*24-E25*24)+(D25*24-C25*24) -> 0 | H25: 0 | I25: 0 | K25: =G25-I25+H25 -> 0
A26: Do. | B26: 45921 | C26: 0 | D26: 0 | E26: 0 | F26: 0 | G26: =(F26*24-E26*24)+(D26*24-C26*24) -> 0 | H26: 0 | I26: 0 | K26: =G26-I26+H26 -> 0
A27: Lu. | B27: 45922 | C27: 0 | D27: 0 | E27: 0 | F27: 0 | G27: =(F27*24-E27*24)+(D27*24-C27*24) -> 0 | H27: =+$H$3*24 -> 0.5 | I27: =+$I$3*24 -> 8 | J27: =G27-I27-H27 -> -8.5
A28: Ma. | B28: 45923 | C28: 0 | D28: 0 | E28: 0 | F28: 0 | G28: =(F28*24-E28*24)+(D28*24-C28*24) -> 0 | H28: =+$H$3*24 -> 0.5 | I28: =+$I$3*24 -> 8 | J28: =G28-I28-H28 -> -8.5
A29: Mi. | B29: 45924 | C29: 0 | D29: 0 | E29: 0 | F29: 0 | G29: =(F29*24-E29*24)+(D29*24-C29*24) -> 0 | H29: =+$H$3*24 -> 0.5 | I29: =+$I$3*24 -> 8 | J29: =G29-I29-H29 -> -8.5
A30: Ju. | B30: 45925 | C30: 0 | D30: 0 | E30: 0 | F30: 0 | G30: =(F30*24-E30*24)+(D30*24-C30*24) -> 0 | H30: =+$H$3*24 -> 0.5 | I30: =+$I$3*24 -> 8 | J30: =G30-I30-H30 -> -8.5
A31: Vi. | B31: 45926 | C31: 0 | D31: 0 | E31: 0 | F31: 0 | G31: =(F31*24-E31*24)+(D31*24-C31*24) -> 0 | H31: =+$H$3*24 -> 0.5 | I31: =+$I$3*24 -> 8 | J31: =G31-I31-H31 -> -8.5
A32: Sá. | B32: 45927 | C32: 0 | D32: 0 | E32: 0 | F32: 0 | G32: =(F32*24-E32*24)+(D32*24-C32*24) -> 0 | H32: 0 | I32: 0 | K32: =G32-I32+H32 -> 0
A33: Do. | B33: 45928 | C33: 0 | D33: 0 | E33: 0 | F33: 0 | G33: =(F33*24-E33*24)+(D33*24-C33*24) -> 0 | H33: 0 | I33: 0 | K33: =G33-I33+H33 -> 0
A34: Lu. | B34: 45929 | C34: 0 | D34: 0 | E34: 0 | F34: 0 | G34: =(F34*24-E34*24)+(D34*24-C34*24) -> 0 | H34: =+$H$3*24 -> 0.5 | I34: =+$I$3*24 -> 8 | J34: =G34-I34-H34 -> -8.5
A35: Mi. | B35: 45930 | C35: 0 | D35: 0 | E35: 0 | F35: 0 | G35: =(F35*24-E35*24)+(D35*24-C35*24) -> 0 | H35: =+$H$3*24 -> 0.5 | I35: =+$I$3*24 -> 8 | J35: =G35-I35-H35 -> -8.5
G36: =SUM(G6:G35) -> 0 | H36: =SUM(H6:H35) -> 11 | I36: =SUM(I6:I35) -> 176 | J36: =SUM(J6:J35) -> -187 | K36: =SUM(K6:K35) -> 0

Sheet OCTUBRE
N1: 9 | O1: 10
C2: TRABAJADOR | F2: MES | N2: H. EXT. | O2: H.S/D EXT Festivos
C3: =+ENERO!$C$3 -> 0 | F3: Octubre | H3: 0.020833333 | I3: 0.33333333 | N3: =J37 -> -195.5 | O3: =K37 -> 0
P4: total
B5: FECHAS | C5: ENTRADA | D5: SALIDA | E5: ENTRADA | F5: SALIDA | G5: H.TRAB | H5: DESCONTAR | I5: H.LAB | J5: H. EXT | K5: H EXT Festivos | L5: OBSERVACIONES | N5: =+N3*N1 -> -1759.5 | O5: =+O3*O1 -> 0 | P5: =+O5+N5 -> -1759.5
A6: Mi. | B6: 45931 | C6: 0 | D6: 0 | E6: 0 | F6: 0 | G6: =(F6*24-E6*24)+(D6*24-C6*24) -> 0 | H6: =+$H$3*24 -> 0.5 | I6: =+$I$3*24 -> 8 | J6: =G6-I6-H6 -> -8.5
A7: Ju. | B7: 45932 | C7: 0 | D7: 0 | E7: 0 | F7: 0 | G7: =(F7*24-E7*24)+(D7*24-C7*24) -> 0 | H7: =+$H$3*24 -> 0.5 | I7: =+$I$3*24 -> 8 | J7: =G7-I7-H7 -> -8.5
A8: Vi. | B8: 45933 | C8: 0 | D8: 0 | E8: 0 | F8: 0 | G8: =(F8*24-E8*24)+(D8*24-C8*24) -> 0 | H8: =+$H$3*24 -> 0.5 | I8: =+$I$3*24 -> 8 | J8: =G8-I8-H8 -> -8.5
A9: Sá. | B9: 45934 | C9: 0 | D9: 0 | E9: 0 | F9: 0 | G9: =(F9*24-E9*24)+(D9*24-C9*24) -> 0 | H9: 0 | I9: 0 | K9: =G9-I9+H9 -> 0
A10: Do. | B10: 45935 | C10: 0 | D10: 0 | E10: 0 | F10: 0 | G10: =(F10*24-E10*24)+(D10*24-C10*24) -> 0 | H10: 0 | I10: 0 | K10: =G10-I10+H10 -> 0
A11: Lu. | B11: 45936 | C11: 0 | D11: 0 | E11: 0 | F11: 0 | G11: =(F11*24-E11*24)+(D11*24-C11*24) -> 0 | H11: =+$H$3*24 -> 0.5 | I11: =+$I$3*24 -> 8 | J11: =G11-I11-H11 -> -8.5
A12: Ma. | B12: 45937 | C12: 0 | D12: 0 | E12: 0 | F12: 0 | G12: =(F12*24-E12*24)+(D12*24-C12*24) -> 0 | H12: =+$H$3*24 -> 0.5 | I12: =+$I$3*24 -> 8 | J12: =G12-I12-H12 -> -8.5
A13: Mi. | B13: 45938 | C13: 0 | D13: 0 | E13: 0 | F13: 0 | G13: =(F13*24-E13*24)+(D13*24-C13*24) -> 0 | H13: =+$H$3*24 -> 0.5 | I13: =+$I$3*24 -> 8 | J13: =G13-I13-H13 -> -8.5
A14: Ju. | B14: 45939 | C14: 0 | D14: 0 | E14: 0 | F14: 0 | G14: =(F14*24-E14*24)+(D14*24-C14*24) -> 0 | H14: =+$H$3*24 -> 0.5 | I14: =+$I$3*24 -> 8 | J14: =G14-I14-H14 -> -8.5
A15: Vi. | B15: 45940 | C15: 0 | D15: 0 | E15: 0 | F15: 0 | G15: =(F15*24-E15*24)+(D15*24-C15*24) -> 0 | H15: =+$H$3*24 -> 0.5 | I15: =+$I$3*24 -> 8 | J15: =G15-I15-H15 -> -8.5
A16: Sá. | B16: 45941 | C16: 0 | D16: 0 | E16: 0 | F16: 0 | G16: =(F16*24-E16*24)+(D16*24-C16*24) -> 0 | H16: 0 | I16: 0 | K16: =G16-I16+H16 -> 0
A17: Do. | B17: 45942 | C17: 0 | D17: 0 | E17: 0 | F17: 0 | G17: =(F17*24-E17*24)+(D17*24-C17*24) -> 0 | H17: 0 | I17: 0 | K17: =G17-I17+H17 -> 0
A18: Lu. | B18: 45943 | C18: 0 | D18: 0 | E18: 0 | F18: 0 | G18: =(F18*24-E18*24)+(D18*24-C18*24) -> 0 | H18: =+$H$3*24 -> 0.5 | I18: =+$I$3*24 -> 8 | J18: =G18-I18-H18 -> -8.5
A19: Ma. | B19: 45944 | C19: 0 | D19: 0 | E19: 0 | F19: 0 | G19: =(F19*24-E19*24)+(D19*24-C19*24) -> 0 | H19: =+$H$3*24 -> 0.5 | I19: =+$I$3*24 -> 8 | J19: =G19-I19-H19 -> -8.5
A20: Mi. | B20: 45945 | C20: 0 | D20: 0 | E20: 0 | F20: 0 | G20: =(F20*24-E20*24)+(D20*24-C20*24) -> 0 | H20: =+$H$3*24 -> 0.5 | I20: =+$I$3*24 -> 8 | J20: =G20-I20-H20 -> -8.5
A21: Ju. | B21: 45946 | C21: 0 | D21: 0 | E21: 0 | F21: 0 | G21: =(F21*24-E21*24)+(D21*24-C21*24) -> 0 | H21: =+$H$3*24 -> 0.5 | I21: =+$I$3*24 -> 8 | J21: =G21-I21-H21 -> -8.5
A22: Vi. | B22: 45947 | C22: 0 | D22: 0 | E22: 0 | F22: 0 | G22: =(F22*24-E22*24)+(D22*24-C22*24) -> 0 | H22: =+$H$3*24 -> 0.5 | I22: =+$I$3*24 -> 8 | J22: =G22-I22-H22 -> -8.5
A23: Sá. | B23: 45948 | C23: 0 | D23: 0 | E23: 0 | F23: 0 | G23: =(F23*24-E23*24)+(D23*24-C23*24) -> 0 | H23: 0 | I23: 0 | K23: =G23-I23+H23 -> 0
A24: Do. | B24: 45949 | C24: 0 | D24: 0 | E24: 0 | F24: 0 | G24: =(F24*24-E24*24)+(D24*24-C24*24) -> 0 | H24: 0 | I24: 0 | K24: =G24-I24+H24 -> 0
A25: Lu. | B25: 45950 | C25: 0 | D25: 0 | E25: 0 | F25: 0 | G25: =(F25*24-E25*24)+(D25*24-C25*24) -> 0 | H25: =+$H$3*24 -> 0.5 | I25: =+$I$3*24 -> 8 | J25: =G25-I25-H25 -> -8.5
A26: Ma. | B26: 45951 | C26: 0 | D26: 0 | E26: 0 | F26: 0 | G26: =(F26*24-E26*24)+(D26*24-C26*24) -> 0 | H26: =+$H$3*24 -> 0.5 | I26: =+$I$3*24 -> 8 | J26: =G26-I26-H26 -> -8.5
A27: Mi. | B27: 45952 | C27: 0 | D27: 0 | E27: 0 | F27: 0 | G27: =(F27*24-E27*24)+(D27*24-C27*24) -> 0 | H27: =+$H$3*24 -> 0.5 | I27: =+$I$3*24 -> 8 | J27: =G27-I27-H27 -> -8.5
A28: Ju. | B28: 45953 | C28: 0 | D28: 0 | E28: 0 | F28: 0 | G28: =(F28*24-E28*24)+(D28*24-C28*24) -> 0 | H28: =+$H$3*24 -> 0.5 | I28: =+$I$3*24 -> 8 | J28: =G28-I28-H28 -> -8.5
A29: Vi. | B29: 45954 | C29: 0 | D29: 0 | E29: 0 | F29: 0 | G29: =(F29*24-E29*24)+(D29*24-C29*24) -> 0 | H29: =+$H$3*24 -> 0.5 | I29: =+$I$3*24 -> 8 | J29: =G29-I29-H29 -> -8.5
A30: Sá. | B30: 45955 | C30: 0 | D30: 0 | E30: 0 | F30: 0 | G30: =(F30*24-E30*24)+(D30*24-C30*24) -> 0 | H30: 0 | I30: 0 | K30: =G30-I30+H30 -> 0
A31: Do. | B31: 45956 | C31: 0 | D31: 0 | E31: 0 | F31: 0 | G31: =(F31*24-E31*24)+(D31*24-C31*24) -> 0 | H31: 0 | I31: 0 | K31: =G31-I31+H31 -> 0
A32: Lu. | B32: 45957 | C32: 0 | D32: 0 | E32: 0 | F32: 0 | G32: =(F32*24-E32*24)+(D32*24-C32*24) -> 0 | H32: =+$H$3*24 -> 0.5 | I32: =+$I$3*24 -> 8 | J32: =G32-I32-H32 -> -8.5
A33: Ma. | B33: 45958 | C33: 0 | D33: 0 | E33: 0 | F33: 0 | G33: =(F33*24-E33*24)+(D33*24-C33*24) -> 0 | H33: =+$H$3*24 -> 0.5 | I33: =+$I$3*24 -> 8 | J33: =G33-I33-H33 -> -8.5
A34: Mi. | B34: 45959 | C34: 0 | D34: 0 | E34: 0 | F34: 0 | G34: =(F34*24-E34*24)+(D34*24-C34*24) -> 0 | H34: =+$H$3*24 -> 0.5 | I34: =+$I$3*24 -> 8 | J34: =G34-I34-H34 -> -8.5
A35: Ju. | B35: 45960 | C35: 0 | D35: 0 | E35: 0 | F35: 0 | G35: =(F35*24-E35*24)+(D35*24-C35*24) -> 0 | H35: =+$H$3*24 -> 0.5 | I35: =+$I$3*24 -> 8 | J35: =G35-I35-H35 -> -8.5
A36: Vi. | B36: 45961 | C36: 0 | D36: 0 | E36: 0 | F36: 0 | G36: =(F36*24-E36*24)+(D36*24-C36*24) -> 0 | H36: =+$H$3*24 -> 0.5 | I36: =+$I$3*24 -> 8 | J36: =G36-I36-H36 -> -8.5
G37: =SUM(G6:G36) -> 0 | H37: =SUM(H6:H36) -> 11.5 | I37: =SUM(I6:I36) -> 184 | J37: =SUM(J6:J36) -> -195.5 | K37: =SUM(K6:K36) -> 0

Sheet NOVIEMBRE
N1: 9 | O1: 10
C2: TRABAJADOR | F2: MES | N2: H. EXT. | O2: H.S/D EXT Festivos
C3: =+ENERO!$C$3 -> 0 | F3: Noviembre | H3: 0.020833333 | I3: 0.33333333 | N3: =J36 -> -170 | O3: =K36 -> 0
P4: total
B5: FECHAS | C5: ENTRADA | D5: SALIDA | E5: ENTRADA | F5: SALIDA | G5: H.TRAB | H5: DESCONTAR | I5: H.LAB | J5: H. EXT | K5: H EXT Festivos | L5: OBSERVACIONES | N5: =+N3*N1 -> -1530 | O5: =+O3*O1 -> 0 | P5: =+O5+N5 -> -1530
A6: Sá. | B6: 45962 | C6: 0 | D6: 0 | E6: 0 | F6: 0 | G6: =(F6*24-E6*24)+(D6*24-C6*24) -> 0 | H6: 0 | I6: 0 | K6: =G6-I6+H6 -> 0
A7: Do. | B7: 45963 | C7: 0 | D7: 0 | E7: 0 | F7: 0 | G7: =(F7*24-E7*24)+(D7*24-C7*24) -> 0 | H7: 0 | I7: 0 | K7: =G7-I7+H7 -> 0
A8: Lu. | B8: 45964 | C8: 0 | D8: 0 | E8: 0 | F8: 0 | G8: =(F8*24-E8*24)+(D8*24-C8*24) -> 0 | H8: =+$H$3*24 -> 0.5 | I8: =+$I$3*24 -> 8 | J8: =G8-I8-H8 -> -8.5
A9: Ma. | B9: 45965 | C9: 0 | D9: 0 | E9: 0 | F9: 0 | G9: =(F9*24-E9*24)+(D9*24-C9*24) -> 0 | H9: =+$H$3*24 -> 0.5 | I9: =+$I$3*24 -> 8 | J9: =G9-I9-H9 -> -8.5
A10: Mi. | B10: 45966 | C10: 0 | D10: 0 | E10: 0 | F10: 0 | G10: =(F10*24-E10*24)+(D10*24-C10*24) -> 0 | H10: =+$H$3*24 -> 0.5 | I10: =+$I$3*24 -> 8 | J10: =G10-I10-H10 -> -8.5
A11: Ju. | B11: 45967 | C11: 0 | D11: 0 | E11: 0 | F11: 0 | G11: =(F11*24-E11*24)+(D11*24-C11*24) -> 0 | H11: =+$H$3*24 -> 0.5 | I11: =+$I$3*24 -> 8 | J11: =G11-I11-H11 -> -8.5
A12: Vi. | B12: 45968 | C12: 0 | D12: 0 | E12: 0 | F12: 0 | G12: =(F12*24-E12*24)+(D12*24-C12*24) -> 0 | H12: =+$H$3*24 -> 0.5 | I12: =+$I$3*24 -> 8 | J12: =G12-I12-H12 -> -8.5
A13: Sá. | B13: 45969 | C13: 0 | D13: 0 | E13: 0 | F13: 0 | G13: =(F13*24-E13*24)+(D13*24-C13*24) -> 0 | H13: 0 | I13: 0 | K13: =G13-I13+H13 -> 0
A14: Do. | B14: 45970 | C14: 0 | D14: 0 | E14: 0 | F14: 0 | G14: =(F14*24-E14*24)+(D14*24-C14*24) -> 0 | H14: 0 | I14: 0 | K14: =G14-I14+H14 -> 0
A15: Lu. | B15: 45971 | C15: 0 | D15: 0 | E15: 0 | F15: 0 | G15: =(F15*24-E15*24)+(D15*24-C15*24) -> 0 | H15: =+$H$3*24 -> 0.5 | I15: =+$I$3*24 -> 8 | J15: =G15-I15-H15 -> -8.5
A16: Ma. | B16: 45972 | C16: 0 | D16: 0 | E16: 0 | F16: 0 | G16: =(F16*24-E16*24)+(D16*24-C16*24) -> 0 | H16: =+$H$3*24 -> 0.5 | I16: =+$I$3*24 -> 8 | J16: =G16-I16-H16 -> -8.5
A17: Mi. | B17: 45973 | C17: 0 | D17: 0 | E17: 0 | F17: 0 | G17: =(F17*24-E17*24)+(D17*24-C17*24) -> 0 | H17: =+$H$3*24 -> 0.5 | I17: =+$I$3*24 -> 8 | J17: =G17-I17-H17 -> -8.5
A18: Ju. | B18: 45974 | C18: 0 | D18: 0 | E18: 0 | F18: 0 | G18: =(F18*24-E18*24)+(D18*24-C18*24) -> 0 | H18: =+$H$3*24 -> 0.5 | I18: =+$I$3*24 -> 8 | J18: =G18-I18-H18 -> -8.5
A19: Vi. | B19: 45975 | C19: 0 | D19: 0 | E19: 0 | F19: 0 | G19: =(F19*24-E19*24)+(D19*24-C19*24) -> 0 | H19: =+$H$3*24 -> 0.5 | I19: =+$I$3*24 -> 8 | J19: =G19-I19-H19 -> -8.5
A20: Sá. | B20: 45976 | C20: 0 | D20: 0 | E20: 0 | F20: 0 | G20: =(F20*24-E20*24)+(D20*24-C20*24) -> 0 | H20: 0 | I20: 0 | K20: =G20-I20+H20 -> 0
A21: Do. | B21: 45977 | C21: 0 | D21: 0 | E21: 0 | F21: 0 | G21: =(F21*24-E21*24)+(D21*24-C21*24) -> 0 | H21: 0 | I21: 0 | K21: =G21-I21+H21 -> 0
A22: Lu. | B22: 45978 | C22: 0 | D22: 0 | E22: 0 | F22: 0 | G22: =(F22*24-E22*24)+(D22*24-C22*24) -> 0 | H22: =+$H$3*24 -> 0.5 | I22: =+$I$3*24 -> 8 | J22: =G22-I22-H22 -> -8.5
A23: Ma. | B23: 45979 | C23: 0 | D23: 0 | E23: 0 | F23: 0 | G23: =(F23*24-E23*24)+(D23*24-C23*24) -> 0 | H23: =+$H$3*24 -> 0.5 | I23: =+$I$3*24 -> 8 | J23: =G23-I23-H23 -> -8.5
A24: Mi. | B24: 45980 | C24: 0 | D24: 0 | E24: 0 | F24: 0 | G24: =(F24*24-E24*24)+(D24*24-C24*24) -> 0 | H24: =+$H$3*24 -> 0.5 | I24: =+$I$3*24 -> 8 | J24: =G24-I24-H24 -> -8.5
A25: Ju. | B25: 45981 | C25: 0 | D25: 0 | E25: 0 | F25: 0 | G25: =(F25*24-E25*24)+(D25*24-C25*24) -> 0 | H25: =+$H$3*24 -> 0.5 | I25: =+$I$3*24 -> 8 | J25: =G25-I25-H25 -> -8.5
A26: Vi. | B26: 45982 | C26: 0 | D26: 0 | E26: 0 | F26: 0 | G26: =(F26*24-E26*24)+(D26*24-C26*24) -> 0 | H26: =+$H$3*24 -> 0.5 | I26: =+$I$3*24 -> 8 | J26: =G26-I26-H26 -> -8.5
