Workbook

Sheet DICIEMBRE 2025
N1: 9 | O1: 10
C2: TRABAJADOR | F2: MES | N2: H. EXT | O2: H.S/D EXT Festivos
F3: Diciembre | H3: 0.020833333 | I3: 0.33333333 | N3: =SUMPRODUCT((J6:J36>0)*(J6:J36)) -> #VALUE! | O3: =SUM(K6:K36) -> 0
P4: total
A5: Día | B5: FECHAS | C5: ENTRADA | D5: SALIDA | E5: ENTRADA | F5: SALIDA | G5: H.TRAB | H5: DESCONTAR | I5: H.LAB | J5: H. EXT | K5: H EXT Festivos | L5: OBSERVACIONES | N5: =N3*N1 -> #VALUE! | O5: =O3*O1 -> 0 | P5: =N5+O5 -> #VALUE!
A6: Lu. | B6: 45992 | C6: 0 | D6: 0 | E6: 0 | F6: 0 | G6: =IF(AND(C6="",D6="",E6="",F6=""),0,(F6-E6+D6-C6)*24) -> 0 | H6: =IF(OR(WEEKDAY($B6,2)>5,COUNTIF(FESTIVOS!$A:$A,$B6)>0),0,$H$3*24) -> 0.5 | I6: =IF(OR(WEEKDAY($B6,2)>5,COUNTIF(FESTIVOS!$A:$A,$B6)>0),0,$I$3*24) -> 8 | J6: =IF(OR(WEEKDAY($B6,2)>5,COUNTIF(FESTIVOS!$A:$A,$B6)>0),"",G6-I6-H6) -> -8.5 | K6: =IF(OR(WEEKDAY($B6,2)>5,COUNTIF(FESTIVOS!$A:$A,$B6)>0),G6,"")
A7: Ma. | B7: 45993 | C7: 0 | D7: 0 | E7: 0 | F7: 0 | G7: =IF(AND(C7="",D7="",E7="",F7=""),0,(F7-E7+D7-C7)*24) -> 0 | H7: =IF(OR(WEEKDAY($B7,2)>5,COUNTIF(FESTIVOS!$A:$A,$B7)>0),0,$H$3*24) -> 0.5 | I7: =IF(OR(WEEKDAY($B7,2)>5,COUNTIF(FESTIVOS!$A:$A,$B7)>0),0,$I$3*24) -> 8 | J7: =IF(OR(WEEKDAY($B7,2)>5,COUNTIF(FESTIVOS!$A:$A,$B7)>0),"",G7-I7-H7) -> -8.5 | K7: =IF(OR(WEEKDAY($B7,2)>5,COUNTIF(FESTIVOS!$A:$A,$B7)>0),G7,"")
A8: Mi. | B8: 45994 | C8: 0 | D8: 0 | E8: 0 | F8: 0 | G8: =IF(AND(C8="",D8="",E8="",F8=""),0,(F8-E8+D8-C8)*24) -> 0 | H8: =IF(OR(WEEKDAY($B8,2)>5,COUNTIF(FESTIVOS!$A:$A,$B8)>0),0,$H$3*24) -> 0.5 | I8: =IF(OR(WEEKDAY($B8,2)>5,COUNTIF(FESTIVOS!$A:$A,$B8)>0),0,$I$3*24) -> 8 | J8: =IF(OR(WEEKDAY($B8,2)>5,COUNTIF(FESTIVOS!$A:$A,$B8)>0),"",G8-I8-H8) -> -8.5 | K8: =IF(OR(WEEKDAY($B8,2)>5,COUNTIF(FESTIVOS!$A:$A,$B8)>0),G8,"")
A9: Ju. | B9: 45995 | C9: 0 | D9: 0 | E9: 0 | F9: 0 | G9: =IF(AND(C9="",D9="",E9="",F9=""),0,(F9-E9+D9-C9)*24) -> 0 | H9: =IF(OR(WEEKDAY($B9,2)>5,COUNTIF(FESTIVOS!$A:$A,$B9)>0),0,$H$3*24) -> 0.5 | I9: =IF(OR(WEEKDAY($B9,2)>5,COUNTIF(FESTIVOS!$A:$A,$B9)>0),0,$I$3*24) -> 8 | J9: =IF(OR(WEEKDAY($B9,2)>5,COUNTIF(FESTIVOS!$A:$A,$B9)>0),"",G9-I9-H9) -> -8.5 | K9: =IF(OR(WEEKDAY($B9,2)>5,COUNTIF(FESTIVOS!$A:$A,$B9)>0),G9,"")
A10: Vi. | B10: 45996 | C10: 0 | D10: 0 | E10: 0 | F10: 0 | G10: =IF(AND(C10="",D10="",E10="",F10=""),0,(F10-E10+D10-C10)*24) -> 0 | H10: =IF(OR(WEEKDAY($B10,2)>5,COUNTIF(FESTIVOS!$A:$A,$B10)>0),0,$H$3*24) -> 0.5 | I10: =IF(OR(WEEKDAY($B10,2)>5,COUNTIF(FESTIVOS!$A:$A,$B10)>0),0,$I$3*24) -> 8 | J10: =IF(OR(WEEKDAY($B10,2)>5,COUNTIF(FESTIVOS!$A:$A,$B10)>0),"",G10-I10-H10) -> -8.5 | K10: =IF(OR(WEEKDAY($B10,2)>5,COUNTIF(FESTIVOS!$A:$A,$B10)>0),G10,"")
A11: Sá. | B11: 45997 | C11: 0 | D11: 0 | E11: 0 | F11: 0 | G11: =IF(AND(C11="",D11="",E11="",F11=""),0,(F11-E11+D11-C11)*24) -> 0 | H11: =IF(OR(WEEKDAY($B11,2)>5,COUNTIF(FESTIVOS!$A:$A,$B11)>0),0,$H$3*24) -> 0 | I11: =IF(OR(WEEKDAY($B11,2)>5,COUNTIF(FESTIVOS!$A:$A,$B11)>0),0,$I$3*24) -> 0 | J11: =IF(OR(WEEKDAY($B11,2)>5,COUNTIF(FESTIVOS!$A:$A,$B11)>0),"",G11-I11-H11) | K11: =IF(OR(WEEKDAY($B11,2)>5,COUNTIF(FESTIVOS!$A:$A,$B11)>0),G11,"") -> 0
A12: Do. | B12: 45998 | C12: 0 | D12: 0 | E12: 0 | F12: 0 | G12: =IF(AND(C12="",D12="",E12="",F12=""),0,(F12-E12+D12-C12)*24) -> 0 | H12: =IF(OR(WEEKDAY($B12,2)>5,COUNTIF(FESTIVOS!$A:$A,$B12)>0),0,$H$3*24) -> 0 | I12: =IF(OR(WEEKDAY($B12,2)>5,COUNTIF(FESTIVOS!$A:$A,$B12)>0),0,$I$3*24) -> 0 | J12: =IF(OR(WEEKDAY($B12,2)>5,COUNTIF(FESTIVOS!$A:$A,$B12)>0),"",G12-I12-H12) | K12: =IF(OR(WEEKDAY($B12,2)>5,COUNTIF(FESTIVOS!$A:$A,$B12)>0),G12,"") -> 0
A13: Lu. | B13: 45999 | C13: 0 | D13: 0 | E13: 0 | F13: 0 | G13: =IF(AND(C13="",D13="",E13="",F13=""),0,(F13-E13+D13-C13)*24) -> 0 | H13: =IF(OR(WEEKDAY($B13,2)>5,COUNTIF(FESTIVOS!$A:$A,$B13)>0),0,$H$3*24) -> 0 | I13: =IF(OR(WEEKDAY($B13,2)>5,COUNTIF(FESTIVOS!$A:$A,$B13)>0),0,$I$3*24) -> 0 | J13: =IF(OR(WEEKDAY($B13,2)>5,COUNTIF(FESTIVOS!$A:$A,$B13)>0),"",G13-I13-H13) | K13: =IF(OR(WEEKDAY($B13,2)>5,COUNTIF(FESTIVOS!$A:$A,$B13)>0),G13,"") -> 0
A14: Ma. | B14: 46000 | C14: 0 | D14: 0 | E14: 0 | F14: 0 | G14: =IF(AND(C14="",D14="",E14="",F14=""),0,(F14-E14+D14-C14)*24) -> 0 | H14: =IF(OR(WEEKDAY($B14,2)>5,COUNTIF(FESTIVOS!$A:$A,$B14)>0),0,$H$3*24) -> 0.5 | I14: =IF(OR(WEEKDAY($B14,2)>5,COUNTIF(FESTIVOS!$A:$A,$B14)>0),0,$I$3*24) -> 8 | J14: =IF(OR(WEEKDAY($B14,2)>5,COUNTIF(FESTIVOS!$A:$A,$B14)>0),"",G14-I14-H14) -> -8.5 | K14: =IF(OR(WEEKDAY($B14,2)>5,COUNTIF(FESTIVOS!$A:$A,$B14)>0),G14,"")
A15: Mi. | B15: 46001 | C15: 0 | D15: 0 | E15: 0 | F15: 0 | G15: =IF(AND(C15="",D15="",E15="",F15=""),0,(F15-E15+D15-C15)*24) -> 0 | H15: =IF(OR(WEEKDAY($B15,2)>5,COUNTIF(FESTIVOS!$A:$A,$B15)>0),0,$H$3*24) -> 0.5 | I15: =IF(OR(WEEKDAY($B15,2)>5,COUNTIF(FESTIVOS!$A:$A,$B15)>0),0,$I$3*24) -> 8 | J15: =IF(OR(WEEKDAY($B15,2)>5,COUNTIF(FESTIVOS!$A:$A,$B15)>0),"",G15-I15-H15) -> -8.5 | K15: =IF(OR(WEEKDAY($B15,2)>5,COUNTIF(FESTIVOS!$A:$A,$B15)>0),G15,"")
A16: Ju. | B16: 46002 | C16: 0 | D16: 0 | E16: 0 | F16: 0 | G16: =IF(AND(C16="",D16="",E16="",F16=""),0,(F16-E16+D16-C16)*24) -> 0 | H16: =IF(OR(WEEKDAY($B16,2)>5,COUNTIF(FESTIVOS!$A:$A,$B16)>0),0,$H$3*24) -> 0.5 | I16: =IF(OR(WEEKDAY($B16,2)>5,COUNTIF(FESTIVOS!$A:$A,$B16)>0),0,$I$3*24) -> 8 | J16: =IF(OR(WEEKDAY($B16,2)>5,COUNTIF(FESTIVOS!$A:$A,$B16)>0),"",G16-I16-H16) -> -8.5 | K16: =IF(OR(WEEKDAY($B16,2)>5,COUNTIF(FESTIVOS!$A:$A,$B16)>0),G16,"")
A17: Vi. | B17: 46003 | C17: 0 | D17: 0 | E17: 0 | F17: 0 | G17: =IF(AND(C17="",D17="",E17="",F17=""),0,(F17-E17+D17-C17)*24) -> 0 | H17: =IF(OR(WEEKDAY($B17,2)>5,COUNTIF(FESTIVOS!$A:$A,$B17)>0),0,$H$3*24) -> 0.5 | I17: =IF(OR(WEEKDAY($B17,2)>5,COUNTIF(FESTIVOS!$A:$A,$B17)>0),0,$I$3*24) -> 8 | J17: =IF(OR(WEEKDAY($B17,2)>5,COUNTIF(FESTIVOS!$A:$A,$B17)>0),"",G17-I17-H17) -> -8.5 | K17: =IF(OR(WEEKDAY($B17,2)>5,COUNTIF(FESTIVOS!$A:$A,$B17)>0),G17,"")
... A36: Mi. | B36: 46022 | C36: 0 | D36: 0 | E36: 0 | F36: 0 | G36: =IF(AND(C36="",D36="",E36="",F36=""),0,(F36-E36+D36-C36)*24) -> 0 | H36: =IF(OR(WEEKDAY($B36,2)>5,COUNTIF(FESTIVOS!$A:$A,$B36)>0),0,$H$3*24) -> 0.5 | I36: =IF(OR(WEEKDAY($B36,2)>5,COUNTIF(FESTIVOS!$A:$A,$B36)>0),0,$I$3*24) -> 8 | J36: =IF(OR(WEEKDAY($B36,2)>5,COUNTIF(FESTIVOS!$A:$A,$B36)>0),"",G36-I36-H36) -> -8.5 | K36: =IF(OR(WEEKDAY($B36,2)>5,COUNTIF(FESTIVOS!$A:$A,$B36)>0),G36,"")

Sheet ENERO
N1: 9 | O1: 10
C2: TRABAJADOR | F2: MES | N2: H. EXT | O2: H.S/D EXT Festivos
F3: Enero | H3: 0.020833333 | I3: 0.33333333 | N3: =SUMPRODUCT((J6:J36>0)*(J6:J36)) -> #VALUE! | O3: =SUM(K6:K36) -> 0
P4: total
A5: Día | B5: FECHAS | C5: ENTRADA | D5: SALIDA | E5: ENTRADA | F5: SALIDA | G5: H.TRAB | H5: DESCONTAR | I5: H.LAB | J5: H. EXT | K5: H EXT Festivos | L5: OBSERVACIONES | N5: =N3*N1 -> #VALUE! | O5: =O3*O1 -> 0 | P5: =N5+O5 -> #VALUE!
A6: Ju. | B6: 46023 | C6: 0 | D6: 0 | E6: 0 | F6: 0 | G6: =IF(AND(C6="",D6="",E6="",F6=""),0,(F6-E6+D6-C6)*24) -> 0 | H6: =IF(OR(WEEKDAY($B6,2)>5,COUNTIF(FESTIVOS!$A:$A,$B6)>0),0,$H$3*24) -> 0 | I6: =IF(OR(WEEKDAY($B6,2)>5,COUNTIF(FESTIVOS!$A:$A,$B6)>0),0,$I$3*24) -> 0 | J6: =IF(OR(WEEKDAY($B6,2)>5,COUNTIF(FESTIVOS!$A:$A,$B6)>0),"",G6-I6-H6) | K6: =IF(OR(WEEKDAY($B6,2)>5,COUNTIF(FESTIVOS!$A:$A,$B6)>0),G6,"") -> 0
A7: Vi. | B7: 46024 | C7: 0 | D7: 0 | E7: 0 | F7: 0 | G7: =IF(AND(C7="",D7="",E7="",F7=""),0,(F7-E7+D7-C7)*24) -> 0 | H7: =IF(OR(WEEKDAY($B7,2)>5,COUNTIF(FESTIVOS!$A:$A,$B7)>0),0,$H$3*24) -> 0.5 | I7: =IF(OR(WEEKDAY($B7,2)>5,COUNTIF(FESTIVOS!$A:$A,$B7)>0),0,$I$3*24) -> 8 | J7: =IF(OR(WEEKDAY($B7,2)>5,COUNTIF(FESTIVOS!$A:$A,$B7)>0),"",G7-I7-H7) -> -8.5 | K7: =IF(OR(WEEKDAY($B7,2)>5,COUNTIF(FESTIVOS!$A:$A,$B7)>0),G7,"")
A8: Sá. | B8: 46025 | C8: 0 | D8: 0 | E8: 0 | F8: 0 | G8: =IF(AND(C8="",D8="",E8="",F8=""),0,(F8-E8+D8-C8)*24) -> 0 | H8: =IF(OR(WEEKDAY($B8,2)>5,COUNTIF(FESTIVOS!$A:$A,$B8)>0),0,$H$3*24) -> 0 | I8: =IF(OR(WEEKDAY($B8,2)>5,COUNTIF(FESTIVOS!$A:$A,$B8)>0),0,$I$3*24) -> 0 | J8: =IF(OR(WEEKDAY($B8,2)>5,COUNTIF(FESTIVOS!$A:$A,$B8)>0),"",G8-I8-H8) | K8: =IF(OR(WEEKDAY($B8,2)>5,COUNTIF(FESTIVOS!$A:$A,$B8)>0),G8,"") -> 0
A9: Do. | B9: 46026 | C9: 0 | D9: 0 | E9: 0 | F9: 0 | G9: =IF(AND(C9="",D9="",E9="",F9=""),0,(F9-E9+D9-C9)*24) -> 0 | H9: =IF(OR(WEEKDAY($B9,2)>5,COUNTIF(FESTIVOS!$A:$A,$B9)>0),0,$H$3*24) -> 0 | I9: =IF(OR(WEEKDAY($B9,2)>5,COUNTIF(FESTIVOS!$A:$A,$B9)>0),0,$I$3*24) -> 0 | J9: =IF(OR(WEEKDAY($B9,2)>5,COUNTIF(FESTIVOS!$A:$A,$B9)>0),"",G9-I9-H9) | K9: =IF(OR(WEEKDAY($B9,2)>5,COUNTIF(FESTIVOS!$A:$A,$B9)>0),G9,"") -> 0
A10: Lu. | B10: 46027 | C10: 0 | D10: 0 | E10: 0 | F10: 0 | G10: =IF(AND(C10="",D10="",E10="",F10=""),0,(F10-E10+D10-C10)*24) -> 0 | H10: =IF(OR(WEEKDAY($B10,2)>5,COUNTIF(FESTIVOS!$A:$A,$B10)>0),0,$H$3*24) -> 0.5 | I10: =IF(OR(WEEKDAY($B10,2)>5,COUNTIF(FESTIVOS!$A:$A,$B10)>0),0,$I$3*24) -> 8 | J10: =IF(OR(WEEKDAY($B10,2)>5,COUNTIF(FESTIVOS!$A:$A,$B10)>0),"",G10-I10-H10) -> -8.5 | K10: =IF(OR(WEEKDAY($B10,2)>5,COUNTIF(FESTIVOS!$A:$A,$B10)>0),G10,"")
A11: Ma. | B11: 46028 | C11: 0 | D11: 0 | E11: 0 | F11: 0 | G11: =IF(AND(C11="",D11="",E11="",F11=""),0,(F11-E11+D11-C11)*24) -> 0 | H11: =IF(OR(WEEKDAY($B11,2)>5,COUNTIF(FESTIVOS!$A:$A,$B11)>0),0,$H$3*24) -> 0 | I11: =IF(OR(WEEKDAY($B11,2)>5,COUNTIF(FESTIVOS!$A:$A,$B11)>0),0,$I$3*24) -> 0 | J11: =IF(OR(WEEKDAY($B11,2)>5,COUNTIF(FESTIVOS!$A:$A,$B11)>0),"",G11-I11-H11) | K11: =IF(OR(WEEKDAY($B11,2)>5,COUNTIF(FESTIVOS!$A:$A,$B11)>0),G11,"") -> 0
A12: Mi. | B12: 46029 | C12: 0 | D12: 0 | E12: 0 | F12: 0 | G12: =IF(AND(C12="",D12="",E12="",F12=""),0,(F12-E12+D12-C12)*24) -> 0 | H12: =IF(OR(WEEKDAY($B12,2)>5,COUNTIF(FESTIVOS!$A:$A,$B12)>0),0,$H$3*24) -> 0.5 | I12: =IF(OR(WEEKDAY($B12,2)>5,COUNTIF(FESTIVOS!$A:$A,$B12)>0),0,$I$3*24) -> 8 | J12: =IF(OR(WEEKDAY($B12,2)>5,COUNTIF(FESTIVOS!$A:$A,$B12)>0),"",G12-I12-H12) -> -8.5 | K12: =IF(OR(WEEKDAY($B12,2)>5,COUNTIF(FESTIVOS!$A:$A,$B12)>0),G12,"")
A13: Ju. | B13: 46030 | C13: 0 | D13: 0 | E13: 0 | F13: 0 | G13: =IF(AND(C13="",D13="",E13="",F13=""),0,(F13-E13+D13-C13)*24) -> 0 | H13: =IF(OR(WEEKDAY($B13,2)>5,COUNTIF(FESTIVOS!$A:$A,$B13)>0),0,$H$3*24) -> 0.5 | I13: =IF(OR(WEEKDAY($B13,2)>5,COUNTIF(FESTIVOS!$A:$A,$B13)>0),0,$I$3*24) -> 8 | J13: =IF(OR(WEEKDAY($B13,2)>5,COUNTIF(FESTIVOS!$A:$A,$B13)>0),"",G13-I13-H13) -> -8.5 | K13: =IF(OR(WEEKDAY($B13,2)>5,COUNTIF(FESTIVOS!$A:$A,$B13)>0),G13,"")
A14: Vi. | B14: 46031 | C14: 0 | D14: 0 | E14: 0 | F14: 0 | G14: =IF(AND(C14="",D14="",E14="",F14=""),0,(F14-E14+D14-C14)*24) -> 0 | H14: =IF(OR(WEEKDAY($B14,2)>5,COUNTIF(FESTIVOS!$A:$A,$B14)>0),0,$H$3*24) -> 0.5 | I14: =IF(OR(WEEKDAY($B14,2)>5,COUNTIF(FESTIVOS!$A:$A,$B14)>0),0,$I$3*24) -> 8 | J14: =IF(OR(WEEKDAY($B14,2)>5,COUNTIF(FESTIVOS!$A:$A,$B14)>0),"",G14-I14-H14) -> -8.5 | K14: =IF(OR(WEEKDAY($B14,2)>5,COUNTIF(FESTIVOS!$A:$A,$B14)>0),G14,"")
A15: Sá. | B15: 46032 | C15: 0 | D15: 0 | E15: 0 | F15: 0 | G15: =IF(AND(C15="",D15="",E15="",F15=""),0,(F15-E15+D15-C15)*24) -> 0 | H15: =IF(OR(WEEKDAY($B15,2)>5,COUNTIF(FESTIVOS!$A:$A,$B15)>0),0,$H$3*24) -> 0 | I15: =IF(OR(WEEKDAY($B15,2)>5,COUNTIF(FESTIVOS!$A:$A,$B15)>0),0,$I$3*24) -> 0 | J15: =IF(OR(WEEKDAY($B15,2)>5,COUNTIF(FESTIVOS!$A:$A,$B15)>0),"",G15-I15-H15) | K15: =IF(OR(WEEKDAY($B15,2)>5,COUNTIF(FESTIVOS!$A:$A,$B15)>0),G15,"") -> 0
A16: Do. | B16: 46033 | C16: 0 | D16: 0 | E16: 0 | F16: 0 | G16: =IF(AND(C16="",D16="",E16="",F16=""),0,(F16-E16+D16-C16)*24) -> 0 | H16: =IF(OR(WEEKDAY($B16,2)>5,COUNTIF(FESTIVOS!$A:$A,$B16)>0),0,$H$3*24) -> 0 | I16: =IF(OR(WEEKDAY($B16,2)>5,COUNTIF(FESTIVOS!$A:$A,$B16)>0),0,$I$3*24) -> 0 | J16: =IF(OR(WEEKDAY($B16,2)>5,COUNTIF(FESTIVOS!$A:$A,$B16)>0),"",G16-I16-H16) | K16: =IF(OR(WEEKDAY($B16,2)>5,COUNTIF(FESTIVOS!$A:$A,$B16)>0),G16,"") -> 0
A17: Lu. | B17: 46034 | C17: 0 | D17: 0 | E17: 0 | F17: 0 | G17: =IF(AND(C17="",D17="",E17="",F17=""),0,(F17-E17+D17-C17)*24) -> 0 | H17: =IF(OR(WEEKDAY($B17,2)>5,COUNTIF(FESTIVOS!$A:$A,$B17)>0),0,$H$3*24) -> 0.5 | I17: =IF(OR(WEEKDAY($B17,2)>5,COUNTIF(FESTIVOS!$A:$A,$B17)>0),0,$I$3*24) -> 8 | J17: =IF(OR(WEEKDAY($B17,2)>5,COUNTIF(FESTIVOS!$A:$A,$B17)>0),"",G17-I17-H17) -> -8.5 | K17: =IF(OR(WEEKDAY($B17,2)>5,COUNTIF(FESTIVOS!$A:$A,$B17)>0),G17,"")
... A36: Sá. | B36: 46053 | C36: 0 | D36: 0 | E36: 0 | F36: 0 | G36: =IF(AND(C36="",D36="",E36="",F36=""),0,(F36-E36+D36-C36)*24) -> 0 | H36: =IF(OR(WEEKDAY($B36,2)>5,COUNTIF(FESTIVOS!$A:$A,$B36)>0),0,$H$3*24) -> 0 | I36: =IF(OR(WEEKDAY($B36,2)>5,COUNTIF(FESTIVOS!$A:$A,$B36)>0),0,$I$3*24) -> 0 | J36: =IF(OR(WEEKDAY($B36,2)>5,COUNTIF(FESTIVOS!$A:$A,$B36)>0),"",G36-I36-H36) | K36: =IF(OR(WEEKDAY($B36,2)>5,COUNTIF(FESTIVOS!$A:$A,$B36)>0),G36,"") -> 0

Sheet FEBRERO
N1: 9 | O1: 10
C2: TRABAJADOR | F2: MES | N2: H. EXT | O2: H.S/D EXT Festivos
F3: Febrero | H3: 0.020833333 | I3: 0.33333333 | N3: =SUMPRODUCT((J6:J33>0)*(J6:J33)) -> #VALUE! | O3: =SUM(K6:K33) -> 0
P4: total
A5: Día | B5: FECHAS | C5: ENTRADA | D5: SALIDA | E5: ENTRADA | F5: SALIDA | G5: H.TRAB | H5: DESCONTAR | I5: H.LAB | J5: H. EXT | K5: H EXT Festivos | L5: OBSERVACIONES | N5: =N3*N1 -> #VALUE! | O5: =O3*O1 -> 0 | P5: =N5+O5 -> #VALUE!
A6: Do. | B6: 46054 | C6: 0 | D6: 0 | E6: 0 | F6: 0 | G6: =IF(AND(C6="",D6="",E6="",F6=""),0,(F6-E6+D6-C6)*24) -> 0 | H6: =IF(OR(WEEKDAY($B6,2)>5,COUNTIF(FESTIVOS!$A:$A,$B6)>0),0,$H$3*24) -> 0 | I6: =IF(OR(WEEKDAY($B6,2)>5,COUNTIF(FESTIVOS!$A:$A,$B6)>0),0,$I$3*24) -> 0 | J6: =IF(OR(WEEKDAY($B6,2)>5,COUNTIF(FESTIVOS!$A:$A,$B6)>0),"",G6-I6-H6) | K6: =IF(OR(WEEKDAY($B6,2)>5,COUNTIF(FESTIVOS!$A:$A,$B6)>0),G6,"") -> 0
A7: Lu. | B7: 46055 | C7: 0 | D7: 0 | E7: 0 | F7: 0 | G7: =IF(AND(C7="",D7="",E7="",F7=""),0,(F7-E7+D7-C7)*24) -> 0 | H7: =IF(OR(WEEKDAY($B7,2)>5,COUNTIF(FESTIVOS!$A:$A,$B7)>0),0,$H$3*24) -> 0.5 | I7: =IF(OR(WEEKDAY($B7,2)>5,COUNTIF(FESTIVOS!$A:$A,$B7)>0),0,$I$3*24) -> 8 | J7: =IF(OR(WEEKDAY($B7,2)>5,COUNTIF(FESTIVOS!$A:$A,$B7)>0),"",G7-I7-H7) -> -8.5 | K7: =IF(OR(WEEKDAY($B7,2)>5,COUNTIF(FESTIVOS!$A:$A,$B7)>0),G7,"")
A8: Ma. | B8: 46056 | C8: 0 | D8: 0 | E8: 0 | F8: 0 | G8: =IF(AND(C8="",D8="",E8="",F8=""),0,(F8-E8+D8-C8)*24) -> 0 | H8: =IF(OR(WEEKDAY($B8,2)>5,COUNTIF(FESTIVOS!$A:$A,$B8)>0),0,$H$3*24) -> 0.5 | I8: =IF(OR(WEEKDAY($B8,2)>5,COUNTIF(FESTIVOS!$A:$A,$B8)>0),0,$I$3*24) -> 8 | J8: =IF(OR(WEEKDAY($B8,2)>5,COUNTIF(FESTIVOS!$A:$A,$B8)>0),"",G8-I8-H8) -> -8.5 | K8: =IF(OR(WEEKDAY($B8,2)>5,COUNTIF(FESTIVOS!$A:$A,$B8)>0),G8,"")
A9: Mi. | B9: 46057 | C9: 0 | D9: 0 | E9: 0 | F9: 0 | G9: =IF(AND(C9="",D9="",E9="",F9=""),0,(F9-E9+D9-C9)*24) -> 0 | H9: =IF(OR(WEEKDAY($B9,2)>5,COUNTIF(FESTIVOS!$A:$A,$B9)>0),0,$H$3*24) -> 0.5 | I9: =IF(OR(WEEKDAY($B9,2)>5,COUNTIF(FESTIVOS!$A:$A,$B9)>0),0,$I$3*24) -> 8 | J9: =IF(OR(WEEKDAY($B9,2)>5,COUNTIF(FESTIVOS!$A:$A,$B9)>0),"",G9-I9-H9) -> -8.5 | K9: =IF(OR(WEEKDAY($B9,2)>5,COUNTIF(FESTIVOS!$A:$A,$B9)>0),G9,"")
A10: Ju. | B10: 46058 | C10: 0 | D10: 0 | E10: 0 | F10: 0 | G10: =IF(AND(C10="",D10="",E10="",F10=""),0,(F10-E10+D10-C10)*24) -> 0 | H10: =IF(OR(WEEKDAY($B10,2)>5,COUNTIF(FESTIVOS!$A:$A,$B10)>0),0,$H$3*24) -> 0.5 | I10: =IF(OR(WEEKDAY($B10,2)>5,COUNTIF(FESTIVOS!$A:$A,$B10)>0),0,$I$3*24) -> 8 | J10: =IF(OR(WEEKDAY($B10,2)>5,COUNTIF(FESTIVOS!$A:$A,$B10)>0),"",G10-I10-H10) -> -8.5 | K10: =IF(OR(WEEKDAY($B10,2)>5,COUNTIF(FESTIVOS!$A:$A,$B10)>0),G10,"")
A11: Vi. | B11: 46059 | C11: 0 | D11: 0 | E11: 0 | F11: 0 | G11: =IF(AND(C11="",D11="",E11="",F11=""),0,(F11-E11+D11-C11)*24) -> 0 | H11: =IF(OR(WEEKDAY($B11,2)>5,COUNTIF(FESTIVOS!$A:$A,$B11)>0),0,$H$3*24) -> 0.5 | I11: =IF(OR(WEEKDAY($B11,2)>5,COUNTIF(FESTIVOS!$A:$A,$B11)>0),0,$I$3*24) -> 8 | J11: =IF(OR(WEEKDAY($B11,2)>5,COUNTIF(FESTIVOS!$A:$A,$B11)>0),"",G11-I11-H11) -> -8.5 | K11: =IF(OR(WEEKDAY($B11,2)>5,COUNTIF(FESTIVOS!$A:$A,$B11)>0),G11,"")
A12: Sá. | B12: 46060 | C12: 0 | D12: 0 | E12: 0 | F12: 0 | G12: =IF(AND(C12="",D12="",E12="",F12=""),0,(F12-E12+D12-C12)*24) -> 0 | H12: =IF(OR(WEEKDAY($B12,2)>5,COUNTIF(FESTIVOS!$A:$A,$B12)>0),0,$H$3*24) -> 0 | I12: =IF(OR(WEEKDAY($B12,2)>5,COUNTIF(FESTIVOS!$A:$A,$B12)>0),0,$I$3*24) -> 0 | J12: =IF(OR(WEEKDAY($B12,2)>5,COUNTIF(FESTIVOS!$A:$A,$B12)>0),"",G12-I12-H12) | K12: =IF(OR(WEEKDAY($B12,2)>5,COUNTIF(FESTIVOS!$A:$A,$B12)>0),G12,"") -> 0
A13: Do. | B13: 46061 | C13: 0 | D13: 0 | E13: 0 | F13: 0 | G13: =IF(AND(C13="",D13="",E13="",F13=""),0,(F13-E13+D13-C13)*24) -> 0 | H13: =IF(OR(WEEKDAY($B13,2)>5,COUNTIF(FESTIVOS!$A:$A,$B13)>0),0,$H$3*24) -> 0 | I13: =IF(OR(WEEKDAY($B13,2)>5,COUNTIF(FESTIVOS!$A:$A,$B13)>0),0,$I$3*24) -> 0 | J13: =IF(OR(WEEKDAY($B13,2)>5,COUNTIF(FESTIVOS!$A:$A,$B13)>0),"",G13-I13-H13) | K13: =IF(OR(WEEKDAY($B13,2)>5,COUNTIF(FESTIVOS!$A:$A,$B13)>0),G13,"") -> 0
A14: Lu. | B14: 46062 | C14: 0 | D14: 0 | E14: 0 | F14: 0 | G14: =IF(AND(C14="",D14="",E14="",F14=""),0,(F14-E14+D14-C14)*24) -> 0 | H14: =IF(OR(WEEKDAY($B14,2)>5,COUNTIF(FESTIVOS!$A:$A,$B14)>0),0,$H$3*24) -> 0.5 | I14: =IF(OR(WEEKDAY($B14,2)>5,COUNTIF(FESTIVOS!$A:$A,$B14)>0),0,$I$3*24) -> 8 | J14: =IF(OR(WEEKDAY($B14,2)>5,COUNTIF(FESTIVOS!$A:$A,$B14)>0),"",G14-I14-H14) -> -8.5 | K14: =IF(OR(WEEKDAY($B14,2)>5,COUNTIF(FESTIVOS!$A:$A,$B14)>0),G14,"")
A15: Ma. | B15: 46063 | C15: 0 | D15: 0 | E15: 0 | F15: 0 | G15: =IF(AND(C15="",D15="",E15="",F15=""),0,(F15-E15+D15-C15)*24) -> 0 | H15: =IF(OR(WEEKDAY($B15,2)>5,COUNTIF(FESTIVOS!$A:$A,$B15)>0),0,$H$3*24) -> 0.5 | I15: =IF(OR(WEEKDAY($B15,2)>5,COUNTIF(FESTIVOS!$A:$A,$B15)>0),0,$I$3*24) -> 8 | J15: =IF(OR(WEEKDAY($B15,2)>5,COUNTIF(FESTIVOS!$A:$A,$B15)>0),"",G15-I15-H15) -> -8.5 | K15: =IF(OR(WEEKDAY($B15,2)>5,COUNTIF(FESTIVOS!$A:$A,$B15)>0),G15,"")
A16: Mi. | B16: 46064 | C16: 0 | D16: 0 | E16: 0 | F16: 0 | G16: =IF(AND(C16="",D16="",E16="",F16=""),0,(F16-E16+D16-C16)*24) -> 0 | H16: =IF(OR(WEEKDAY($B16,2)>5,COUNTIF(FESTIVOS!$A:$A,$B16)>0),0,$H$3*24) -> 0.5 | I16: =IF(OR(WEEKDAY($B16,2)>5,COUNTIF(FESTIVOS!$A:$A,$B16)>0),0,$I$3*24) -> 8 | J16: =IF(OR(WEEKDAY($B16,2)>5,COUNTIF(FESTIVOS!$A:$A,$B16)>0),"",G16-I16-H16) -> -8.5 | K16: =IF(OR(WEEKDAY($B16,2)>5,COUNTIF(FESTIVOS!$A:$A,$B16)>0),G16,"")
A17: Ju. | B17: 46065 | C17: 0 | D17: 0 | E17: 0 | F17: 0 | G17: =IF(AND(C17="",D17="",E17="",F17=""),0,(F17-E17+D17-C17)*24) -> 0 | H17: =IF(OR(WEEKDAY($B17,2)>5,COUNTIF(FESTIVOS!$A:$A,$B17)>0),0,$H$3*24) -> 0.5 | I17: =IF(OR(WEEKDAY($B17,2)>5,COUNTIF(FESTIVOS!$A:$A,$B17)>0),0,$I$3*24) -> 8 | J17: =IF(OR(WEEKDAY($B17,2)>5,COUNTIF(FESTIVOS!$A:$A,$B17)>0),"",G17-I17-H17) -> -8.5 | K17: =IF(OR(WEEKDAY($B17,2)>5,COUNTIF(FESTIVOS!$A:$A,$B17)>0),G17,"")
... A33: Sá. | B33: 46081 | C33: 0 | D33: 0 | E33: 0 | F33: 0 | G33: =IF(AND(C33="",D33="",E33="",F33=""),0,(F33-E33+D33-C33)*24) -> 0 | H33: =IF(OR(WEEKDAY($B33,2)>5,COUNTIF(FESTIVOS!$A:$A,$B33)>0),0,$H$3*24) -> 0 | I33: =IF(OR(WEEKDAY($B33,2)>5,COUNTIF(FESTIVOS!$A:$A,$B33)>0),0,$I$3*24) -> 0 | J33: =IF(OR(WEEKDAY($B33,2)>5,COUNTIF(FESTIVOS!$A:$A,$B33)>0),"",G33-I33-H33) | K33: =IF(OR(WEEKDAY($B33,2)>5,COUNTIF(FESTIVOS!$A:$A,$B33)>0),G33,"") -> 0

Sheet MARZO
N1: 9 | O1: 10
C2: TRABAJADOR | F2: MES | N2: H. EXT | O2: H.S/D EXT Festivos
F3: Marzo | H3: 0.020833333 | I3: 0.33333333 | N3: =SUMPRODUCT((J6:J36>0)*(J6:J36)) -> #VALUE! | O3: =SUM(K6:K36) -> 0
P4: total
A5: Día | B5: FECHAS | C5: ENTRADA | D5: SALIDA | E5: ENTRADA | F5: SALIDA | G5: H.TRAB | H5: DESCONTAR | I5: H.LAB | J5: H. EXT | K5: H EXT Festivos | L5: OBSERVACIONES | N5: =N3*N1 -> #VALUE! | O5: =O3*O1 -> 0 | P5: =N5+O5 -> #VALUE!
A6: Do. | B6: 46082 | C6: 0 | D6: 0 | E6: 0 | F6: 0 | G6: =IF(AND(C6="",D6="",E6="",F6=""),0,(F6-E6+D6-C6)*24) -> 0 | H6: =IF(OR(WEEKDAY($B6,2)>5,COUNTIF(FESTIVOS!$A:$A,$B6)>0),0,$H$3*24) -> 0 | I6: =IF(OR(WEEKDAY($B6,2)>5,COUNTIF(FESTIVOS!$A:$A,$B6)>0),0,$I$3*24) -> 0 | J6: =IF(OR(WEEKDAY($B6,2)>5,COUNTIF(FESTIVOS!$A:$A,$B6)>0),"",G6-I6-H6) | K6: =IF(OR(WEEKDAY($B6,2)>5,COUNTIF(FESTIVOS!$A:$A,$B6)>0),G6,"") -> 0
A7: Lu. | B7: 46083 | C7: 0 | D7: 0 | E7: 0 | F7: 0 | G7: =IF(AND(C7="",D7="",E7="",F7=""),0,(F7-E7+D7-C7)*24) -> 0 | H7: =IF(OR(WEEKDAY($B7,2)>5,COUNTIF(FESTIVOS!$A:$A,$B7)>0),0,$H$3*24) -> 0 | I7: =IF(OR(WEEKDAY($B7,2)>5,COUNTIF(FESTIVOS!$A:$A,$B7)>0),0,$I$3*24) -> 0 | J7: =IF(OR(WEEKDAY($B7,2)>5,COUNTIF(FESTIVOS!$A:$A,$B7)>0),"",G7-I7-H7) | K7: =IF(OR(WEEKDAY($B7,2)>5,COUNTIF(FESTIVOS!$A:$A,$B7)>0),G7,"") -> 0
A8: Ma. | B8: 46084 | C8: 0 | D8: 0 | E8: 0 | F8: 0 | G8: =IF(AND(C8="",D8="",E8="",F8=""),0,(F8-E8+D8-C8)*24) -> 0 | H8: =IF(OR(WEEKDAY($B8,2)>5,COUNTIF(FESTIVOS!$A:$A,$B8)>0),0,$H$3*24) -> 0.5 | I8: =IF(OR(WEEKDAY($B8,2)>5,COUNTIF(FESTIVOS!$A:$A,$B8)>0),0,$I$3*24) -> 8 | J8: =IF(OR(WEEKDAY($B8,2)>5,COUNTIF(FESTIVOS!$A:$A,$B8)>0),"",G8-I8-H8) -> -8.5 | K8: =IF(OR(WEEKDAY($B8,2)>5,COUNTIF(FESTIVOS!$A:$A,$B8)>0),G8,"")
A9: Mi. | B9: 46085 | C9: 0 | D9: 0 | E9: 0 | F9: 0 | G9: =IF(AND(C9="",D9="",E9="",F9=""),0,(F9-E9+D9-C9)*24) -> 0 | H9: =IF(OR(WEEKDAY($B9,2)>5,COUNTIF(FESTIVOS!$A:$A,$B9)>0),0,$H$3*24) -> 0.5 | I9: =IF(OR(WEEKDAY($B9,2)>5,COUNTIF(FESTIVOS!$A:$A,$B9)>0),0,$I$3*24) -> 8 | J9: =IF(OR(WEEKDAY($B9,2)>5,COUNTIF(FESTIVOS!$A:$A,$B9)>0),"",G9-I9-H9) -> -8.5 | K9: =IF(OR(WEEKDAY($B9,2)>5,COUNTIF(FESTIVOS!$A:$A,$B9)>0),G9,"")
A10: Ju. | B10: 46086 | C10: 0 | D10: 0 | E10: 0 | F10: 0 | G10: =IF(AND(C10="",D10="",E10="",F10=""),0,(F10-E10+D10-C10)*24) -> 0 | H10: =IF(OR(WEEKDAY($B10,2)>5,COUNTIF(FESTIVOS!$A:$A,$B10)>0),0,$H$3*24) -> 0.5 | I10: =IF(OR(WEEKDAY($B10,2)>5,COUNTIF(FESTIVOS!$A:$A,$B10)>0),0,$I$3*24) -> 8 | J10: =IF(OR(WEEKDAY($B10,2)>5,COUNTIF(FESTIVOS!$A:$A,$B10)>0),"",G10-I10-H10) -> -8.5 | K10: =IF(OR(WEEKDAY($B10,2)>5,COUNTIF(FESTIVOS!$A:$A,$B10)>0),G10,"")
A11: Vi. | B11: 46087 | C11: 0 | D11: 0 | E11: 0 | F11: 0 | G11: =IF(AND(C11="",D11="",E11="",F11=""),0,(F11-E11+D11-C11)*24) -> 0 | H11: =IF(OR(WEEKDAY($B11,2)>5,COUNTIF(FESTIVOS!$A:$A,$B11)>0),0,$H$3*24) -> 0.5 | I11: =IF(OR(WEEKDAY($B11,2)>5,COUNTIF(FESTIVOS!$A:$A,$B11)>0),0,$I$3*24) -> 8 | J11: =IF(OR(WEEKDAY($B11,2)>5,COUNTIF(FESTIVOS!$A:$A,$B11)>0),"",G11-I11-H11) -> -8.5 | K11: =IF(OR(WEEKDAY($B11,2)>5,COUNTIF(FESTIVOS!$A:$A,$B11)>0),G11,"")
A12: Sá. | B12: 46088 | C12: 0 | D12: 0 | E12: 0 | F12: 0 | G12: =IF(AND(C12="",D12="",E12="",F12=""),0,(F12-E12+D12-C12)*24) -> 0 | H12: =IF(OR(WEEKDAY($B12,2)>5,COUNTIF(FESTIVOS!$A:$A,$B12)>0),0,$H$3*24) -> 0 | I12: =IF(OR(WEEKDAY($B12,2)>5,COUNTIF(FESTIVOS!$A:$A,$B12)>0),0,$I$3*24) -> 0 | J12: =IF(OR(WEEKDAY($B12,2)>5,COUNTIF(FESTIVOS!$A:$A,$B12)>0),"",G12-I12-H12) | K12: =IF(OR(WEEKDAY($B12,2)>5,COUNTIF(FESTIVOS!$A:$A,$B12)>0),G12,"") -> 0
A13: Do. | B13: 46089 | C13: 0 | D13: 0 | E13: 0 | F13: 0 | G13: =IF(AND(C13="",D13="",E13="",F13=""),0,(F13-E13+D13-C13)*24) -> 0 | H13: =IF(OR(WEEKDAY($B13,2)>5,COUNTIF(FESTIVOS!$A:$A,$B13)>0),0,$H$3*24) -> 0 | I13: =IF(OR(WEEKDAY($B13,2)>5,COUNTIF(FESTIVOS!$A:$A,$B13)>0),0,$I$3*24) -> 0 | J13: =IF(OR(WEEKDAY($B13,2)>5,COUNTIF(FESTIVOS!$A:$A,$B13)>0),"",G13-I13-H13) | K13: =IF(OR(WEEKDAY($B13,2)>5,COUNTIF(FESTIVOS!$A:$A,$B13)>0),G13,"") -> 0
A14: Lu. | B14: 46090 | C14: 0 | D14: 0 | E14: 0 | F14: 0 | G14: =IF(AND(C14="",D14="",E14="",F14=""),0,(F14-E14+D14-C14)*24) -> 0 | H14: =IF(OR(WEEKDAY($B14,2)>5,COUNTIF(FESTIVOS!$A:$A,$B14)>0),0,$H$3*24) -> 0.5 | I14: =IF(OR(WEEKDAY($B14,2)>5,COUNTIF(FESTIVOS!$A:$A,$B14)>0),0,$I$3*24) -> 8 | J14: =IF(OR(WEEKDAY($B14,2)>5,COUNTIF(FESTIVOS!$A:$A,$B14)>0),"",G14-I14-H14) -> -8.5 | K14: =IF(OR(WEEKDAY($B14,2)>5,COUNTIF(FESTIVOS!$A:$A,$B14)>0),G14,"")
A15: Ma. | B15: 46091 | C15: 0 | D15: 0 | E15: 0 | F15: 0 | G15: =IF(AND(C15="",D15="",E15="",F15=""),0,(F15-E15+D15-C15)*24) -> 0 | H15: =IF(OR(WEEKDAY($B15,2)>5,COUNTIF(FESTIVOS!$A:$A,$B15)>0),0,$H$3*24) -> 0.5 | I15: =IF(OR(WEEKDAY($B15,2)>5,COUNTIF(FESTIVOS!$A:$A,$B15)>0),0,$I$3*24) -> 8 | J15: =IF(OR(WEEKDAY($B15,2)>5,COUNTIF(FESTIVOS!$A:$A,$B15)>0),"",G15-I15-H15) -> -8.5 | K15: =IF(OR(WEEKDAY($B15,2)>5,COUNTIF(FESTIVOS!$A:$A,$B15)>0),G15,"")
A16: Mi. | B16: 46092 | C16: 0 | D16: 0 | E16: 0 | F16: 0 | G16: =IF(AND(C16="",D16="",E16="",F16=""),0,(F16-E16+D16-C16)*24) -> 0 | H16: =IF(OR(WEEKDAY($B16,2)>5,COUNTIF(FESTIVOS!$A:$A,$B16)>0),0,$H$3*24) -> 0.5 | I16: =IF(OR(WEEKDAY($B16,2)>5,COUNTIF(FESTIVOS!$A:$A,$B16)>0),0,$I$3*24) -> 8 | J16: =IF(OR(WEEKDAY($B16,2)>5,COUNTIF(FESTIVOS!$A:$A,$B16)>0),"",G16-I16-H16) -> -8.5 | K16: =IF(OR(WEEKDAY($B16,2)>5,COUNTIF(FESTIVOS!$A:$A,$B16)>0),G16,"")
A17: Ju. | B17: 46093 | C17: 0 | D17: 0 | E17: 0 | F17: 0 | G17: =IF(AND(C17="",D17="",E17="",F17=""),0,(F17-E17+D17-C17)*24) -> 0 | H17: =IF(OR(WEEKDAY($B17,2)>5,COUNTIF(FESTIVOS!$A:$A,$B17)>0),0,$H$3*24) -> 0.5 | I17: =IF(OR(WEEKDAY($B17,2)>5,COUNTIF(FESTIVOS!$A:$A,$B17)>0),0,$I$3*24) -> 8 | J17: =IF(OR(WEEKDAY($B17,2)>5,COUNTIF(FESTIVOS!$A:$A,$B17)>0),"",G17-I17-H17) -> -8.5 | K17: =IF(OR(WEEKDAY($B17,2)>5,COUNTIF(FESTIVOS!$A:$A,$B17)>0),G17,"")
... A36: Ma. | B36: 46112 | C36: 0 | D36: 0 | E36: 0 | F36: 0 | G36: =IF(AND(C36="",D36="",E36="",F36=""),0,(F36-E36+D36-C36)*24) -> 0 | H36: =IF(OR(WEEKDAY($B36,2)>5,COUNTIF(FESTIVOS!$A:$A,$B36)>0),0,$H$3*24) -> 0.5 | I36: =IF(OR(WEEKDAY($B36,2)>5,COUNTIF(FESTIVOS!$A:$A,$B36)>0),0,$I$3*24) -> 8 | J36: =IF(OR(WEEKDAY($B36,2)>5,COUNTIF(FESTIVOS!$A:$A,$B36)>0),"",G36-I36-H36) -> -8.5 | K36: =IF(OR(WEEKDAY($B36,2)>5,COUNTIF(FESTIVOS!$A:$A,$B36)>0),G36,"")

Sheet ABRIL
N1: 9 | O1: 10
C2: TRABAJADOR | F2: MES | N2: H. EXT | O2: H.S/D EXT Festivos
F3: Abril | H3: 0.020833333 | I3: 0.33333333 | N3: =SUMPRODUCT((J6:J35>0)*(J6:J35)) -> #VALUE! | O3: =SUM(K6:K35) -> 0
P4: total
A5: Día | B5: FECHAS | C5: ENTRADA | D5: SALIDA | E5: ENTRADA | F5: SALIDA | G5: H.TRAB | H5: DESCONTAR | I5: H.LAB | J5: H. EXT | K5: H EXT Festivos | L5: OBSERVACIONES | N5: =N3*N1 -> #VALUE! | O5: =O3*O1 -> 0 | P5: =N5+O5 -> #VALUE!
A6: Mi. | B6: 46113 | C6: 0 | D6: 0 | E6: 0 | F6: 0 | G6: =IF(AND(C6="",D6="",E6="",F6=""),0,(F6-E6+D6-C6)*24) -> 0 | H6: =IF(OR(WEEKDAY($B6,2)>5,COUNTIF(FESTIVOS!$A:$A,$B6)>0),0,$H$3*24) -> 0.5 | I6: =IF(OR(WEEKDAY($B6,2)>5,COUNTIF(FESTIVOS!$A:$A,$B6)>0),0,$I$3*24) -> 8 | J6: =IF(OR(WEEKDAY($B6,2)>5,COUNTIF(FESTIVOS!$A:$A,$B6)>0),"",G6-I6-H6) -> -8.5 | K6: =IF(OR(WEEKDAY($B6,2)>5,COUNTIF(FESTIVOS!$A:$A,$B6)>0),G6,"")
A7: Ju. | B7: 46114 | C7: 0 | D7: 0 | E7: 0 | F7: 0 | G7: =IF(AND(C7="",D7="",E7="",F7=""),0,(F7-E7+D7-C7)*24) -> 0 | H7: =IF(OR(WEEKDAY($B7,2)>5,COUNTIF(FESTIVOS!$A:$A,$B7)>0),0,$H$3*24) -> 0 | I7: =IF(OR(WEEKDAY($B7,2)>5,COUNTIF(FESTIVOS!$A:$A,$B7)>0),0,$I$3*24) -> 0 | J7: =IF(OR(WEEKDAY($B7,2)>5,COUNTIF(FESTIVOS!$A:$A,$B7)>0),"",G7-I7-H7) | K7: =IF(OR(WEEKDAY($B7,2)>5,COUNTIF(FESTIVOS!$A:$A,$B7)>0),G7,"") -> 0
A8: Vi. | B8: 46115 | C8: 0 | D8: 0 | E8: 0 | F8: 0 | G8: =IF(AND(C8="",D8="",E8="",F8=""),0,(F8-E8+D8-C8)*24) -> 0 | H8: =IF(OR(WEEKDAY($B8,2)>5,COUNTIF(FESTIVOS!$A:$A,$B8)>0),0,$H$3*24) -> 0 | I8: =IF(OR(WEEKDAY($B8,2)>5,COUNTIF(FESTIVOS!$A:$A,$B8)>0),0,$I$3*24) -> 0 | J8: =IF(OR(WEEKDAY($B8,2)>5,COUNTIF(FESTIVOS!$A:$A,$B8)>0),"",G8-I8-H8) | K8: =IF(OR(WEEKDAY($B8,2)>5,COUNTIF(FESTIVOS!$A:$A,$B8)>0),G8,"") -> 0
A9: Sá. | B9: 46116 | C9: 0 | D9: 0 | E9: 0 | F9: 0 | G9: =IF(AND(C9="",D9="",E9="",F9=""),0,(F9-E9+D9-C9)*24) -> 0 | H9: =IF(OR(WEEKDAY($B9,2)>5,COUNTIF(FESTIVOS!$A:$A,$B9)>0),0,$H$3*24) -> 0 | I9: =IF(OR(WEEKDAY($B9,2)>5,COUNTIF(FESTIVOS!$A:$A,$B9)>0),0,$I$3*24) -> 0 | J9: =IF(OR(WEEKDAY($B9,2)>5,COUNTIF(FESTIVOS!$A:$A,$B9)>0),"",G9-I9-H9) | K9: =IF(OR(WEEKDAY($B9,2)>5,COUNTIF(FESTIVOS!$A:$A,$B9)>0),G9,"") -> 0
A10: Do. | B10: 46117 | C10: 0 | D10: 0 | E10: 0 | F10: 0 | G10: =IF(AND(C10="",D10="",E10="",F10=""),0,(F10-E10+D10-C10)*24) -> 0 | H10: =IF(OR(WEEKDAY($B10,2)>5,COUNTIF(FESTIVOS!$A:$A,$B10)>0),0,$H$3*24) -> 0 | I10: =IF(OR(WEEKDAY($B10,2)>5,COUNTIF(FESTIVOS!$A:$A,$B10)>0),0,$I$3*24) -> 0 | J10: =IF(OR(WEEKDAY($B10,2)>5,COUNTIF(FESTIVOS!$A:$A,$B10)>0),"",G10-I10-H10) | K10: =IF(OR(WEEKDAY($B10,2)>5,COUNTIF(FESTIVOS!$A:$A,$B10)>0),G10,"") -> 0
A11: Lu. | B11: 46118 | C11: 0 | D11: 0 | E11: 0 | F11: 0 | G11: =IF(AND(C11="",D11="",E11="",F11=""),0,(F11-E11+D11-C11)*24) -> 0 | H11: =IF(OR(WEEKDAY($B11,2)>5,COUNTIF(FESTIVOS!$A:$A,$B11)>0),0,$H$3*24) -> 0 | I11: =IF(OR(WEEKDAY($B11,2)>5,COUNTIF(FESTIVOS!$A:$A,$B11)>0),0,$I$3*24) -> 0 | J11: =IF(OR(WEEKDAY($B11,2)>5,COUNTIF(FESTIVOS!$A:$A,$B11)>0),"",G11-I11-H11) | K11: =IF(OR(WEEKDAY($B11,2)>5,COUNTIF(FESTIVOS!$A:$A,$B11)>0),G11,"") -> 0
A12: Ma. | B12: 46119 | C12: 0 | D12: 0 | E12: 0 | F12: 0 | G12: =IF(AND(C12="",D12="",E12="",F12=""),0,(F12-E12+D12-C12)*24) -> 0 | H12: =IF(OR(WEEKDAY($B12,2)>5,COUNTIF(FESTIVOS!$A:$A,$B12)>0),0,$H$3*24) -> 0.5 | I12: =IF(OR(WEEKDAY($B12,2)>5,COUNTIF(FESTIVOS!$A:$A,$B12)>0),0,$I$3*24) -> 8 | J12: =IF(OR(WEEKDAY($B12,2)>5,COUNTIF(FESTIVOS!$A:$A,$B12)>0),"",G12-I12-H12) -> -8.5 | K12: =IF(OR(WEEKDAY($B12,2)>5,COUNTIF(FESTIVOS!$A:$A,$B12)>0),G12,"")
A13: Mi. | B13: 46120 | C13: 0 | D13: 0 | E13: 0 | F13: 0 | G13: =IF(AND(C13="",D13="",E13="",F13=""),0,(F13-E13+D13-C13)*24) -> 0 | H13: =IF(OR(WEEKDAY($B13,2)>5,COUNTIF(FESTIVOS!$A:$A,$B13)>0),0,$H$3*24) -> 0.5 | I13: =IF(OR(WEEKDAY($B13,2)>5,COUNTIF(FESTIVOS!$A:$A,$B13)>0),0,$I$3*24) -> 8 | J13: =IF(OR(WEEKDAY($B13,2)>5,COUNTIF(FESTIVOS!$A:$A,$B13)>0),"",G13-I13-H13) -> -8.5 | K13: =IF(OR(WEEKDAY($B13,2)>5,COUNTIF(FESTIVOS!$A:$A,$B13)>0),G13,"")
A14: Ju. | B14: 46121 | C14: 0 | D14: 0 | E14: 0 | F14: 0 | G14: =IF(AND(C14="",D14="",E14="",F14=""),0,(F14-E14+D14-C14)*24) -> 0 | H14: =IF(OR(WEEKDAY($B14,2)>5,COUNTIF(FESTIVOS!$A:$A,$B14)>0),0,$H$3*24) -> 0.5 | I14: =IF(OR(WEEKDAY($B14,2)>5,COUNTIF(FESTIVOS!$A:$A,$B14)>0),0,$I$3*24) -> 8 | J14: =IF(OR(WEEKDAY($B14,2)>5,COUNTIF(FESTIVOS!$A:$A,$B14)>0),"",G14-I14-H14) -> -8.5 | K14: =IF(OR(WEEKDAY($B14,2)>5,COUNTIF(FESTIVOS!$A:$A,$B14)>0),G14,"")
A15: Vi. | B15: 46122 | C15: 0 | D15: 0 | E15: 0 | F15: 0 | G15: =IF(AND(C15="",D15="",E15="",F15=""),0,(F15-E15+D15-C15)*24) -> 0 | H15: =IF(OR(WEEKDAY($B15,2)>5,COUNTIF(FESTIVOS!$A:$A,$B15)>0),0,$H$3*24) -> 0.5 | I15: =IF(OR(WEEKDAY($B15,2)>5,COUNTIF(FESTIVOS!$A:$A,$B15)>0),0,$I$3*24) -> 8 | J15: =IF(OR(WEEKDAY($B15,2)>5,COUNTIF(FESTIVOS!$A:$A,$B15)>0),"",G15-I15-H15) -> -8.5 | K15: =IF(OR(WEEKDAY($B15,2)>5,COUNTIF(FESTIVOS!$A:$A,$B15)>0),G15,"")
A16: Sá. | B16: 46123 | C16: 0 | D16: 0 | E16: 0 | F16: 0 | G16: =IF(AND(C16="",D16="",E16="",F16=""),0,(F16-E16+D16-C16)*24) -> 0 | H16: =IF(OR(WEEKDAY($B16,2)>5,COUNTIF(FESTIVOS!$A:$A,$B16)>0),0,$H$3*24) -> 0 | I16: =IF(OR(WEEKDAY($B16,2)>5,COUNTIF(FESTIVOS!$A:$A,$B16)>0),0,$I$3*24) -> 0 | J16: =IF(OR(WEEKDAY($B16,2)>5,COUNTIF(FESTIVOS!$A:$A,$B16)>0),"",G16-I16-H16) | K16: =IF(OR(WEEKDAY($B16,2)>5,COUNTIF(FESTIVOS!$A:$A,$B16)>0),G16,"") -> 0
A17: Do. | B17: 46124 | C17: 0 | D17: 0 | E17: 0 | F17: 0 | G17: =IF(AND(C17="",D17="",E17="",F17=""),0,(F17-E17+D17-C17)*24) -> 0 | H17: =IF(OR(WEEKDAY($B17,2)>5,COUNTIF(FESTIVOS!$A:$A,$B17)>0),0,$H$3*24) -> 0 | I17: =IF(OR(WEEKDAY($B17,2)>5,COUNTIF(FESTIVOS!$A:$A,$B17)>0),0,$I$3*24) -> 0 | J17: =IF(OR(WEEKDAY($B17,2)>5,COUNTIF(FESTIVOS!$A:$A,$B17)>0),"",G17-I17-H17) | K17: =IF(OR(WEEKDAY($B17,2)>5,COUNTIF(FESTIVOS!$A:$A,$B17)>0),G17,"") -> 0
... A35: Ju. | B35: 46142 | C35: 0 | D35: 0 | E35: 0 | F35: 0 | G35: =IF(AND(C35="",D35="",E35="",F35=""),0,(F35-E35+D35-C35)*24) -> 0 | H35: =IF(OR(WEEKDAY($B35,2)>5,COUNTIF(FESTIVOS!$A:$A,$B35)>0),0,$H$3*24) -> 0.5 | I35: =IF(OR(WEEKDAY($B35,2)>5,COUNTIF(FESTIVOS!$A:$A,$B35)>0),0,$I$3*24) -> 8 | J35: =IF(OR(WEEKDAY($B35,2)>5,COUNTIF(FESTIVOS!$A:$A,$B35)>0),"",G35-I35-H35) -> -8.5 | K35: =IF(OR(WEEKDAY($B35,2)>5,COUNTIF(FESTIVOS!$A:$A,$B35)>0),G35,"")

Sheet MAYO
N1: 9 | O1: 10
C2: TRABAJADOR | F2: MES | N2: H. EXT | O2: H.S/D EXT Festivos
F3: Mayo | H3: 0.020833333 | I3: 0.33333333 | N3: =SUMPRODUCT((J6:J36>0)*(J6:J36)) -> #VALUE! | O3: =SUM(K6:K36) -> 0
P4: total
A5: Día | B5: FECHAS | C5: ENTRADA | D5: SALIDA | E5: ENTRADA | F5: SALIDA | G5: H.TRAB | H5: DESCONTAR | I5: H.LAB | J5: H. EXT | K5: H EXT Festivos | L5: OBSERVACIONES | N5: =N3*N1 -> #VALUE! | O5: =O3*O1 -> 0 | P5: =N5+O5 -> #VALUE!
A6: Vi. | B6: 46143 | C6: 0 | D6: 0 | E6: 0 | F6: 0 | G6: =IF(AND(C6="",D6="",E6="",F6=""),0,(F6-E6+D6-C6)*24) -> 0 | H6: =IF(OR(WEEKDAY($B6,2)>5,COUNTIF(FESTIVOS!$A:$A,$B6)>0),0,$H$3*24) -> 0 | I6: =IF(OR(WEEKDAY($B6,2)>5,COUNTIF(FESTIVOS!$A:$A,$B6)>0),0,$I$3*24) -> 0 | J6: =IF(OR(WEEKDAY($B6,2)>5,COUNTIF(FESTIVOS!$A:$A,$B6)>0),"",G6-I6-H6) | K6: =IF(OR(WEEKDAY($B6,2)>5,COUNTIF(FESTIVOS!$A:$A,$B6)>0),G6,"") -> 0
A7: Sá. | B7: 46144 | C7: 0 | D7: 0 | E7: 0 | F7: 0 | G7: =IF(AND(C7="",D7="",E7="",F7=""),0,(F7-E7+D7-C7)*24) -> 0 | H7: =IF(OR(WEEKDAY($B7,2)>5,COUNTIF(FESTIVOS!$A:$A,$B7)>0),0,$H$3*24) -> 0 | I7: =IF(OR(WEEKDAY($B7,2)>5,COUNTIF(FESTIVOS!$A:$A,$B7)>0),0,$I$3*24) -> 0 | J7: =IF(OR(WEEKDAY($B7,2)>5,COUNTIF(FESTIVOS!$A:$A,$B7)>0),"",G7-I7-H7) | K7: =IF(OR(WEEKDAY($B7,2)>5,COUNTIF(FESTIVOS!$A:$A,$B7)>0),G7,"") -> 0
A8: Do. | B8: 46145 | C8: 0 | D8: 0 | E8: 0 | F8: 0 | G8: =IF(AND(C8="",D8="",E8="",F8=""),0,(F8-E8+D8-C8)*24) -> 0 | H8: =IF(OR(WEEKDAY($B8,2)>5,COUNTIF(FESTIVOS!$A:$A,$B8)>0),0,$H$3*24) -> 0 | I8: =IF(OR(WEEKDAY($B8,2)>5,COUNTIF(FESTIVOS!$A:$A,$B8)>0),0,$I$3*24) -> 0 | J8: =IF(OR(WEEKDAY($B8,2)>5,COUNTIF(FESTIVOS!$A:$A,$B8)>0),"",G8-I8-H8) | K8: =IF(OR(WEEKDAY($B8,2)>5,COUNTIF(FESTIVOS!$A:$A,$B8)>0),G8,"") -> 0
A9: Lu. | B9: 46146 | C9: 0 | D9: 0 | E9: 0 | F9: 0 | G9: =IF(AND(C9="",D9="",E9="",F9=""),0,(F9-E9+D9-C9)*24) -> 0 | H9: =IF(OR(WEEKDAY($B9,2)>5,COUNTIF(FESTIVOS!$A:$A,$B9)>0),0,$H$3*24) -> 0.5 | I9: =IF(OR(WEEKDAY($B9,2)>5,COUNTIF(FESTIVOS!$A:$A,$B9)>0),0,$I$3*24) -> 8 | J9: =IF(OR(WEEKDAY($B9,2)>5,COUNTIF(FESTIVOS!$A:$A,$B9)>0),"",G9-I9-H9) -> -8.5 | K9: =IF(OR(WEEKDAY($B9,2)>5,COUNTIF(FESTIVOS!$A:$A,$B9)>0),G9,"")
A10: Ma. | B10: 46147 | C10: 0 | D10: 0 | E10: 0 | F10: 0 | G10: =IF(AND(C10="",D10="",E10="",F10=""),0,(F10-E10+D10-C10)*24) -> 0 | H10: =IF(OR(WEEKDAY($B10,2)>5,COUNTIF(FESTIVOS!$A:$A,$B10)>0),0,$H$3*24) -> 0.5 | I10: =IF(OR(WEEKDAY($B10,2)>5,COUNTIF(FESTIVOS!$A:$A,$B10)>0),0,$I$3*24) -> 8 | J10: =IF(OR(WEEKDAY($B10,2)>5,COUNTIF(FESTIVOS!$A:$A,$B10)>0),"",G10-I10-H10) -> -8.5 | K10: =IF(OR(WEEKDAY($B10,2)>5,COUNTIF(FESTIVOS!$A:$A,$B10)>0),G10,"")
A11: Mi. | B11: 46148 | C11: 0 | D11: 0 | E11: 0 | F11: 0 | G11: =IF(AND(C11="",D11="",E11="",F11=""),0,(F11-E11+D11-C11)*24) -> 0 | H11: =IF(OR(WEEKDAY($B11,2)>5,COUNTIF(FESTIVOS!$A:$A,$B11)>0),0,$H$3*24) -> 0.5 | I11: =IF(OR(WEEKDAY($B11,2)>5,COUNTIF(FESTIVOS!$A:$A,$B11)>0),0,$I$3*24) -> 8 | J11: =IF(OR(WEEKDAY($B11,2)>5,COUNTIF(FESTIVOS!$A:$A,$B11)>0),"",G11-I11-H11) -> -8.5 | K11: =IF(OR(WEEKDAY($B11,2)>5,COUNTIF(FESTIVOS!$A:$A,$B11)>0),G11,"")
A12: Ju. | B12: 46149 | C12: 0 | D12: 0 | E12: 0 | F12: 0 | G12: =IF(AND(C12="",D12="",E12="",F12=""),0,(F12-E12+D12-C12)*24) -> 0 | H12: =IF(OR(WEEKDAY($B12,2)>5,COUNTIF(FESTIVOS!$A:$A,$B12)>0),0,$H$3*24) -> 0.5 | I12: =IF(OR(WEEKDAY($B12,2)>5,COUNTIF(FESTIVOS!$A:$A,$B12)>0),0,$I$3*24) -> 8 | J12: =IF(OR(WEEKDAY($B12,2)>5,COUNTIF(FESTIVOS!$A:$A,$B12)>0),"",G12-I12-H12) -> -8.5 | K12: =IF(OR(WEEKDAY($B12,2)>5,COUNTIF(FESTIVOS!$A:$A,$B12)>0),G12,"")
A13: Vi. | B13: 46150 | C13: 0 | D13: 0 | E13: 0 | F13: 0 | G13: =IF(AND(C13="",D13="",E13="",F13=""),0,(F13-E13+D13-C13)*24) -> 0 | H13: =IF(OR(WEEKDAY($B13,2)>5,COUNTIF(FESTIVOS!$A:$A,$B13)>0),0,$H$3*24) -> 0.5 | I13: =IF(OR(WEEKDAY($B13,2)>5,COUNTIF(FESTIVOS!$A:$A,$B13)>0),0,$I$3*24) -> 8 | J13: =IF(OR(WEEKDAY($B13,2)>5,COUNTIF(FESTIVOS!$A:$A,$B13)>0),"",G13-I13-H13) -> -8.5 | K13: =IF(OR(WEEKDAY($B13,2)>5,COUNTIF(FESTIVOS!$A:$A,$B13)>0),G13,"")
A14: Sá. | B14: 46151 | C14: 0 | D14: 0 | E14: 0 | F14: 0 | G14: =IF(AND(C14="",D14="",E14="",F14=""),0,(F14-E14+D14-C14)*24) -> 0 | H14: =IF(OR(WEEKDAY($B14,2)>5,COUNTIF(FESTIVOS!$A:$A,$B14)>0),0,$H$3*24) -> 0 | I14: =IF(OR(WEEKDAY($B14,2)>5,COUNTIF(FESTIVOS!$A:$A,$B14)>0),0,$I$3*24) -> 0 | J14: =IF(OR(WEEKDAY($B14,2)>5,COUNTIF(FESTIVOS!$A:$A,$B14)>0),"",G14-I14-H14) | K14: =IF(OR(WEEKDAY($B14,2)>5,COUNTIF(FESTIVOS!$A:$A,$B14)>0),G14,"") -> 0
A15: Do. | B15: 46152 | C15: 0 | D15: 0 | E15: 0 | F15: 0 | G15: =IF(AND(C15="",D15="",E15="",F15=""),0,(F15-E15+D15-C15)*24) -> 0 | H15: =IF(OR(WEEKDAY($B15,2)>5,COUNTIF(FESTIVOS!$A:$A,$B15)>0),0,$H$3*24) -> 0 | I15: =IF(OR(WEEKDAY($B15,2)>5,COUNTIF(FESTIVOS!$A:$A,$B15)>0),0,$I$3*24) -> 0 | J15: =IF(OR(WEEKDAY($B15,2)>5,COUNTIF(FESTIVOS!$A:$A,$B15)>0),"",G15-I15-H15) | K15: =IF(OR(WEEKDAY($B15,2)>5,COUNTIF(FESTIVOS!$A:$A,$B15)>0),G15,"") -> 0
A16: Lu. | B16: 46153 | C16: 0 | D16: 0 | E16: 0 | F16: 0 | G16: =IF(AND(C16="",D16="",E16="",F16=""),0,(F16-E16+D16-C16)*24) -> 0 | H16: =IF(OR(WEEKDAY($B16,2)>5,COUNTIF(FESTIVOS!$A:$A,$B16)>0),0,$H$3*24) -> 0.5 | I16: =IF(OR(WEEKDAY($B16,2)>5,COUNTIF(FESTIVOS!$A:$A,$B16)>0),0,$I$3*24) -> 8 | J16: =IF(OR(WEEKDAY($B16,2)>5,COUNTIF(FESTIVOS!$A:$A,$B16)>0),"",G16-I16-H16) -> -8.5 | K16: =IF(OR(WEEKDAY($B16,2)>5,COUNTIF(FESTIVOS!$A:$A,$B16)>0),G16,"")
A17: Ma. | B17: 46154 | C17: 0 | D17: 0 | E17: 0 | F17: 0 | G17: =IF(AND(C17="",D17="",E17="",F17=""),0,(F17-E17+D17-C17)*24) -> 0 | H17: =IF(OR(WEEKDAY($B17,2)>5,COUNTIF(FESTIVOS!$A:$A,$B17)>0),0,$H$3*24) -> 0.5 | I17: =IF(OR(WEEKDAY($B17,2)>5,COUNTIF(FESTIVOS!$A:$A,$B17)>0),0,$I$3*24) -> 8 | J17: =IF(OR(WEEKDAY($B17,2)>5,COUNTIF(FESTIVOS!$A:$A,$B17)>0),"",G17-I17-H17) -> -8.5 | K17: =IF(OR(WEEKDAY($B17,2)>5,COUNTIF(FESTIVOS!$A:$A,$B17)>0),G17,"")
... A36: Do. | B36: 46173 | C36: 0 | D36: 0 | E36: 0 | F36: 0 | G36: =IF(AND(C36="",D36="",E36="",F36=""),0,(F36-E36+D36-C36)*24) -> 0 | H36: =IF(OR(WEEKDAY($B36,2)>5,COUNTIF(FESTIVOS!$A:$A,$B36)>0),0,$H$3*24) -> 0 | I36: =IF(OR(WEEKDAY($B36,2)>5,COUNTIF(FESTIVOS!$A:$A,$B36)>0),0,$I$3*24) -> 0 | J36: =IF(OR(WEEKDAY($B36,2)>5,COUNTIF(FESTIVOS!$A:$A,$B36)>0),"",G36-I36-H36) | K36: =IF(OR(WEEKDAY($B36,2)>5,COUNTIF(FESTIVOS!$A:$A,$B36)>0),G36,"") -> 0

Sheet JUNIO
N1: 9 | O1: 10
C2: TRABAJADOR | F2: MES | N2: H. EXT | O2: H.S/D EXT Festivos
F3: Junio | H3: 0.020833333 | I3: 0.33333333 | N3: =SUMPRODUCT((J6:J35>0)*(J6:J35)) -> #VALUE! | O3: =SUM(K6:K35) -> 0
P4: total
A5: Día | B5: FECHAS | C5: ENTRADA | D5: SALIDA | E5: ENTRADA | F5: SALIDA | G5: H.TRAB | H5: DESCONTAR | I5: H.LAB | J5: H. EXT | K5: H EXT Festivos | L5: OBSERVACIONES | N5: =N3*N1 -> #VALUE! | O5: =O3*O1 -> 0 | P5: =N5+O5 -> #VALUE!
A6: Lu. | B6: 46174 | C6: 0 | D6: 0 | E6: 0 | F6: 0 | G6: =IF(AND(C6="",D6="",E6="",F6=""),0,(F6-E6+D6-C6)*24) -> 0 | H6: =IF(OR(WEEKDAY($B6,2)>5,COUNTIF(FESTIVOS!$A:$A,$B6)>0),0,$H$3*24) -> 0.5 | I6: =IF(OR(WEEKDAY($B6,2)>5,COUNTIF(FESTIVOS!$A:$A,$B6)>0),0,$I$3*24) -> 8 | J6: =IF(OR(WEEKDAY($B6,2)>5,COUNTIF(FESTIVOS!$A:$A,$B6)>0),"",G6-I6-H6) -> -8.5 | K6: =IF(OR(WEEKDAY($B6,2)>5,COUNTIF(FESTIVOS!$A:$A,$B6)>0),G6,"")
A7: Ma. | B7: 46175 | C7: 0 | D7: 0 | E7: 0 | F7: 0 | G7: =IF(AND(C7="",D7="",E7="",F7=""),0,(F7-E7+D7-C7)*24) -> 0 | H7: =IF(OR(WEEKDAY($B7,2)>5,COUNTIF(FESTIVOS!$A:$A,$B7)>0),0,$H$3*24) -> 0.5 | I7: =IF(OR(WEEKDAY($B7,2)>5,COUNTIF(FESTIVOS!$A:$A,$B7)>0),0,$I$3*24) -> 8 | J7: =IF(OR(WEEKDAY($B7,2)>5,COUNTIF(FESTIVOS!$A:$A,$B7)>0),"",G7-I7-H7) -> -8.5 | K7: =IF(OR(WEEKDAY($B7,2)>5,COUNTIF(FESTIVOS!$A:$A,$B7)>0),G7,"")
A8: Mi. | B8: 46176 | C8: 0 | D8: 0 | E8: 0 | F8: 0 | G8: =IF(AND(C8="",D8="",E8="",F8=""),0,(F8-E8+D8-C8)*24) -> 0 | H8: =IF(OR(WEEKDAY($B8,2)>5,COUNTIF(FESTIVOS!$A:$A,$B8)>0),0,$H$3*24) -> 0.5 | I8: =IF(OR(WEEKDAY($B8,2)>5,COUNTIF(FESTIVOS!$A:$A,$B8)>0),0,$I$3*24) -> 8 | J8: =IF(OR(WEEKDAY($B8,2)>5,COUNTIF(FESTIVOS!$A:$A,$B8)>0),"",G8-I8-H8) -> -8.5 | K8: =IF(OR(WEEKDAY($B8,2)>5,COUNTIF(FESTIVOS!$A:$A,$B8)>0),G8,"")
A9: Ju. | B9: 46177 | C9: 0 | D9: 0 | E9: 0 | F9: 0 | G9: =IF(AND(C9="",D9="",E9="",F9=""),0,(F9-E9+D9-C9)*24) -> 0 | H9: =IF(OR(WEEKDAY($B9,2)>5,COUNTIF(FESTIVOS!$A:$A,$B9)>0),0,$H$3*24) -> 0.5 | I9: =IF(OR(WEEKDAY($B9,2)>5,COUNTIF(FESTIVOS!$A:$A,$B9)>0),0,$I$3*24) -> 8 | J9: =IF(OR(WEEKDAY($B9,2)>5,COUNTIF(FESTIVOS!$A:$A,$B9)>0),"",G9-I9-H9) -> -8.5 | K9: =IF(OR(WEEKDAY($B9,2)>5,COUNTIF(FESTIVOS!$A:$A,$B9)>0),G9,"")
A10: Vi. | B10: 46178 | C10: 0 | D10: 0 | E10: 0 | F10: 0 | G10: =IF(AND(C10="",D10="",E10="",F10=""),0,(F10-E10+D10-C10)*24) -> 0 | H10: =IF(OR(WEEKDAY($B10,2)>5,COUNTIF(FESTIVOS!$A:$A,$B10)>0),0,$H$3*24) -> 0.5 | I10: =IF(OR(WEEKDAY($B10,2)>5,COUNTIF(FESTIVOS!$A:$A,$B10)>0),0,$I$3*24) -> 8 | J10: =IF(OR(WEEKDAY($B10,2)>5,COUNTIF(FESTIVOS!$A:$A,$B10)>0),"",G10-I10-H10) -> -8.5 | K10: =IF(OR(WEEKDAY($B10,2)>5,COUNTIF(FESTIVOS!$A:$A,$B10)>0),G10,"")
A11: Sá. | B11: 46179 | C11: 0 | D11: 0 | E11: 0 | F11: 0 | G11: =IF(AND(C11="",D11="",E11="",F11=""),0,(F11-E11+D11-C11)*24) -> 0 | H11: =IF(OR(WEEKDAY($B11,2)>5,COUNTIF(FESTIVOS!$A:$A,$B11)>0),0,$H$3*24) -> 0 | I11: =IF(OR(WEEKDAY($B11,2)>5,COUNTIF(FESTIVOS!$A:$A,$B11)>0),0,$I$3*24) -> 0 | J11: =IF(OR(WEEKDAY($B11,2)>5,COUNTIF(FESTIVOS!$A:$A,$B11)>0),"",G11-I11-H11) | K11: =IF(OR(WEEKDAY($B11,2)>5,COUNTIF(FESTIVOS!$A:$A,$B11)>0),G11,"") -> 0
A12: Do. | B12: 46180 | C12: 0 | D12: 0 | E12: 0 | F12: 0 | G12: =IF(AND(C12="",D12="",E12="",F12=""),0,(F12-E12+D12-C12)*24) -> 0 | H12: =IF(OR(WEEKDAY($B12,2)>5,COUNTIF(FESTIVOS!$A:$A,$B12)>0),0,$H$3*24) -> 0 | I12: =IF(OR(WEEKDAY($B12,2)>5,COUNTIF(FESTIVOS!$A:$A,$B12)>0),0,$I$3*24) -> 0 | J12: =IF(OR(WEEKDAY($B12,2)>5,COUNTIF(FESTIVOS!$A:$A,$B12)>0),"",G12-I12-H12) | K12: =IF(OR(WEEKDAY($B12,2)>5,COUNTIF(FESTIVOS!$A:$A,$B12)>0),G12,"") -> 0
A13: Lu. | B13: 46181 | C13: 0 | D13: 0 | E13: 0 | F13: 0 | G13: =IF(AND(C13="",D13="",E13="",F13=""),0,(F13-E13+D13-C13)*24) -> 0 | H13: =IF(OR(WEEKDAY($B13,2)>5,COUNTIF(FESTIVOS!$A:$A,$B13)>0),0,$H$3*24) -> 0.5 | I13: =IF(OR(WEEKDAY($B13,2)>5,COUNTIF(FESTIVOS!$A:$A,$B13)>0),0,$I$3*24) -> 8 | J13: =IF(OR(WEEKDAY($B13,2)>5,COUNTIF(FESTIVOS!$A:$A,$B13)>0),"",G13-I13-H13) -> -8.5 | K13: =IF(OR(WEEKDAY($B13,2)>5,COUNTIF(FESTIVOS!$A:$A,$B13)>0),G13,"")
A14: Ma. | B14: 46182 | C14: 0 | D14: 0 | E14: 0 | F14: 0 | G14: =IF(AND(C14="",D14="",E14="",F14=""),0,(F14-E14+D14-C14)*24) -> 0 | H14: =IF(OR(WEEKDAY($B14,2)>5,COUNTIF(FESTIVOS!$A:$A,$B14)>0),0,$H$3*24) -> 0.5 | I14: =IF(OR(WEEKDAY($B14,2)>5,COUNTIF(FESTIVOS!$A:$A,$B14)>0),0,$I$3*24) -> 8 | J14: =IF(OR(WEEKDAY($B14,2)>5,COUNTIF(FESTIVOS!$A:$A,$B14)>0),"",G14-I14-H14) -> -8.5 | K14: =IF(OR(WEEKDAY($B14,2)>5,COUNTIF(FESTIVOS!$A:$A,$B14)>0),G14,"")
A15: Mi. | B15: 46183 | C15: 0 | D15: 0 | E15: 0 | F15: 0 | G15: =IF(AND(C15="",D15="",E15="",F15=""),0,(F15-E15+D15-C15)*24) -> 0 | H15: =IF(OR(WEEKDAY($B15,2)>5,COUNTIF(FESTIVOS!$A:$A,$B15)>0),0,$H$3*24) -> 0.5 | I15: =IF(OR(WEEKDAY($B15,2)>5,COUNTIF(FESTIVOS!$A:$A,$B15)>0),0,$I$3*24) -> 8 | J15: =IF(OR(WEEKDAY($B15,2)>5,COUNTIF(FESTIVOS!$A:$A,$B15)>0),"",G15-I15-H15) -> -8.5 | K15: =IF(OR(WEEKDAY($B15,2)>5,COUNTIF(FESTIVOS!$A:$A,$B15)>0),G15,"")
A16: Ju. | B16: 46184 | C16: 0 | D16: 0 | E16: 0 | F16: 0 | G16: =IF(AND(C16="",D16="",E16="",F16=""),0,(F16-E16+D16-C16)*24) -> 0 | H16: =IF(OR(WEEKDAY($B16,2)>5,COUNTIF(FESTIVOS!$A:$A,$B16)>0),0,$H$3*24) -> 0.5 | I16: =IF(OR(WEEKDAY($B16,2)>5,COUNTIF(FESTIVOS!$A:$A,$B16)>0),0,$I$3*24) -> 8 | J16: =IF(OR(WEEKDAY($B16,2)>5,COUNTIF(FESTIVOS!$A:$A,$B16)>0),"",G16-I16-H16) -> -8.5 | K16: =IF(OR(WEEKDAY($B16,2)>5,COUNTIF(FESTIVOS!$A:$A,$B16)>0),G16,"")
A17: Vi. | B17: 46185 | C17: 0 | D17: 0 | E17: 0 | F17: 0 | G17: =IF(AND(C17="",D17="",E17="",F17=""),0,(F17-E17+D17-C17)*24) -> 0 | H17: =IF(OR(WEEKDAY($B17,2)>5,COUNTIF(FESTIVOS!$A:$A,$B17)>0),0,$H$3*24) -> 0.5 | I17: =IF(OR(WEEKDAY($B17,2)>5,COUNTIF(FESTIVOS!$A:$A,$B17)>0),0,$I$3*24) -> 8 | J17: =IF(OR(WEEKDAY($B17,2)>5,COUNTIF(FESTIVOS!$A:$A,$B17)>0),"",G17-I17-H17) -> -8.5 | K17: =IF(OR(WEEKDAY($B17,2)>5,COUNTIF(FESTIVOS!$A:$A,$B17)>0),G17,"")
... A35: Ma. | B35: 46203 | C35: 0 | D35: 0 | E35: 0 | F35: 0 | G35: =IF(AND(C35="",D35="",E35="",F35=""),0,(F35-E35+D35-C35)*24) -> 0 | H35: =IF(OR(WEEKDAY($B35,2)>5,COUNTIF(FESTIVOS!$A:$A,$B35)>0),0,$H$3*24) -> 0.5 | I35: =IF(OR(WEEKDAY($B35,2)>5,COUNTIF(FESTIVOS!$A:$A,$B35)>0),0,$I$3*24) -> 8 | J35: =IF(OR(WEEKDAY($B35,2)>5,COUNTIF(FESTIVOS!$A:$A,$B35)>0),"",G35-I35-H35) -> -8.5 | K35: =IF(OR(WEEKDAY($B35,2)>5,COUNTIF(FESTIVOS!$A:$A,$B35)>0),G35,"")

Sheet JULIO
N1: 9 | O1: 10
C2: TRABAJADOR | F2: MES | N2: H. EXT | O2: H.S/D EXT Festivos
F3: Julio | H3: 0.020833333 | I3: 0.33333333 | N3: =SUMPRODUCT((J6:J36>0)*(J6:J36)) -> #VALUE! | O3: =SUM(K6:K36) -> 0
P4: total
A5: Día | B5: FECHAS | C5: ENTRADA | D5: SALIDA | E5: ENTRADA | F5: SALIDA | G5: H.TRAB | H5: DESCONTAR | I5: H.LAB | J5: H. EXT | K5: H EXT Festivos | L5: OBSERVACIONES | N5: =N3*N1 -> #VALUE! | O5: =O3*O1 -> 0 | P5: =N5+O5 -> #VALUE!
A6: Mi. | B6: 46204 | C6: 0 | D6: 0 | E6: 0 | F6: 0 | G6: =IF(AND(C6="",D6="",E6="",F6=""),0,(F6-E6+D6-C6)*24) -> 0 | H6: =IF(OR(WEEKDAY($B6,2)>5,COUNTIF(FESTIVOS!$A:$A,$B6)>0),0,$H$3*24) -> 0.5 | I6: =IF(OR(WEEKDAY($B6,2)>5,COUNTIF(FESTIVOS!$A:$A,$B6)>0),0,$I$3*24) -> 8 | J6: =IF(OR(WEEKDAY($B6,2)>5,COUNTIF(FESTIVOS!$A:$A,$B6)>0),"",G6-I6-H6) -> -8.5 | K6: =IF(OR(WEEKDAY($B6,2)>5,COUNTIF(FESTIVOS!$A:$A,$B6)>0),G6,"")
A7: Ju. | B7: 46205 | C7: 0 | D7: 0 | E7: 0 | F7: 0 | G7: =IF(AND(C7="",D7="",E7="",F7=""),0,(F7-E7+D7-C7)*24) -> 0 | H7: =IF(OR(WEEKDAY($B7,2)>5,COUNTIF(FESTIVOS!$A:$A,$B7)>0),0,$H$3*24) -> 0.5 | I7: =IF(OR(WEEKDAY($B7,2)>5,COUNTIF(FESTIVOS!$A:$A,$B7)>0),0,$I$3*24) -> 8 | J7: =IF(OR(WEEKDAY($B7,2)>5,COUNTIF(FESTIVOS!$A:$A,$B7)>0),"",G7-I7-H7) -> -8.5 | K7: =IF(OR(WEEKDAY($B7,2)>5,COUNTIF(FESTIVOS!$A:$A,$B7)>0),G7,"")
A8: Vi. | B8: 46206 | C8: 0 | D8: 0 | E8: 0 | F8: 0 | G8: =IF(AND(C8="",D8="",E8="",F8=""),0,(F8-E8+D8-C8)*24) -> 0 | H8: =IF(OR(WEEKDAY($B8,2)>5,COUNTIF(FESTIVOS!$A:$A,$B8)>0),0,$H$3*24) -> 0.5 | I8: =IF(OR(WEEKDAY($B8,2)>5,COUNTIF(FESTIVOS!$A:$A,$B8)>0),0,$I$3*24) -> 8 | J8: =IF(OR(WEEKDAY($B8,2)>5,COUNTIF(FESTIVOS!$A:$A,$B8)>0),"",G8-I8-H8) -> -8.5 | K8: =IF(OR(WEEKDAY($B8,2)>5,COUNTIF(FESTIVOS!$A:$A,$B8)>0),G8,"")
A9: Sá. | B9: 46207 | C9: 0 | D9: 0 | E9: 0 | F9: 0 | G9: =IF(AND(C9="",D9="",E9="",F9=""),0,(F9-E9+D9-C9)*24) -> 0 | H9: =IF(OR(WEEKDAY($B9,2)>5,COUNTIF(FESTIVOS!$A:$A,$B9)>0),0,$H$3*24) -> 0 | I9: =IF(OR(WEEKDAY($B9,2)>5,COUNTIF(FESTIVOS!$A:$A,$B9)>0),0,$I$3*24) -> 0 | J9: =IF(OR(WEEKDAY($B9,2)>5,COUNTIF(FESTIVOS!$A:$A,$B9)>0),"",G9-I9-H9) | K9: =IF(OR(WEEKDAY($B9,2)>5,COUNTIF(FESTIVOS!$A:$A,$B9)>0),G9,"") -> 0
A10: Do. | B10: 46208 | C10: 0 | D10: 0 | E10: 0 | F10: 0 | G10: =IF(AND(C10="",D10="",E10="",F10=""),0,(F10-E10+D10-C10)*24) -> 0 | H10: =IF(OR(WEEKDAY($B10,2)>5,COUNTIF(FESTIVOS!$A:$A,$B10)>0),0,$H$3*24) -> 0 | I10: =IF(OR(WEEKDAY($B10,2)>5,COUNTIF(FESTIVOS!$A:$A,$B10)>0),0,$I$3*24) -> 0 | J10: =IF(OR(WEEKDAY($B10,2)>5,COUNTIF(FESTIVOS!$A:$A,$B10)>0),"",G10-I10-H10) | K10: =IF(OR(WEEKDAY($B10,2)>5,COUNTIF(FESTIVOS!$A:$A,$B10)>0),G10,"") -> 0
A11: Lu. | B11: 46209 | C11: 0 | D11: 0 | E11: 0 | F11: 0 | G11: =IF(AND(C11="",D11="",E11="",F11=""),0,(F11-E11+D11-C11)*24) -> 0 | H11: =IF(OR(WEEKDAY($B11,2)>5,COUNTIF(FESTIVOS!$A:$A,$B11)>0),0,$H$3*24) -> 0.5 | I11: =IF(OR(WEEKDAY($B11,2)>5,COUNTIF(FESTIVOS!$A:$A,$B11)>0),0,$I$3*24) -> 8 | J11: =IF(OR(WEEKDAY($B11,2)>5,COUNTIF(FESTIVOS!$A:$A,$B11)>0),"",G11-I11-H11) -> -8.5 | K11: =IF(OR(WEEKDAY($B11,2)>5,COUNTIF(FESTIVOS!$A:$A,$B11)>0),G11,"")
A12: Ma. | B12: 46210 | C12: 0 | D12: 0 | E12: 0 | F12: 0 | G12: =IF(AND(C12="",D12="",E12="",F12=""),0,(F12-E12+D12-C12)*24) -> 0 | H12: =IF(OR(WEEKDAY($B12,2)>5,COUNTIF(FESTIVOS!$A:$A,$B12)>0),0,$H$3*24) -> 0.5 | I12: =IF(OR(WEEKDAY($B12,2)>5,COUNTIF(FESTIVOS!$A:$A,$B12)>0),0,$I$3*24) -> 8 | J12: =IF(OR(WEEKDAY($B12,2)>5,COUNTIF(FESTIVOS!$A:$A,$B12)>0),"",G12-I12-H12) -> -8.5 | K12: =IF(OR(WEEKDAY($B12,2)>5,COUNTIF(FESTIVOS!$A:$A,$B12)>0),G12,"")
A13: Mi. | B13: 46211 | C13: 0 | D13: 0 | E13: 0 | F13: 0 | G13: =IF(AND(C13="",D13="",E13="",F13=""),0,(F13-E13+D13-C13)*24) -> 0 | H13: =IF(OR(WEEKDAY($B13,2)>5,COUNTIF(FESTIVOS!$A:$A,$B13)>0),0,$H$3*24) -> 0.5 | I13: =IF(OR(WEEKDAY($B13,2)>5,COUNTIF(FESTIVOS!$A:$A,$B13)>0),0,$I$3*24) -> 8 | J13: =IF(OR(WEEKDAY($B13,2)>5,COUNTIF(FESTIVOS!$A:$A,$B13)>0),"",G13-I13-H13) -> -8.5 | K13: =IF(OR(WEEKDAY($B13,2)>5,COUNTIF(FESTIVOS!$A:$A,$B13)>0),G13,"")
A14: Ju. | B14: 46212 | C14: 0 | D14: 0 | E14: 0 | F14: 0 | G14: =IF(AND(C14="",D14="",E14="",F14=""),0,(F14-E14+D14-C14)*24) -> 0 | H14: =IF(OR(WEEKDAY($B14,2)>5,COUNTIF(FESTIVOS!$A:$A,$B14)>0),0,$H$3*24) -> 0.5 | I14: =IF(OR(WEEKDAY($B14,2)>5,COUNTIF(FESTIVOS!$A:$A,$B14)>0),0,$I$3*24) -> 8 | J14: =IF(OR(WEEKDAY($B14,2)>5,COUNTIF(FESTIVOS!$A:$A,$B14)>0),"",G14-I14-H14) -> -8.5 | K14: =IF(OR(WEEKDAY($B14,2)>5,COUNTIF(FESTIVOS!$A:$A,$B14)>0),G14,"")
A15: Vi. | B15: 46213 | C15: 0 | D15: 0 | E15: 0 | F15: 0 | G15: =IF(AND(C15="",D15="",E15="",F15=""),0,(F15-E15+D15-C15)*24) -> 0 | H15: =IF(OR(WEEKDAY($B15,2)>5,COUNTIF(FESTIVOS!$A:$A,$B15)>0),0,$H$3*24) -> 0.5 | I15: =IF(OR(WEEKDAY($B15,2)>5,COUNTIF(FESTIVOS!$A:$A,$B15)>0),0,$I$3*24) -> 8 | J15: =IF(OR(WEEKDAY($B15,2)>5,COUNTIF(FESTIVOS!$A:$A,$B15)>0),"",G15-I15-H15) -> -8.5 | K15: =IF(OR(WEEKDAY($B15,2)>5,COUNTIF(FESTIVOS!$A:$A,$B15)>0),G15,"")
A16: Sá. | B16: 46214 | C16: 0 | D16: 0 | E16: 0 | F16: 0 | G16: =IF(AND(C16="",D16="",E16="",F16=""),0,(F16-E16+D16-C16)*24) -> 0 | H16: =IF(OR(WEEKDAY($B16,2)>5,COUNTIF(FESTIVOS!$A:$A,$B16)>0),0,$H$3*24) -> 0 | I16: =IF(OR(WEEKDAY($B16,2)>5,COUNTIF(FESTIVOS!$A:$A,$B16)>0),0,$I$3*24) -> 0 | J16: =IF(OR(WEEKDAY($B16,2)>5,COUNTIF(FESTIVOS!$A:$A,$B16)>0),"",G16-I16-H16) | K16: =IF(OR(WEEKDAY($B16,2)>5,COUNTIF(FESTIVOS!$A:$A,$B16)>0),G16,"") -> 0
A17: Do. | B17: 46215 | C17: 0 | D17: 0 | E17: 0 | F17: 0 | G17: =IF(AND(C17="",D17="",E17="",F17=""),0,(F17-E17+D17-C17)*24) -> 0 | H17: =IF(OR(WEEKDAY($B17,2)>5,COUNTIF(FESTIVOS!$A:$A,$B17)>0),0,$H$3*24) -> 0 | I17: =IF(OR(WEEKDAY($B17,2)>5,COUNTIF(FESTIVOS!$A:$A,$B17)>0),0,$I$3*24) -> 0 | J17: =IF(OR(WEEKDAY($B17,2)>5,COUNTIF(FESTIVOS!$A:$A,$B17)>0),"",G17-I17-H17) | K17: =IF(OR(WEEKDAY($B17,2)>5,COUNTIF(FESTIVOS!$A:$A,$B17)>0),G17,"") -> 0
... A36: Vi. | B36: 46234 | C36: 0 | D36: 0 | E36: 0 | F36: 0 | G36: =IF(AND(C36="",D36="",E36="",F36=""),0,(F36-E36+D36-C36)*24) -> 0 | H36: =IF(OR(WEEKDAY($B36,2)>5,COUNTIF(FESTIVOS!$A:$A,$B36)>0),0,$H$3*24) -> 0.5 | I36: =IF(OR(WEEKDAY($B36,2)>5,COUNTIF(FESTIVOS!$A:$A,$B36)>0),0,$I$3*24) -> 8 | J36: =IF(OR(WEEKDAY($B36,2)>5,COUNTIF(FESTIVOS!$A:$A,$B36)>0),"",G36-I36-H36) -> -8.5 | K36: =IF(OR(WEEKDAY($B36,2)>5,COUNTIF(FESTIVOS!$A:$A,$B36)>0),G36,"")

Sheet AGOSTO
N1: 9 | O1: 10
C2: TRABAJADOR | F2: MES | N2: H. EXT | O2: H.S/D EXT Festivos
F3: Agosto | H3: 0.020833333 | I3: 0.33333333 | N3: =SUMPRODUCT((J6:J36>0)*(J6:J36)) -> #VALUE! | O3: =SUM(K6:K36) -> 0
P4: total
A5: Día | B5: FECHAS | C5: ENTRADA | D5: SALIDA | E5: ENTRADA | F5: SALIDA | G5: H.TRAB | H5: DESCONTAR | I5: H.LAB | J5: H. EXT | K5: H EXT Festivos | L5: OBSERVACIONES | N5: =N3*N1 -> #VALUE! | O5: =O3*O1 -> 0 | P5: =N5+O5 -> #VALUE!
A6: Sá. | B6: 46235 | C6: 0 | D6: 0 | E6: 0 | F6: 0 | G6: =IF(AND(C6="",D6="",E6="",F6=""),0,(F6-E6+D6-C6)*24) -> 0 | H6: =IF(OR(WEEKDAY($B6,2)>5,COUNTIF(FESTIVOS!$A:$A,$B6)>0),0,$H$3*24) -> 0 | I6: =IF(OR(WEEKDAY($B6,2)>5,COUNTIF(FESTIVOS!$A:$A,$B6)>0),0,$I$3*24) -> 0 | J6: =IF(OR(WEEKDAY($B6,2)>5,COUNTIF(FESTIVOS!$A:$A,$B6)>0),"",G6-I6-H6) | K6: =IF(OR(WEEKDAY($B6,2)>5,COUNTIF(FESTIVOS!$A:$A,$B6)>0),G6,"") -> 0
A7: Do. | B7: 46236 | C7: 0 | D7: 0 | E7: 0 | F7: 0 | G7: =IF(AND(C7="",D7="",E7="",F7=""),0,(F7-E7+D7-C7)*24) -> 0 | H7: =IF(OR(WEEKDAY($B7,2)>5,COUNTIF(FESTIVOS!$A:$A,$B7)>0),0,$H$3*24) -> 0 | I7: =IF(OR(WEEKDAY($B7,2)>5,COUNTIF(FESTIVOS!$A:$A,$B7)>0),0,$I$3*24) -> 0 | J7: =IF(OR(WEEKDAY($B7,2)>5,COUNTIF(FESTIVOS!$A:$A,$B7)>0),"",G7-I7-H7) | K7: =IF(OR(WEEKDAY($B7,2)>5,COUNTIF(FESTIVOS!$A:$A,$B7)>0),G7,"") -> 0
A8: Lu. | B8: 46237 | C8: 0 | D8: 0 | E8: 0 | F8: 0 | G8: =IF(AND(C8="",D8="",E8="",F8=""),0,(F8-E8+D8-C8)*24) -> 0 | H8: =IF(OR(WEEKDAY($B8,2)>5,COUNTIF(FESTIVOS!$A:$A,$B8)>0),0,$H$3*24) -> 0.5 | I8: =IF(OR(WEEKDAY($B8,2)>5,COUNTIF(FESTIVOS!$A:$A,$B8)>0),0,$I$3*24) -> 8 | J8: =IF(OR(WEEKDAY($B8,2)>5,COUNTIF(FESTIVOS!$A:$A,$B8)>0),"",G8-I8-H8) -> -8.5 | K8: =IF(OR(WEEKDAY($B8,2)>5,COUNTIF(FESTIVOS!$A:$A,$B8)>0),G8,"")
A9: Ma. | B9: 46238 | C9: 0 | D9: 0 | E9: 0 | F9: 0 | G9: =IF(AND(C9="",D9="",E9="",F9=""),0,(F9-E9+D9-C9)*24) -> 0 | H9: =IF(OR(WEEKDAY($B9,2)>5,COUNTIF(FESTIVOS!$A:$A,$B9)>0),0,$H$3*24) -> 0.5 | I9: =IF(OR(WEEKDAY($B9,2)>5,COUNTIF(FESTIVOS!$A:$A,$B9)>0),0,$I$3*24) -> 8 | J9: =IF(OR(WEEKDAY($B9,2)>5,COUNTIF(FESTIVOS!$A:$A,$B9)>0),"",G9-I9-H9) -> -8.5 | K9: =IF(OR(WEEKDAY($B9,2)>5,COUNTIF(FESTIVOS!$A:$A,$B9)>0),G9,"")
A10: Mi. | B10: 46239 | C10: 0 | D10: 0 | E10: 0 | F10: 0 | G10: =IF(AND(C10="",D10="",E10="",F10=""),0,(F10-E10+D10-C10)*24) -> 0 | H10: =IF(OR(WEEKDAY($B10,2)>5,COUNTIF(FESTIVOS!$A:$A,$B10)>0),0,$H$3*24) -> 0.5 | I10: =IF(OR(WEEKDAY($B10,2)>5,COUNTIF(FESTIVOS!$A:$A,$B10)>0),0,$I$3*24) -> 8 | J10: =IF(OR(WEEKDAY($B10,2)>5,COUNTIF(FESTIVOS!$A:$A,$B10)>0),"",G10-I10-H10) -> -8.5 | K10: =IF(OR(WEEKDAY($B10,2)>5,COUNTIF(FESTIVOS!$A:$A,$B10)>0),G10,"")
A11: Ju. | B11: 46240 | C11: 0 | D11: 0 | E11: 0 | F11: 0 | G11: =IF(AND(C11="",D11="",E11="",F11=""),0,(F11-E11+D11-C11)*24) -> 0 | H11: =IF(OR(WEEKDAY($B11,2)>5,COUNTIF(FESTIVOS!$A:$A,$B11)>0),0,$H$3*24) -> 0.5 | I11: =IF(OR(WEEKDAY($B11,2)>5,COUNTIF(FESTIVOS!$A:$A,$B11)>0),0,$I$3*24) -> 8 | J11: =IF(OR(WEEKDAY($B11,2)>5,COUNTIF(FESTIVOS!$A:$A,$B11)>0),"",G11-I11-H11) -> -8.5 | K11: =IF(OR(WEEKDAY($B11,2)>5,COUNTIF(FESTIVOS!$A:$A,$B11)>0),G11,"")
A12: Vi. | B12: 46241 | C12: 0 | D12: 0 | E12: 0 | F12: 0 | G12: =IF(AND(C12="",D12="",E12="",F12=""),0,(F12-E12+D12-C12)*24) -> 0 | H12: =IF(OR(WEEKDAY($B12,2)>5,COUNTIF(FESTIVOS!$A:$A,$B12)>0),0,$H$3*24) -> 0.5 | I12: =IF(OR(WEEKDAY($B12,2)>5,COUNTIF(FESTIVOS!$A:$A,$B12)>0),0,$I$3*24) -> 8 | J12: =IF(OR(WEEKDAY($B12,2)>5,COUNTIF(FESTIVOS!$A:$A,$B12)>0),"",G12-I12-H12) -> -8.5 | K12: =IF(OR(WEEKDAY($B12,2)>5,COUNTIF(FESTIVOS!$A:$A,$B12)>0),G12,"")
A13: Sá. | B13: 46242 | C13: 0 | D13: 0 | E13: 0 | F13: 0 | G13: =IF(AND(C13="",D13="",E13="",F13=""),0,(F13-E13+D13-C13)*24) -> 0 | H13: =IF(OR(WEEKDAY($B13,2)>5,COUNTIF(FESTIVOS!$A:$A,$B13)>0),0,$H$3*24) -> 0 | I13: =IF(OR(WEEKDAY($B13,2)>5,COUNTIF(FESTIVOS!$A:$A,$B13)>0),0,$I$3*24) -> 0 | J13: =IF(OR(WEEKDAY($B13,2)>5,COUNTIF(FESTIVOS!$A:$A,$B13)>0),"",G13-I13-H13) | K13: =IF(OR(WEEKDAY($B13,2)>5,COUNTIF(FESTIVOS!$A:$A,$B13)>0),G13,"") -> 0
A14: Do. | B14: 46243 | C14: 0 | D14: 0 | E14: 0 | F14: 0 | G14: =IF(AND(C14="",D14="",E14="",F14=""),0,(F14-E14+D14-C14)*24) -> 0 | H14: =IF(OR(WEEKDAY($B14,2)>5,COUNTIF(FESTIVOS!$A:$A,$B14)>0),0,$H$3*24) -> 0 | I14: =IF(OR(WEEKDAY($B14,2)>5,COUNTIF(FESTIVOS!$A:$A,$B14)>0),0,$I$3*24) -> 0 | J14: =IF(OR(WEEKDAY($B14,2)>5,COUNTIF(FESTIVOS!$A:$A,$B14)>0),"",G14-I14-H14) | K14: =IF(OR(WEEKDAY($B14,2)>5,COUNTIF(FESTIVOS!$A:$A,$B14)>0),G14,"") -> 0
A15: Lu. | B15: 46244 | C15: 0 | D15: 0 | E15: 0 | F15: 0 | G15: =IF(AND(C15="",D15="",E15="",F15=""),0,(F15-E15+D15-C15)*24) -> 0 | H15: =IF(OR(WEEKDAY($B15,2)>5,COUNTIF(FESTIVOS!$A:$A,$B15)>0),0,$H$3*24) -> 0.5 | I15: =IF(OR(WEEKDAY($B15,2)>5,COUNTIF(FESTIVOS!$A:$A,$B15)>0),0,$I$3*24) -> 8 | J15: =IF(OR(WEEKDAY($B15,2)>5,COUNTIF(FESTIVOS!$A:$A,$B15)>0),"",G15-I15-H15) -> -8.5 | K15: =IF(OR(WEEKDAY($B15,2)>5,COUNTIF(FESTIVOS!$A:$A,$B15)>0),G15,"")
A16: Ma. | B16: 46245 | C16: 0 | D16: 0 | E16: 0 | F16: 0 | G16: =IF(AND(C16="",D16="",E16="",F16=""),0,(F16-E16+D16-C16)*24) -> 0 | H16: =IF(OR(WEEKDAY($B16,2)>5,COUNTIF(FESTIVOS!$A:$A,$B16)>0),0,$H$3*24) -> 0.5 | I16: =IF(OR(WEEKDAY($B16,2)>5,COUNTIF(FESTIVOS!$A:$A,$B16)>0),0,$I$3*24) -> 8 | J16: =IF(OR(WEEKDAY($B16,2)>5,COUNTIF(FESTIVOS!$A:$A,$B16)>0),"",G16-I16-H16) -> -8.5 | K16: =IF(OR(WEEKDAY($B16,2)>5,COUNTIF(FESTIVOS!$A:$A,$B16)>0),G16,"")
A17: Mi. | B17: 46246 | C17: 0 | D17: 0 | E17: 0 | F17: 0 | G17: =IF(AND(C17="",D17="",E17="",F17=""),0,(F17-E17+D17-C17)*24) -> 0 | H17: =IF(OR(WEEKDAY($B17,2)>5,COUNTIF(FESTIVOS!$A:$A,$B17)>0),0,$H$3*24) -> 0.5 | I17: =IF(OR(WEEKDAY($B17,2)>5,COUNTIF(FESTIVOS!$A:$A,$B17)>0),0,$I$3*24) -> 8 | J17: =IF(OR(WEEKDAY($B17,2)>5,COUNTIF(FESTIVOS!$A:$A,$B17)>0),"",G17-I17-H17) -> -8.5 | K17: =IF(OR(WEEKDAY($B17,2)>5,COUNTIF(FESTIVOS!$A:$A,$B17)>0),G17,"")
... A36: Lu. | B36: 46265 | C36: 0 | D36: 0 | E36: 0 | F36: 0 | G36: =IF(AND(C36="",D36="",E36="",F36=""),0,(F36-E36+D36-C36)*24) -> 0 | H36: =IF(OR(WEEKDAY($B36,2)>5,COUNTIF(FESTIVOS!$A:$A,$B36)>0),0,$H$3*24) -> 0.5 | I36: =IF(OR(WEEKDAY($B36,2)>5,COUNTIF(FESTIVOS!$A:$A,$B36)>0),0,$I$3*24) -> 8 | J36: =IF(OR(WEEKDAY($B36,2)>5,COUNTIF(FESTIVOS!$A:$A,$B36)>0),"",G36-I36-H36) -> -8.5 | K36: =IF(OR(WEEKDAY($B36,2)>5,COUNTIF(FESTIVOS!$A:$A,$B36)>0),G36,"")

Sheet SEPTIEMBRE
N1: 9 | O1: 10
C2: TRABAJADOR | F2: MES | N2: H. EXT | O2: H.S/D EXT Festivos
F3: Septiembre | H3: 0.020833333 | I3: 0.33333333 | N3: =SUMPRODUCT((J6:J35>0)*(J6:J35)) -> #VALUE! | O3: =SUM(K6:K35) -> 0
P4: total
A5: Día | B5: FECHAS | C5: ENTRADA | D5: SALIDA | E5: ENTRADA | F5: SALIDA | G5: H.TRAB | H5: DESCONTAR | I5: H.LAB | J5: H. EXT | K5: H EXT Festivos | L5: OBSERVACIONES | N5: =N3*N1 -> #VALUE! | O5: =O3*O1 -> 0 | P5: =N5+O5 -> #VALUE!
A6: Ma. | B6: 46266 | C6: 0 | D6: 0 | E6: 0 | F6: 0 | G6: =IF(AND(C6="",D6="",E6="",F6=""),0,(F6-E6+D6-C6)*24) -> 0 | H6: =IF(OR(WEEKDAY($B6,2)>5,COUNTIF(FESTIVOS!$A:$A,$B6)>0),0,$H$3*24) -> 0.5 | I6: =IF(OR(WEEKDAY($B6,2)>5,COUNTIF(FESTIVOS!$A:$A,$B6)>0),0,$I$3*24) -> 8 | J6: =IF(OR(WEEKDAY($B6,2)>5,COUNTIF(FESTIVOS!$A:$A,$B6)>0),"",G6-I6-H6) -> -8.5 | K6: =IF(OR(WEEKDAY($B6,2)>5,COUNTIF(FESTIVOS!$A:$A,$B6)>0),G6,"")
A7: Mi. | B7: 46267 | C7: 0 | D7: 0 | E7: 0 | F7: 0 | G7: =IF(AND(C7="",D7="",E7="",F7=""),0,(F7-E7+D7-C7)*24) -> 0 | H7: =IF(OR(WEEKDAY($B7,2)>5,COUNTIF(FESTIVOS!$A:$A,$B7)>0),0,$H$3*24) -> 0.5 | I7: =IF(OR(WEEKDAY($B7,2)>5,COUNTIF(FESTIVOS!$A:$A,$B7)>0),0,$I$3*24) -> 8 | J7: =IF(OR(WEEKDAY($B7,2)>5,COUNTIF(FESTIVOS!$A:$A,$B7)>0),"",G7-I7-H7) -> -8.5 | K7: =IF(OR(WEEKDAY($B7,2)>5,COUNTIF(FESTIVOS!$A:$A,$B7)>0),G7,"")
A8: Ju. | B8: 46268 | C8: 0 | D8: 0 | E8: 0 | F8: 0 | G8: =IF(AND(C8="",D8="",E8="",F8=""),0,(F8-E8+D8-C8)*24) -> 0 | H8: =IF(OR(WEEKDAY($B8,2)>5,COUNTIF(FESTIVOS!$A:$A,$B8)>0),0,$H$3*24) -> 0.5 | I8: =IF(OR(WEEKDAY($B8,2)>5,COUNTIF(FESTIVOS!$A:$A,$B8)>0),0,$I$3*24) -> 8 | J8: =IF(OR(WEEKDAY($B8,2)>5,COUNTIF(FESTIVOS!$A:$A,$B8)>0),"",G8-I8-H8) -> -8.5 | K8: =IF(OR(WEEKDAY($B8,2)>5,COUNTIF(FESTIVOS!$A:$A,$B8)>0),G8,"")
A9: Vi. | B9: 46269 | C9: 0 | D9: 0 | E9: 0 | F9: 0 | G9: =IF(AND(C9="",D9="",E9="",F9=""),0,(F9-E9+D9-C9)*24) -> 0 | H9: =IF(OR(WEEKDAY($B9,2)>5,COUNTIF(FESTIVOS!$A:$A,$B9)>0),0,$H$3*24) -> 0.5 | I9: =IF(OR(WEEKDAY($B9,2)>5,COUNTIF(FESTIVOS!$A:$A,$B9)>0),0,$I$3*24) -> 8 | J9: =IF(OR(WEEKDAY($B9,2)>5,COUNTIF(FESTIVOS!$A:$A,$B9)>0),"",G9-I9-H9) -> -8.5 | K9: =IF(OR(WEEKDAY($B9,2)>5,COUNTIF(FESTIVOS!$A:$A,$B9)>0),G9,"")
A10: Sá. | B10: 46270 | C10: 0 | D10: 0 | E10: 0 | F10: 0 | G10: =IF(AND(C10="",D10="",E10="",F10=""),0,(F10-E10+D10-C10)*24) -> 0 | H10: =IF(OR(WEEKDAY($B10,2)>5,COUNTIF(FESTIVOS!$A:$A,$B10)>0),0,$H$3*24) -> 0 | I10: =IF(OR(WEEKDAY($B10,2)>5,COUNTIF(FESTIVOS!$A:$A,$B10)>0),0,$I$3*24) -> 0 | J10: =IF(OR(WEEKDAY($B10,2)>5,COUNTIF(FESTIVOS!$A:$A,$B10)>0),"",G10-I10-H10) | K10: =IF(OR(WEEKDAY($B10,2)>5,COUNTIF(FESTIVOS!$A:$A,$B10)>0),G10,"") -> 0
A11: Do. | B11: 46271 | C11: 0 | D11: 0 | E11: 0 | F11: 0 | G11: =IF(AND(C11="",D11="",E11="",F11=""),0,(F11-E11+D11-C11)*24) -> 0 | H11: =IF(OR(WEEKDAY($B11,2)>5,COUNTIF(FESTIVOS!$A:$A,$B11)>0),0,$H$3*24) -> 0 | I11: =IF(OR(WEEKDAY($B11,2)>5,COUNTIF(FESTIVOS!$A:$A,$B11)>0),0,$I$3*24) -> 0 | J11: =IF(OR(WEEKDAY($B11,2)>5,COUNTIF(FESTIVOS!$A:$A,$B11)>0),"",G11-I11-H11) | K11: =IF(OR(WEEKDAY($B11,2)>5,COUNTIF(FESTIVOS!$A:$A,$B11)>0),G11,"") -> 0
A12: Lu. | B12: 46272 | C12: 0 | D12: 0 | E12: 0 | F12: 0 | G12: =IF(AND(C12="",D12="",E12="",F12=""),0,(F12-E12+D12-C12)*24) -> 0 | H12: =IF(OR(WEEKDAY($B12,2)>5,COUNTIF(FESTIVOS!$A:$A,$B12)>0),0,$H$3*24) -> 0.5 | I12: =IF(OR(WEEKDAY($B12,2)>5,COUNTIF(FESTIVOS!$A:$A,$B12)>0),0,$I$3*24) -> 8 | J12: =IF(OR(WEEKDAY($B12,2)>5,COUNTIF(FESTIVOS!$A:$A,$B12)>0),"",G12-I12-H12) -> -8.5 | K12: =IF(OR(WEEKDAY($B12,2)>5,COUNTIF(FESTIVOS!$A:$A,$B12)>0),G12,"")
A13: Ma. | B13: 46273 | C13: 0 | D13: 0 | E13: 0 | F13: 0 | G13: =IF(AND(C13="",D13="",E13="",F13=""),0,(F13-E13+D13-C13)*24) -> 0 | H13: =IF(OR(WEEKDAY($B13,2)>5,COUNTIF(FESTIVOS!$A:$A,$B13)>0),0,$H$3*24) -> 0.5 | I13: =IF(OR(WEEKDAY($B13,2)>5,COUNTIF(FESTIVOS!$A:$A,$B13)>0),0,$I$3*24) -> 8 | J13: =IF(OR(WEEKDAY($B13,2)>5,COUNTIF(FESTIVOS!$A:$A,$B13)>0),"",G13-I13-H13) -> -8.5 | K13: =IF(OR(WEEKDAY($B13,2)>5,COUNTIF(FESTIVOS!$A:$A,$B13)>0),G13,"")
